Workbook

Sheet 사용안내
B2: 부서 업무일지 · 출장 / 분석 / 일일 통합 관리
B4: 시트 구성
B5: 월력표 | C5: 연·월을 고르면 달력이 그려집니다. 각 날짜의 파란 줄은 자동 집계, 흰 칸은 자유 메모.
B6: 업무일지 | C6: 출장·분석 1건 = 1행. 사건번호를 고르면 사건명·요청처·담당자가 통째로 자동 연동.
B7: 일일실시사항 | C7: 출장·분석 외 부서의 모든 일일 업무(행정·교육·회의·장비관리·당직 등)를 기록.
B8: 사건마스터 | C8: 사건을 한 번만 등록하고 담당자 배정표에서 여러 명을 [주담당]·[참여]로 선택 → 업무일지로 전달.
B9: 부서 전체현황 | C9: 기준연도 1칸만 바꾸면 월별 추이·유형별·팀별·요청처별·일일실시 집계가 전부 갱신.
B10: 사건별 현황 | C10: 사건번호 기준 누계(전체 기간). 아래쪽에서 사건 하나를 골라 상세 조회.
B11: 개인별 현황 | C11: 담당자별 주담당/참여 분리 집계, 투입시간 누계, 월별 참여건수 매트릭스.
B12: 코드설정 | C12: 모든 드롭다운의 원본. 담당자·팀·유형·공휴일을 여기서 관리.
B14: 입력 순서
B15: ① 코드설정 | C15: 담당자·소속팀·팀 마스터·요청처를 우리 부서에 맞게 수정합니다.
B16: ② 사건마스터 | C16: 사건번호·사건명·요청처를 등록하고, L열부터 담당자 배정칸에서 참여자를 모두 선택합니다.
B17: ③ 업무일지 | C17: 5행의 예시를 지우고, 사건번호를 고른 뒤 날짜·유형·시간을 입력합니다. 담당자는 자동으로 들어옵니다.
B18: ④ 일일실시사항 | C18: 사건과 무관한 일일 업무를 그날그날 기록합니다.
B19: ⑤ 현황 시트 | C19: 기준연도만 바꿔 가며 결과를 확인합니다. 입력할 것은 없습니다.
B21: 색상 규칙
B22: 파란 글씨 | C22: 직접 입력하는 칸
B23: 검정 글씨 | C23: 같은 시트 안에서 자동 계산되는 칸 (덮어쓰지 마세요)
B24: 초록 글씨 | C24: 다른 시트에서 자동으로 끌어온 칸 (업무일지 담당자칸은 덮어써서 그 행만 바꿀 수 있음)
B25: 노란 배경 | C25: 반드시 확인·변경해야 하는 핵심 입력값 (기준연도, 조회 연·월, 사건번호 선택)
B26: 주황 배경 행 | C26: 각 시트 5행의 작성 예시 — 실제 사용 전 내용을 지우세요
B27: 행 배경색 | C27: 완료 = 연녹색 / 보류 = 주황 / 종료일이 지났는데 미완료 = 빨강
B29: 집계 기준
B30: 총 인시(H) | C30: 1인 투입시간 × 투입인원. 부서가 그 건에 실제로 쓴 총 공수입니다.
B31: 본인 투입시간(H) | C31: 그 건의 1인 투입시간을 개인별로 합산한 값 (총 인시와 다릅니다).
B32: 연인원(명) | C32: 각 건의 투입인원을 그대로 합산 — 같은 사람이 여러 건에 참여하면 중복 계상됩니다.
B33: 월 귀속 | C33: 출장·분석은 '시작일', 일일실시사항은 '일자'가 속한 달로 집계됩니다.
B34: 팀별 집계 | C34: 주담당자의 소속팀 기준입니다.
B36: 주의
B37: 동명이인 | C37: 참여자 집계가 이름 부분일치 방식이라 '김디지(1팀)'처럼 반드시 구분해 등록하세요.
B38: 입력 한도 | C38: 업무일지·일일실시사항 각 1000건(5~1004행), 사건 60건, 담당자 20명입니다.
B39: 월력표 메모 | C39: 연·월을 바꿔도 메모 칸은 그대로 남습니다. 한 달이 끝나면 시트를 복사해 보관하세요.
B40: 참여자 6명 초과 | C40: 사건마스터에서 6명 넘게 배정하면 업무일지엔 주담당 + 참여자 5명까지만 전달됩니다.

Sheet 월력표
A1: 월력표 · 월간 업무 캘린더
A2: ※ 노란 칸(연도·월)만 바꾸면 달력이 다시 그려집니다. ※ 각 날짜의 파란 줄은 [업무일지]·[일일실시사항]에서 자동 집계된 건수입니다. ※ 흰 칸은 자유 메모입니다 — 연·월을 바꿔도 메모는 그대로 남으니, 달이 끝나면 시트를 복사해 보관하세요.
A4: 연도 | B4: 2026 | C4: 월 | D4: 3 | E4: =TEXT(DATE($B$4,$D$4,1),"yyyy년 m월") | H4: =DATE($B$4,$D$4,1)-WEEKDAY(DATE($B$4,$D$4,1))+1
A6: 일 | B6: 월 | C6: 화 | D6: 수 | E6: 목 | F6: 금 | G6: 토
A7: =IF(MONTH($H$4+0)<>$D$4,"",$H$4+0) | B7: =IF(MONTH($H$4+1)<>$D$4,"",$H$4+1) | C7: =IF(MONTH($H$4+2)<>$D$4,"",$H$4+2) | D7: =IF(MONTH($H$4+3)<>$D$4,"",$H$4+3) | E7: =IF(MONTH($H$4+4)<>$D$4,"",$H$4+4) | F7: =IF(MONTH($H$4+5)<>$D$4,"",$H$4+5) | G7: =IF(MONTH($H$4+6)<>$D$4,"",$H$4+6) | J7: =IF(A7="",0,COUNTIFS(업무일지!$B$5:$B$1004,"<="&A7,업무일지!$C$5:$C$1004,">="&A7,업무일지!$D$5:$D$1004,"출장")) | K7: =IF(B7="",0,COUNTIFS(업무일지!$B$5:$B$1004,"<="&B7,업무일지!$C$5:$C$1004,">="&B7,업무일지!$D$5:$D$1004,"출장")) | L7: =IF(C7="",0,COUNTIFS(업무일지!$B$5:$B$1004,"<="&C7,업무일지!$C$5:$C$1004,">="&C7,업무일지!$D$5:$D$1004,"출장")) | M7: =IF(D7="",0,COUNTIFS(업무일지!$B$5:$B$1004,"<="&D7,업무일지!$C$5:$C$1004,">="&D7,업무일지!$D$5:$D$1004,"출장")) | N7: =IF(E7="",0,COUNTIFS(업무일지!$B$5:$B$1004,"<="&E7,업무일지!$C$5:$C$1004,">="&E7,업무일지!$D$5:$D$1004,"출장")) | O7: =IF(F7="",0,COUNTIFS(업무일지!$B$5:$B$1004,"<="&F7,업무일지!$C$5:$C$1004,">="&F7,업무일지!$D$5:$D$1004,"출장")) | P7: =IF(G7="",0,COUNTIFS(업무일지!$B$5:$B$1004,"<="&G7,업무일지!$C$5:$C$1004,">="&G7,업무일지!$D$5:$D$1004,"출장")) | Q7: =IF(A7="",0,COUNTIFS(업무일지!$B$5:$B$1004,"<="&A7,업무일지!$C$5:$C$1004,">="&A7,업무일지!$D$5:$D$1004,"분석")) | R7: =IF(B7="",0,COUNTIFS(업무일지!$B$5:$B$1004,"<="&B7,업무일지!$C$5:$C$1004,">="&B7,업무일지!$D$5:$D$1004,"분석")) | S7: =IF(C7="",0,COUNTIFS(업무일지!$B$5:$B$1004,"<="&C7,업무일지!$C$5:$C$1004,">="&C7,업무일지!$D$5:$D$1004,"분석")) | T7: =IF(D7="",0,COUNTIFS(업무일지!$B$5:$B$1004,"<="&D7,업무일지!$C$5:$C$1004,">="&D7,업무일지!$D$5:$D$1004,"분석")) | U7: =IF(E7="",0,COUNTIFS(업무일지!$B$5:$B$1004,"<="&E7,업무일지!$C$5:$C$1004,">="&E7,업무일지!$D$5:$D$1004,"분석")) | V7: =IF(F7="",0,COUNTIFS(업무일지!$B$5:$B$1004,"<="&F7,업무일지!$C$5:$C$1004,">="&F7,업무일지!$D$5:$D$1004,"분석")) | W7: =IF(G7="",0,COUNTIFS(업무일지!$B$5:$B$1004,"<="&G7,업무일지!$C$5:$C$1004,">="&G7,업무일지!$D$5:$D$1004,"분석")) | X7: =IF(A7="",0,COUNTIFS(일일실시사항!$B$5:$B$1004,A7)) | Y7: =IF(B7="",0,COUNTIFS(일일실시사항!$B$5:$B$1004,B7)) | Z7: =IF(C7="",0,COUNTIFS(일일실시사항!$B$5:$B$1004,C7)) | AA7: =IF(D7="",0,COUNTIFS(일일실시사항!$B$5:$B$1004,D7)) | AB7: =IF(E7="",0,COUNTIFS(일일실시사항!$B$5:$B$1004,E7)) | AC7: =IF(F7="",0,COUNTIFS(일일실시사항!$B$5:$B$1004,F7)) | AD7: =IF(G7="",0,COUNTIFS(일일실시사항!$B$5:$B$1004,G7))
A8: =IF(A7="","",IF(J7+Q7+X7=0,"",IF(J7=0,"","출장 "&J7&" ")&IF(Q7=0,"","분석 "&Q7&" ")&IF(X7=0,"","일일 "&X7))) | B8: =IF(B7="","",IF(K7+R7+Y7=0,"",IF(K7=0,"","출장 "&K7&" ")&IF(R7=0,"","분석 "&R7&" ")&IF(Y7=0,"","일일 "&Y7))) | C8: =IF(C7="","",IF(L7+S7+Z7=0,"",IF(L7=0,"","출장 "&L7&" ")&IF(S7=0,"","분석 "&S7&" ")&IF(Z7=0,"","일일 "&Z7))) | D8: =IF(D7="","",IF(M7+T7+AA7=0,"",IF(M7=0,"","출장 "&M7&" ")&IF(T7=0,"","분석 "&T7&" ")&IF(AA7=0,"","일일 "&AA7))) | E8: =IF(E7="","",IF(N7+U7+AB7=0,"",IF(N7=0,"","출장 "&N7&" ")&IF(U7=0,"","분석 "&U7&" ")&IF(AB7=0,"","일일 "&AB7))) | F8: =IF(F7="","",IF(O7+V7+AC7=0,"",IF(O7=0,"","출장 "&O7&" ")&IF(V7=0,"","분석 "&V7&" ")&IF(AC7=0,"","일일 "&AC7))) | G8: =IF(G7="","",IF(P7+W7+AD7=0,"",IF(P7=0,"","출장 "&P7&" ")&IF(W7=0,"","분석 "&W7&" ")&IF(AD7=0,"","일일 "&AD7))) | J8: =IF(A10="",0,COUNTIFS(업무일지!$B$5:$B$1004,"<="&A10,업무일지!$C$5:$C$1004,">="&A10,업무일지!$D$5:$D$1004,"출장")) | K8: =IF(B10="",0,COUNTIFS(업무일지!$B$5:$B$1004,"<="&B10,업무일지!$C$5:$C$1004,">="&B10,업무일지!$D$5:$D$1004,"출장")) | L8: =IF(C10="",0,COUNTIFS(업무일지!$B$5:$B$1004,"<="&C10,업무일지!$C$5:$C$1004,">="&C10,업무일지!$D$5:$D$1004,"출장")) | M8: =IF(D10="",0,COUNTIFS(업무일지!$B$5:$B$1004,"<="&D10,업무일지!$C$5:$C$1004,">="&D10,업무일지!$D$5:$D$1004,"출장")) | N8: =IF(E10="",0,COUNTIFS(업무일지!$B$5:$B$1004,"<="&E10,업무일지!$C$5:$C$1004,">="&E10,업무일지!$D$5:$D$1004,"출장")) | O8: =IF(F10="",0,COUNTIFS(업무일지!$B$5:$B$1004,"<="&F10,업무일지!$C$5:$C$1004,">="&F10,업무일지!$D$5:$D$1004,"출장")) | P8: =IF(G10="",0,COUNTIFS(업무일지!$B$5:$B$1004,"<="&G10,업무일지!$C$5:$C$1004,">="&G10,업무일지!$D$5:$D$1004,"출장")) | Q8: =IF(A10="",0,COUNTIFS(업무일지!$B$5:$B$1004,"<="&A10,업무일지!$C$5:$C$1004,">="&A10,업무일지!$D$5:$D$1004,"분석")) | R8: =IF(B10="",0,COUNTIFS(업무일지!$B$5:$B$1004,"<="&B10,업무일지!$C$5:$C$1004,">="&B10,업무일지!$D$5:$D$1004,"분석")) | S8: =IF(C10="",0,COUNTIFS(업무일지!$B$5:$B$1004,"<="&C10,업무일지!$C$5:$C$1004,">="&C10,업무일지!$D$5:$D$1004,"분석")) | T8: =IF(D10="",0,COUNTIFS(업무일지!$B$5:$B$1004,"<="&D10,업무일지!$C$5:$C$1004,">="&D10,업무일지!$D$5:$D$1004,"분석")) | U8: =IF(E10="",0,COUNTIFS(업무일지!$B$5:$B$1004,"<="&E10,업무일지!$C$5:$C$1004,">="&E10,업무일지!$D$5:$D$1004,"분석")) | V8: =IF(F10="",0,COUNTIFS(업무일지!$B$5:$B$1004,"<="&F10,업무일지!$C$5:$C$1004,">="&F10,업무일지!$D$5:$D$1004,"분석")) | W8: =IF(G10="",0,COUNTIFS(업무일지!$B$5:$B$1004,"<="&G10,업무일지!$C$5:$C$1004,">="&G10,업무일지!$D$5:$D$1004,"분석")) | X8: =IF(A10="",0,COUNTIFS(일일실시사항!$B$5:$B$1004,A10)) | Y8: =IF(B10="",0,COUNTIFS(일일실시사항!$B$5:$B$1004,B10)) | Z8: =IF(C10="",0,COUNTIFS(일일실시사항!$B$5:$B$1004,C10)) | AA8: =IF(D10="",0,COUNTIFS(일일실시사항!$B$5:$B$1004,D10)) | AB8: =IF(E10="",0,COUNTIFS(일일실시사항!$B$5:$B$1004,E10)) | AC8: =IF(F10="",0,COUNTIFS(일일실시사항!$B$5:$B$1004,F10)) | AD8: =IF(G10="",0,COUNTIFS(일일실시사항!$B$5:$B$1004,G10))
J9: =IF(A13="",0,COUNTIFS(업무일지!$B$5:$B$1004,"<="&A13,업무일지!$C$5:$C$1004,">="&A13,업무일지!$D$5:$D$1004,"출장")) | K9: =IF(B13="",0,COUNTIFS(업무일지!$B$5:$B$1004,"<="&B13,업무일지!$C$5:$C$1004,">="&B13,업무일지!$D$5:$D$1004,"출장")) | L9: =IF(C13="",0,COUNTIFS(업무일지!$B$5:$B$1004,"<="&C13,업무일지!$C$5:$C$1004,">="&C13,업무일지!$D$5:$D$1004,"출장")) | M9: =IF(D13="",0,COUNTIFS(업무일지!$B$5:$B$1004,"<="&D13,업무일지!$C$5:$C$1004,">="&D13,업무일지!$D$5:$D$1004,"출장")) | N9: =IF(E13="",0,COUNTIFS(업무일지!$B$5:$B$1004,"<="&E13,업무일지!$C$5:$C$1004,">="&E13,업무일지!$D$5:$D$1004,"출장")) | O9: =IF(F13="",0,COUNTIFS(업무일지!$B$5:$B$1004,"<="&F13,업무일지!$C$5:$C$1004,">="&F13,업무일지!$D$5:$D$1004,"출장")) | P9: =IF(G13="",0,COUNTIFS(업무일지!$B$5:$B$1004,"<="&G13,업무일지!$C$5:$C$1004,">="&G13,업무일지!$D$5:$D$1004,"출장")) | Q9: =IF(A13="",0,COUNTIFS(업무일지!$B$5:$B$1004,"<="&A13,업무일지!$C$5:$C$1004,">="&A13,업무일지!$D$5:$D$1004,"분석")) | R9: =IF(B13="",0,COUNTIFS(업무일지!$B$5:$B$1004,"<="&B13,업무일지!$C$5:$C$1004,">="&B13,업무일지!$D$5:$D$1004,"분석")) | S9: =IF(C13="",0,COUNTIFS(업무일지!$B$5:$B$1004,"<="&C13,업무일지!$C$5:$C$1004,">="&C13,업무일지!$D$5:$D$1004,"분석")) | T9: =IF(D13="",0,COUNTIFS(업무일지!$B$5:$B$1004,"<="&D13,업무일지!$C$5:$C$1004,">="&D13,업무일지!$D$5:$D$1004,"분석")) | U9: =IF(E13="",0,COUNTIFS(업무일지!$B$5:$B$1004,"<="&E13,업무일지!$C$5:$C$1004,">="&E13,업무일지!$D$5:$D$1004,"분석")) | V9: =IF(F13="",0,COUNTIFS(업무일지!$B$5:$B$1004,"<="&F13,업무일지!$C$5:$C$1004,">="&F13,업무일지!$D$5:$D$1004,"분석")) | W9: =IF(G13="",0,COUNTIFS(업무일지!$B$5:$B$1004,"<="&G13,업무일지!$C$5:$C$1004,">="&G13,업무일지!$D$5:$D$1004,"분석")) | X9: =IF(A13="",0,COUNTIFS(일일실시사항!$B$5:$B$1004,A13)) | Y9: =IF(B13="",0,COUNTIFS(일일실시사항!$B$5:$B$1004,B13)) | Z9: =IF(C13="",0,COUNTIFS(일일실시사항!$B$5:$B$1004,C13)) | AA9: =IF(D13="",0,COUNTIFS(일일실시사항!$B$5:$B$1004,D13)) | AB9: =IF(E13="",0,COUNTIFS(일일실시사항!$B$5:$B$1004,E13)) | AC9: =IF(F13="",0,COUNTIFS(일일실시사항!$B$5:$B$1004,F13)) | AD9: =IF(G13="",0,COUNTIFS(일일실시사항!$B$5:$B$1004,G13))
A10: =IF(MONTH($H$4+7)<>$D$4,"",$H$4+7) | B10: =IF(MONTH($H$4+8)<>$D$4,"",$H$4+8) | C10: =IF(MONTH($H$4+9)<>$D$4,"",$H$4+9) | D10: =IF(MONTH($H$4+10)<>$D$4,"",$H$4+10) | E10: =IF(MONTH($H$4+11)<>$D$4,"",$H$4+11) | F10: =IF(MONTH($H$4+12)<>$D$4,"",$H$4+12) | G10: =IF(MONTH($H$4+13)<>$D$4,"",$H$4+13) | J10: =IF(A16="",0,COUNTIFS(업무일지!$B$5:$B$1004,"<="&A16,업무일지!$C$5:$C$1004,">="&A16,업무일지!$D$5:$D$1004,"출장")) | K10: =IF(B16="",0,COUNTIFS(업무일지!$B$5:$B$1004,"<="&B16,업무일지!$C$5:$C$1004,">="&B16,업무일지!$D$5:$D$1004,"출장")) | L10: =IF(C16="",0,COUNTIFS(업무일지!$B$5:$B$1004,"<="&C16,업무일지!$C$5:$C$1004,">="&C16,업무일지!$D$5:$D$1004,"출장")) | M10: =IF(D16="",0,COUNTIFS(업무일지!$B$5:$B$1004,"<="&D16,업무일지!$C$5:$C$1004,">="&D16,업무일지!$D$5:$D$1004,"출장")) | N10: =IF(E16="",0,COUNTIFS(업무일지!$B$5:$B$1004,"<="&E16,업무일지!$C$5:$C$1004,">="&E16,업무일지!$D$5:$D$1004,"출장")) | O10: =IF(F16="",0,COUNTIFS(업무일지!$B$5:$B$1004,"<="&F16,업무일지!$C$5:$C$1004,">="&F16,업무일지!$D$5:$D$1004,"출장")) | P10: =IF(G16="",0,COUNTIFS(업무일지!$B$5:$B$1004,"<="&G16,업무일지!$C$5:$C$1004,">="&G16,업무일지!$D$5:$D$1004,"출장")) | Q10: =IF(A16="",0,COUNTIFS(업무일지!$B$5:$B$1004,"<="&A16,업무일지!$C$5:$C$1004,">="&A16,업무일지!$D$5:$D$1004,"분석")) | R10: =IF(B16="",0,COUNTIFS(업무일지!$B$5:$B$1004,"<="&B16,업무일지!$C$5:$C$1004,">="&B16,업무일지!$D$5:$D$1004,"분석")) | S10: =IF(C16="",0,COUNTIFS(업무일지!$B$5:$B$1004,"<="&C16,업무일지!$C$5:$C$1004,">="&C16,업무일지!$D$5:$D$1004,"분석")) | T10: =IF(D16="",0,COUNTIFS(업무일지!$B$5:$B$1004,"<="&D16,업무일지!$C$5:$C$1004,">="&D16,업무일지!$D$5:$D$1004,"분석")) | U10: =IF(E16="",0,COUNTIFS(업무일지!$B$5:$B$1004,"<="&E16,업무일지!$C$5:$C$1004,">="&E16,업무일지!$D$5:$D$1004,"분석")) | V10: =IF(F16="",0,COUNTIFS(업무일지!$B$5:$B$1004,"<="&F16,업무일지!$C$5:$C$1004,">="&F16,업무일지!$D$5:$D$1004,"분석")) | W10: =IF(G16="",0,COUNTIFS(업무일지!$B$5:$B$1004,"<="&G16,업무일지!$C$5:$C$1004,">="&G16,업무일지!$D$5:$D$1004,"분석")) | X10: =IF(A16="",0,COUNTIFS(일일실시사항!$B$5:$B$1004,A16)) | Y10: =IF(B16="",0,COUNTIFS(일일실시사항!$B$5:$B$1004,B16)) | Z10: =IF(C16="",0,COUNTIFS(일일실시사항!$B$5:$B$1004,C16)) | AA10: =IF(D16="",0,COUNTIFS(일일실시사항!$B$5:$B$1004,D16)) | AB10: =IF(E16="",0,COUNTIFS(일일실시사항!$B$5:$B$1004,E16)) | AC10: =IF(F16="",0,COUNTIFS(일일실시사항!$B$5:$B$1004,F16)) | AD10: =IF(G16="",0,COUNTIFS(일일실시사항!$B$5:$B$1004,G16))
A11: =IF(A10="","",IF(J8+Q8+X8=0,"",IF(J8=0,"","출장 "&J8&" ")&IF(Q8=0,"","분석 "&Q8&" ")&IF(X8=0,"","일일 "&X8))) | B11: =IF(B10="","",IF(K8+R8+Y8=0,"",IF(K8=0,"","출장 "&K8&" ")&IF(R8=0,"","분석 "&R8&" ")&IF(Y8=0,"","일일 "&Y8))) | C11: =IF(C10="","",IF(L8+S8+Z8=0,"",IF(L8=0,"","출장 "&L8&" ")&IF(S8=0,"","분석 "&S8&" ")&IF(Z8=0,"","일일 "&Z8))) | D11: =IF(D10="","",IF(M8+T8+AA8=0,"",IF(M8=0,"","출장 "&M8&" ")&IF(T8=0,"","분석 "&T8&" ")&IF(AA8=0,"","일일 "&AA8))) | E11: =IF(E10="","",IF(N8+U8+AB8=0,"",IF(N8=0,"","출장 "&N8&" ")&IF(U8=0,"","분석 "&U8&" ")&IF(AB8=0,"","일일 "&AB8))) | F11: =IF(F10="","",IF(O8+V8+AC8=0,"",IF(O8=0,"","출장 "&O8&" ")&IF(V8=0,"","분석 "&V8&" ")&IF(AC8=0,"","일일 "&AC8))) | G11: =IF(G10="","",IF(P8+W8+AD8=0,"",IF(P8=0,"","출장 "&P8&" ")&IF(W8=0,"","분석 "&W8&" ")&IF(AD8=0,"","일일 "&AD8))) | J11: =IF(A19="",0,COUNTIFS(업무일지!$B$5:$B$1004,"<="&A19,업무일지!$C$5:$C$1004,">="&A19,업무일지!$D$5:$D$1004,"출장")) | K11: =IF(B19="",0,COUNTIFS(업무일지!$B$5:$B$1004,"<="&B19,업무일지!$C$5:$C$1004,">="&B19,업무일지!$D$5:$D$1004,"출장")) | L11: =IF(C19="",0,COUNTIFS(업무일지!$B$5:$B$1004,"<="&C19,업무일지!$C$5:$C$1004,">="&C19,업무일지!$D$5:$D$1004,"출장")) | M11: =IF(D19="",0,COUNTIFS(업무일지!$B$5:$B$1004,"<="&D19,업무일지!$C$5:$C$1004,">="&D19,업무일지!$D$5:$D$1004,"출장")) | N11: =IF(E19="",0,COUNTIFS(업무일지!$B$5:$B$1004,"<="&E19,업무일지!$C$5:$C$1004,">="&E19,업무일지!$D$5:$D$1004,"출장")) | O11: =IF(F19="",0,COUNTIFS(업무일지!$B$5:$B$1004,"<="&F19,업무일지!$C$5:$C$1004,">="&F19,업무일지!$D$5:$D$1004,"출장")) | P11: =IF(G19="",0,COUNTIFS(업무일지!$B$5:$B$1004,"<="&G19,업무일지!$C$5:$C$1004,">="&G19,업무일지!$D$5:$D$1004,"출장")) | Q11: =IF(A19="",0,COUNTIFS(업무일지!$B$5:$B$1004,"<="&A19,업무일지!$C$5:$C$1004,">="&A19,업무일지!$D$5:$D$1004,"분석")) | R11: =IF(B19="",0,COUNTIFS(업무일지!$B$5:$B$1004,"<="&B19,업무일지!$C$5:$C$1004,">="&B19,업무일지!$D$5:$D$1004,"분석")) | S11: =IF(C19="",0,COUNTIFS(업무일지!$B$5:$B$1004,"<="&C19,업무일지!$C$5:$C$1004,">="&C19,업무일지!$D$5:$D$1004,"분석")) | T11: =IF(D19="",0,COUNTIFS(업무일지!$B$5:$B$1004,"<="&D19,업무일지!$C$5:$C$1004,">="&D19,업무일지!$D$5:$D$1004,"분석")) | U11: =IF(E19="",0,COUNTIFS(업무일지!$B$5:$B$1004,"<="&E19,업무일지!$C$5:$C$1004,">="&E19,업무일지!$D$5:$D$1004,"분석")) | V11: =IF(F19="",0,COUNTIFS(업무일지!$B$5:$B$1004,"<="&F19,업무일지!$C$5:$C$1004,">="&F19,업무일지!$D$5:$D$1004,"분석")) | W11: =IF(G19="",0,COUNTIFS(업무일지!$B$5:$B$1004,"<="&G19,업무일지!$C$5:$C$1004,">="&G19,업무일지!$D$5:$D$1004,"분석")) | X11: =IF(A19="",0,COUNTIFS(일일실시사항!$B$5:$B$1004,A19)) | Y11: =IF(B19="",0,COUNTIFS(일일실시사항!$B$5:$B$1004,B19)) | Z11: =IF(C19="",0,COUNTIFS(일일실시사항!$B$5:$B$1004,C19)) | AA11: =IF(D19="",0,COUNTIFS(일일실시사항!$B$5:$B$1004,D19)) | AB11: =IF(E19="",0,COUNTIFS(일일실시사항!$B$5:$B$1004,E19)) | AC11: =IF(F19="",0,COUNTIFS(일일실시사항!$B$5:$B$1004,F19)) | AD11: =IF(G19="",0,COUNTIFS(일일실시사항!$B$5:$B$1004,G19))
J12: =IF(A22="",0,COUNTIFS(업무일지!$B$5:$B$1004,"<="&A22,업무일지!$C$5:$C$1004,">="&A22,업무일지!$D$5:$D$1004,"출장")) | K12: =IF(B22="",0,COUNTIFS(업무일지!$B$5:$B$1004,"<="&B22,업무일지!$C$5:$C$1004,">="&B22,업무일지!$D$5:$D$1004,"출장")) | L12: =IF(C22="",0,COUNTIFS(업무일지!$B$5:$B$1004,"<="&C22,업무일지!$C$5:$C$1004,">="&C22,업무일지!$D$5:$D$1004,"출장")) | M12: =IF(D22="",0,COUNTIFS(업무일지!$B$5:$B$1004,"<="&D22,업무일지!$C$5:$C$1004,">="&D22,업무일지!$D$5:$D$1004,"출장")) | N12: =IF(E22="",0,COUNTIFS(업무일지!$B$5:$B$1004,"<="&E22,업무일지!$C$5:$C$1004,">="&E22,업무일지!$D$5:$D$1004,"출장")) | O12: =IF(F22="",0,COUNTIFS(업무일지!$B$5:$B$1004,"<="&F22,업무일지!$C$5:$C$1004,">="&F22,업무일지!$D$5:$D$1004,"출장")) | P12: =IF(G22="",0,COUNTIFS(업무일지!$B$5:$B$1004,"<="&G22,업무일지!$C$5:$C$1004,">="&G22,업무일지!$D$5:$D$1004,"출장")) | Q12: =IF(A22="",0,COUNTIFS(업무일지!$B$5:$B$1004,"<="&A22,업무일지!$C$5:$C$1004,">="&A22,업무일지!$D$5:$D$1004,"분석")) | R12: =IF(B22="",0,COUNTIFS(업무일지!$B$5:$B$1004,"<="&B22,업무일지!$C$5:$C$1004,">="&B22,업무일지!$D$5:$D$1004,"분석")) | S12: =IF(C22="",0,COUNTIFS(업무일지!$B$5:$B$1004,"<="&C22,업무일지!$C$5:$C$1004,">="&C22,업무일지!$D$5:$D$1004,"분석")) | T12: =IF(D22="",0,COUNTIFS(업무일지!$B$5:$B$1004,"<="&D22,업무일지!$C$5:$C$1004,">="&D22,업무일지!$D$5:$D$1004,"분석")) | U12: =IF(E22="",0,COUNTIFS(업무일지!$B$5:$B$1004,"<="&E22,업무일지!$C$5:$C$1004,">="&E22,업무일지!$D$5:$D$1004,"분석")) | V12: =IF(F22="",0,COUNTIFS(업무일지!$B$5:$B$1004,"<="&F22,업무일지!$C$5:$C$1004,">="&F22,업무일지!$D$5:$D$1004,"분석")) | W12: =IF(G22="",0,COUNTIFS(업무일지!$B$5:$B$1004,"<="&G22,업무일지!$C$5:$C$1004,">="&G22,업무일지!$D$5:$D$1004,"분석")) | X12: =IF(A22="",0,COUNTIFS(일일실시사항!$B$5:$B$1004,A22)) | Y12: =IF(B22="",0,COUNTIFS(일일실시사항!$B$5:$B$1004,B22)) | Z12: =IF(C22="",0,COUNTIFS(일일실시사항!$B$5:$B$1004,C22)) | AA12: =IF(D22="",0,COUNTIFS(일일실시사항!$B$5:$B$1004,D22)) | AB12: =IF(E22="",0,COUNTIFS(일일실시사항!$B$5:$B$1004,E22)) | AC12: =IF(F22="",0,COUNTIFS(일일실시사항!$B$5:$B$1004,F22)) | AD12: =IF(G22="",0,COUNTIFS(일일실시사항!$B$5:$B$1004,G22))
A13: =IF(MONTH($H$4+14)<>$D$4,"",$H$4+14) | B13: =IF(MONTH($H$4+15)<>$D$4,"",$H$4+15) | C13: =IF(MONTH($H$4+16)<>$D$4,"",$H$4+16) | D13: =IF(MONTH($H$4+17)<>$D$4,"",$H$4+17) | E13: =IF(MONTH($H$4+18)<>$D$4,"",$H$4+18) | F13: =IF(MONTH($H$4+19)<>$D$4,"",$H$4+19) | G13: =IF(MONTH($H$4+20)<>$D$4,"",$H$4+20)
A14: =IF(A13="","",IF(J9+Q9+X9=0,"",IF(J9=0,"","출장 "&J9&" ")&IF(Q9=0,"","분석 "&Q9&" ")&IF(X9=0,"","일일 "&X9))) | B14: =IF(B13="","",IF(K9+R9+Y9=0,"",IF(K9=0,"","출장 "&K9&" ")&IF(R9=0,"","분석 "&R9&" ")&IF(Y9=0,"","일일 "&Y9))) | C14: =IF(C13="","",IF(L9+S9+Z9=0,"",IF(L9=0,"","출장 "&L9&" ")&IF(S9=0,"","분석 "&S9&" ")&IF(Z9=0,"","일일 "&Z9))) | D14: =IF(D13="","",IF(M9+T9+AA9=0,"",IF(M9=0,"","출장 "&M9&" ")&IF(T9=0,"","분석 "&T9&" ")&IF(AA9=0,"","일일 "&AA9))) | E14: =IF(E13="","",IF(N9+U9+AB9=0,"",IF(N9=0,"","출장 "&N9&" ")&IF(U9=0,"","분석 "&U9&" ")&IF(AB9=0,"","일일 "&AB9))) | F14: =IF(F13="","",IF(O9+V9+AC9=0,"",IF(O9=0,"","출장 "&O9&" ")&IF(V9=0,"","분석 "&V9&" ")&IF(AC9=0,"","일일 "&AC9))) | G14: =IF(G13="","",IF(P9+W9+AD9=0,"",IF(P9=0,"","출장 "&P9&" ")&IF(W9=0,"","분석 "&W9&" ")&IF(AD9=0,"","일일 "&AD9)))
A16: =IF(MONTH($H$4+21)<>$D$4,"",$H$4+21) | B16: =IF(MONTH($H$4+22)<>$D$4,"",$H$4+22) | C16: =IF(MONTH($H$4+23)<>$D$4,"",$H$4+23) | D16: =IF(MONTH($H$4+24)<>$D$4,"",$H$4+24) | E16: =IF(MONTH($H$4+25)<>$D$4,"",$H$4+25) | F16: =IF(MONTH($H$4+26)<>$D$4,"",$H$4+26) | G16: =IF(MONTH($H$4+27)<>$D$4,"",$H$4+27)
A17: =IF(A16="","",IF(J10+Q10+X10=0,"",IF(J10=0,"","출장 "&J10&" ")&IF(Q10=0,"","분석 "&Q10&" ")&IF(X10=0,"","일일 "&X10))) | B17: =IF(B16="","",IF(K10+R10+Y10=0,"",IF(K10=0,"","출장 "&K10&" ")&IF(R10=0,"","분석 "&R10&" ")&IF(Y10=0,"","일일 "&Y10))) | C17: =IF(C16="","",IF(L10+S10+Z10=0,"",IF(L10=0,"","출장 "&L10&" ")&IF(S10=0,"","분석 "&S10&" ")&IF(Z10=0,"","일일 "&Z10))) | D17: =IF(D16="","",IF(M10+T10+AA10=0,"",IF(M10=0,"","출장 "&M10&" ")&IF(T10=0,"","분석 "&T10&" ")&IF(AA10=0,"","일일 "&AA10))) | E17: =IF(E16="","",IF(N10+U10+AB10=0,"",IF(N10=0,"","출장 "&N10&" ")&IF(U10=0,"","분석 "&U10&" ")&IF(AB10=0,"","일일 "&AB10))) | F17: =IF(F16="","",IF(O10+V10+AC10=0,"",IF(O10=0,"","출장 "&O10&" ")&IF(V10=0,"","분석 "&V10&" ")&IF(AC10=0,"","일일 "&AC10))) | G17: =IF(G16="","",IF(P10+W10+AD10=0,"",IF(P10=0,"","출장 "&P10&" ")&IF(W10=0,"","분석 "&W10&" ")&IF(AD10=0,"","일일 "&AD10)))
A19: =IF(MONTH($H$4+28)<>$D$4,"",$H$4+28) | B19: =IF(MONTH($H$4+29)<>$D$4,"",$H$4+29) | C19: =IF(MONTH($H$4+30)<>$D$4,"",$H$4+30) | D19: =IF(MONTH($H$4+31)<>$D$4,"",$H$4+31) | E19: =IF(MONTH($H$4+32)<>$D$4,"",$H$4+32) | F19: =IF(MONTH($H$4+33)<>$D$4,"",$H$4+33) | G19: =IF(MONTH($H$4+34)<>$D$4,"",$H$4+34)
A20: =IF(A19="","",IF(J11+Q11+X11=0,"",IF(J11=0,"","출장 "&J11&" ")&IF(Q11=0,"","분석 "&Q11&" ")&IF(X11=0,"","일일 "&X11))) | B20: =IF(B19="","",IF(K11+R11+Y11=0,"",IF(K11=0,"","출장 "&K11&" ")&IF(R11=0,"","분석 "&R11&" ")&IF(Y11=0,"","일일 "&Y11))) | C20: =IF(C19="","",IF(L11+S11+Z11=0,"",IF(L11=0,"","출장 "&L11&" ")&IF(S11=0,"","분석 "&S11&" ")&IF(Z11=0,"","일일 "&Z11))) | D20: =IF(D19="","",IF(M11+T11+AA11=0,"",IF(M11=0,"","출장 "&M11&" ")&IF(T11=0,"","분석 "&T11&" ")&IF(AA11=0,"","일일 "&AA11))) | E20: =IF(E19="","",IF(N11+U11+AB11=0,"",IF(N11=0,"","출장 "&N11&" ")&IF(U11=0,"","분석 "&U11&" ")&IF(AB11=0,"","일일 "&AB11))) | F20: =IF(F19="","",IF(O11+V11+AC11=0,"",IF(O11=0,"","출장 "&O11&" ")&IF(V11=0,"","분석 "&V11&" ")&IF(AC11=0,"","일일 "&AC11))) | G20: =IF(G19="","",IF(P11+W11+AD11=0,"",IF(P11=0,"","출장 "&P11&" ")&IF(W11=0,"","분석 "&W11&" ")&IF(AD11=0,"","일일 "&AD11)))
A22: =IF(MONTH($H$4+35)<>$D$4,"",$H$4+35) | B22: =IF(MONTH($H$4+36)<>$D$4,"",$H$4+36) | C22: =IF(MONTH($H$4+37)<>$D$4,"",$H$4+37) | D22: =IF(MONTH($H$4+38)<>$D$4,"",$H$4+38) | E22: =IF(MONTH($H$4+39)<>$D$4,"",$H$4+39) | F22: =IF(MONTH($H$4+40)<>$D$4,"",$H$4+40) | G22: =IF(MONTH($H$4+41)<>$D$4,"",$H$4+41)
A23: =IF(A22="","",IF(J12+Q12+X12=0,"",IF(J12=0,"","출장 "&J12&" ")&IF(Q12=0,"","분석 "&Q12&" ")&IF(X12=0,"","일일 "&X12))) | B23: =IF(B22="","",IF(K12+R12+Y12=0,"",IF(K12=0,"","출장 "&K12&" ")&IF(R12=0,"","분석 "&R12&" ")&IF(Y12=0,"","일일 "&Y12))) | C23: =IF(C22="","",IF(L12+S12+Z12=0,"",IF(L12=0,"","출장 "&L12&" ")&IF(S12=0,"","분석 "&S12&" ")&IF(Z12=0,"","일일 "&Z12))) | D23: =IF(D22="","",IF(M12+T12+AA12=0,"",IF(M12=0,"","출장 "&M12&" ")&IF(T12=0,"","분석 "&T12&" ")&IF(AA12=0,"","일일 "&AA12))) | E23: =IF(E22="","",IF(N12+U12+AB12=0,"",IF(N12=0,"","출장 "&N12&" ")&IF(U12=0,"","분석 "&U12&" ")&IF(AB12=0,"","일일 "&AB12))) | F23: =IF(F22="","",IF(O12+V12+AC12=0,"",IF(O12=0,"","출장 "&O12&" ")&IF(V12=0,"","분석 "&V12&" ")&IF(AC12=0,"","일일 "&AC12))) | G23: =IF(G22="","",IF(P12+W12+AD12=0,"",IF(P12=0,"","출장 "&P12&" ")&IF(W12=0,"","분석 "&W12&" ")&IF(AD12=0,"","일일 "&AD12)))
A26: 이달 요약
A27: 구분 | B27: 건수 | C27: 총 인시(H) | D27: 출장 소요일수 | E27: 대상매체(건) | F27: 데이터량(GB) | G27: 진행중
A28: 출장 | B28: =COUNTIFS(업무일지!$B$5:$B$1004,">="&DATE($B$4,$D$4,1),업무일지!$B$5:$B$1004,"<"&DATE($B$4,$D$4+1,1),업무일지!$D$5:$D$1004,"출장") | C28: =SUMIFS(업무일지!$W$5:$W$1004,업무일지!$B$5:$B$1004,">="&DATE($B$4,$D$4,1),업무일지!$B$5:$B$1004,"<"&DATE($B$4,$D$4+1,1),업무일지!$D$5:$D$1004,"출장") | D28: =SUMIFS(업무일지!$U$5:$U$1004,업무일지!$B$5:$B$1004,">="&DATE($B$4,$D$4,1),업무일지!$B$5:$B$1004,"<"&DATE($B$4,$D$4+1,1),업무일지!$D$5:$D$1004,"출장") | E28: =SUMIFS(업무일지!$S$5:$S$1004,업무일지!$B$5:$B$1004,">="&DATE($B$4,$D$4,1),업무일지!$B$5:$B$1004,"<"&DATE($B$4,$D$4+1,1),업무일지!$D$5:$D$1004,"출장") | F28: =SUMIFS(업무일지!$T$5:$T$1004,업무일지!$B$5:$B$1004,">="&DATE($B$4,$D$4,1),업무일지!$B$5:$B$1004,"<"&DATE($B$4,$D$4+1,1),업무일지!$D$5:$D$1004,"출장") | G28: =COUNTIFS(업무일지!$B$5:$B$1004,">="&DATE($B$4,$D$4,1),업무일지!$B$5:$B$1004,"<"&DATE($B$4,$D$4+1,1),업무일지!$D$5:$D$1004,"출장",업무일지!$X$5:$X$1004,"진행중")
A29: 분석 | B29: =COUNTIFS(업무일지!$B$5:$B$1004,">="&DATE($B$4,$D$4,1),업무일지!$B$5:$B$1004,"<"&DATE($B$4,$D$4+1,1),업무일지!$D$5:$D$1004,"분석") | C29: =SUMIFS(업무일지!$W$5:$W$1004,업무일지!$B$5:$B$1004,">="&DATE($B$4,$D$4,1),업무일지!$B$5:$B$1004,"<"&DATE($B$4,$D$4+1,1),업무일지!$D$5:$D$1004,"분석") | D29: =SUMIFS(업무일지!$U$5:$U$1004,업무일지!$B$5:$B$1004,">="&DATE($B$4,$D$4,1),업무일지!$B$5:$B$1004,"<"&DATE($B$4,$D$4+1,1),업무일지!$D$5:$D$1004,"분석") | E29: =SUMIFS(업무일지!$S$5:$S$1004,업무일지!$B$5:$B$1004,">="&DATE($B$4,$D$4,1),업무일지!$B$5:$B$1004,"<"&DATE($B$4,$D$4+1,1),업무일지!$D$5:$D$1004,"분석") | F29: =SUMIFS(업무일지!$T$5:$T$1004,업무일지!$B$5:$B$1004,">="&DATE($B$4,$D$4,1),업무일지!$B$5:$B$1004,"<"&DATE($B$4,$D$4+1,1),업무일지!$D$5:$D$1004,"분석") | G29: =COUNTIFS(업무일지!$B$5:$B$1004,">="&DATE($B$4,$D$4,1),업무일지!$B$5:$B$1004,"<"&DATE($B$4,$D$4+1,1),업무일지!$D$5:$D$1004,"분석",업무일지!$X$5:$X$1004,"진행중")
A30: 일일실시 | B30: =COUNTIFS(일일실시사항!$B$5:$B$1004,">="&DATE($B$4,$D$4,1),일일실시사항!$B$5:$B$1004,"<"&DATE($B$4,$D$4+1,1)) | C30: =SUMIFS(일일실시사항!$J$5:$J$1004,일일실시사항!$B$5:$B$1004,">="&DATE($B$4,$D$4,1),일일실시사항!$B$5:$B$1004,"<"&DATE($B$4,$D$4+1,1)) | D30: - | E30: - | F30: - | G30: =COUNTIFS(일일실시사항!$B$5:$B$1004,">="&DATE($B$4,$D$4,1),일일실시사항!$B$5:$B$1004,"<"&DATE($B$4,$D$4+1,1),일일실시사항!$K$5:$K$1004,"진행중")
A31: 합계 | B31: =SUM(B28:B30) | C31: =SUM(C28:C30) | D31: =SUM(D28:D29) | E31: =SUM(E28:E29) | F31: =SUM(F28:F29) | G31: =SUM(G28:G30)
A33: ※ 달력 칸의 자동 집계는 [업무일지]의 시작일~종료일 기간에 걸친 건과 [일일실시사항]의 해당 일자 건을 셉니다.
A34: ※ 오늘 날짜는 초록색, 공휴일([코드설정] K열)과 일요일은 빨간색으로 표시됩니다.

Sheet 업무일지
A1: 부서 업무일지 · 출장 / 분석 통합 대장
A2: ※ 출장·분석 1건 = 1행. 사건번호(F)를 고르면 사건명·요청처와 [사건마스터]에 배정된 담당자(I~N)가 통째로 따라옵니다. ※ 그 건에만 인원이 다르면 I~N칸을 직접 골라 덮어쓰세요(그 행만 수동으로 바뀝니다). ※ 파란 글씨 칸만 입력 / 초록 글씨는 사건마스터 연동 / 회색 칸은 자동. ※ 5행은 예시이므로 지우고 사용하세요.
A4: 연번 | B4: 시작일 | C4: 종료일 | D4: 직무구분 | E4: 세부유형 | F4: 사건번호 | G4: 사건명 · 업무명 | H4: 요청·의뢰처 | I4: 주담당자 | J4: 참여자 1 | K4: 참여자 2 | L4: 참여자 3 | M4: 참여자 4 | N4: 참여자 5 | O4: 투입인원(명) | P4: 참여자 명단(자동) | Q4: 소속팀 | R4: 장소 / 분석실 | S4: 대상매체(건) | T4: 데이터량(GB) | U4: 소요일수 | V4: 1인 투입시간(H) | W4: 총 인시(H) | X4: 진행상태 | Y4: 비고
A5: =IF($B5="","",COUNT($B$5:$B5)) | B5: 46085 | C5: 46086 | D5: 출장 | E5: 압수·수색 집행 | F5: 2026-형제-1024 | G5: =IF($F5="","",IFERROR(INDEX(사건마스터!$B$5:$B$64,MATCH($F5,사건마스터!$A$5:$A$64,0)),"")) | H5: =IF($F5="","",IFERROR(INDEX(사건마스터!$C$5:$C$64,MATCH($F5,사건마스터!$A$5:$A$64,0)),"")) | I5: =IF($F5="","",IFERROR(INDEX(사건마스터!$H$5:$H$64,MATCH($F5,사건마스터!$A$5:$A$64,0)),"")) | J5: =IF($F5="","",IFERROR(INDEX(사건마스터!$AH$5:$AH$64,MATCH($F5,사건마스터!$A$5:$A$64,0)),"")) | K5: =IF($F5="","",IFERROR(INDEX(사건마스터!$AI$5:$AI$64,MATCH($F5,사건마스터!$A$5:$A$64,0)),"")) | L5: =IF($F5="","",IFERROR(INDEX(사건마스터!$AJ$5:$AJ$64,MATCH($F5,사건마스터!$A$5:$A$64,0)),"")) | M5: =IF($F5="","",IFERROR(INDEX(사건마스터!$AK$5:$AK$64,MATCH($F5,사건마스터!$A$5:$A$64,0)),"")) | N5: =IF($F5="","",IFERROR(INDEX(사건마스터!$AL$5:$AL$64,MATCH($F5,사건마스터!$A$5:$A$64,0)),"")) | O5: =IF($I5="","",COUNTIF($I5:$N5,"?*")) | P5: =IF($I5="","",_xlfn.TEXTJOIN(", ",TRUE,$I5:$N5)) | Q5: =IF($I5="","",IFERROR(INDEX(코드설정!$D$5:$D$24,MATCH($I5,코드설정!$C$5:$C$24,0)),"")) | R5: 경기 성남시 판교 | S5: 6 | T5: 3200 | U5: =IF(OR($B5="",$C5=""),"",$C5-$B5+1) | V5: 16 | W5: =IF(OR($V5="",$O5=""),"",$V5*$O5) | X5: 완료 | Y5: ※ 예시 - 지우고 사용하세요
A6: =IF($B6="","",COUNT($B$5:$B6)) | G6: =IF($F6="","",IFERROR(INDEX(사건마스터!$B$5:$B$64,MATCH($F6,사건마스터!$A$5:$A$64,0)),"")) | H6: =IF($F6="","",IFERROR(INDEX(사건마스터!$C$5:$C$64,MATCH($F6,사건마스터!$A$5:$A$64,0)),"")) | I6: =IF($F6="","",IFERROR(INDEX(사건마스터!$H$5:$H$64,MATCH($F6,사건마스터!$A$5:$A$64,0)),"")) | J6: =IF($F6="","",IFERROR(INDEX(사건마스터!$AH$5:$AH$64,MATCH($F6,사건마스터!$A$5:$A$64,0)),"")) | K6: =IF($F6="","",IFERROR(INDEX(사건마스터!$AI$5:$AI$64,MATCH($F6,사건마스터!$A$5:$A$64,0)),"")) | L6: =IF($F6="","",IFERROR(INDEX(사건마스터!$AJ$5:$AJ$64,MATCH($F6,사건마스터!$A$5:$A$64,0)),"")) | M6: =IF($F6="","",IFERROR(INDEX(사건마스터!$AK$5:$AK$64,MATCH($F6,사건마스터!$A$5:$A$64,0)),"")) | N6: =IF($F6="","",IFERROR(INDEX(사건마스터!$AL$5:$AL$64,MATCH($F6,사건마스터!$A$5:$A$64,0)),"")) | O6: =IF($I6="","",COUNTIF($I6:$N6,"?*")) | P6: =IF($I6="","",_xlfn.TEXTJOIN(", ",TRUE,$I6:$N6)) | Q6: =IF($I6="","",IFERROR(INDEX(코드설정!$D$5:$D$24,MATCH($I6,코드설정!$C$5:$C$24,0)),"")) | U6: =IF(OR($B6="",$C6=""),"",$C6-$B6+1) | W6: =IF(OR($V6="",$O6=""),"",$V6*$O6)
A7: =IF($B7="","",COUNT($B$5:$B7)) | G7: =IF($F7="","",IFERROR(INDEX(사건마스터!$B$5:$B$64,MATCH($F7,사건마스터!$A$5:$A$64,0)),"")) | H7: =IF($F7="","",IFERROR(INDEX(사건마스터!$C$5:$C$64,MATCH($F7,사건마스터!$A$5:$A$64,0)),"")) | I7: =IF($F7="","",IFERROR(INDEX(사건마스터!$H$5:$H$64,MATCH($F7,사건마스터!$A$5:$A$64,0)),"")) | J7: =IF($F7="","",IFERROR(INDEX(사건마스터!$AH$5:$AH$64,MATCH($F7,사건마스터!$A$5:$A$64,0)),"")) | K7: =IF($F7="","",IFERROR(INDEX(사건마스터!$AI$5:$AI$64,MATCH($F7,사건마스터!$A$5:$A$64,0)),"")) | L7: =IF($F7="","",IFERROR(INDEX(사건마스터!$AJ$5:$AJ$64,MATCH($F7,사건마스터!$A$5:$A$64,0)),"")) | M7: =IF($F7="","",IFERROR(INDEX(사건마스터!$AK$5:$AK$64,MATCH($F7,사건마스터!$A$5:$A$64,0)),"")) | N7: =IF($F7="","",IFERROR(INDEX(사건마스터!$AL$5:$AL$64,MATCH($F7,사건마스터!$A$5:$A$64,0)),"")) | O7: =IF($I7="","",COUNTIF($I7:$N7,"?*")) | P7: =IF($I7="","",_xlfn.TEXTJOIN(", ",TRUE,$I7:$N7)) | Q7: =IF($I7="","",IFERROR(INDEX(코드설정!$D$5:$D$24,MATCH($I7,코드설정!$C$5:$C$24,0)),"")) | U7: =IF(OR($B7="",$C7=""),"",$C7-$B7+1) | W7: =IF(OR($V7="",$O7=""),"",$V7*$O7)
A8: =IF($B8="","",COUNT($B$5:$B8)) | G8: =IF($F8="","",IFERROR(INDEX(사건마스터!$B$5:$B$64,MATCH($F8,사건마스터!$A$5:$A$64,0)),"")) | H8: =IF($F8="","",IFERROR(INDEX(사건마스터!$C$5:$C$64,MATCH($F8,사건마스터!$A$5:$A$64,0)),"")) | I8: =IF($F8="","",IFERROR(INDEX(사건마스터!$H$5:$H$64,MATCH($F8,사건마스터!$A$5:$A$64,0)),"")) | J8: =IF($F8="","",IFERROR(INDEX(사건마스터!$AH$5:$AH$64,MATCH($F8,사건마스터!$A$5:$A$64,0)),"")) | K8: =IF($F8="","",IFERROR(INDEX(사건마스터!$AI$5:$AI$64,MATCH($F8,사건마스터!$A$5:$A$64,0)),"")) | L8: =IF($F8="","",IFERROR(INDEX(사건마스터!$AJ$5:$AJ$64,MATCH($F8,사건마스터!$A$5:$A$64,0)),"")) | M8: =IF($F8="","",IFERROR(INDEX(사건마스터!$AK$5:$AK$64,MATCH($F8,사건마스터!$A$5:$A$64,0)),"")) | N8: =IF($F8="","",IFERROR(INDEX(사건마스터!$AL$5:$AL$64,MATCH($F8,사건마스터!$A$5:$A$64,0)),"")) | O8: =IF($I8="","",COUNTIF($I8:$N8,"?*")) | P8: =IF($I8="","",_xlfn.TEXTJOIN(", ",TRUE,$I8:$N8)) | Q8: =IF($I8="","",IFERROR(INDEX(코드설정!$D$5:$D$24,MATCH($I8,코드설정!$C$5:$C$24,0)),"")) | U8: =IF(OR($B8="",$C8=""),"",$C8-$B8+1) | W8: =IF(OR($V8="",$O8=""),"",$V8*$O8)
A9: =IF($B9="","",COUNT($B$5:$B9)) | G9: =IF($F9="","",IFERROR(INDEX(사건마스터!$B$5:$B$64,MATCH($F9,사건마스터!$A$5:$A$64,0)),"")) | H9: =IF($F9="","",IFERROR(INDEX(사건마스터!$C$5:$C$64,MATCH($F9,사건마스터!$A$5:$A$64,0)),"")) | I9: =IF($F9="","",IFERROR(INDEX(사건마스터!$H$5:$H$64,MATCH($F9,사건마스터!$A$5:$A$64,0)),"")) | J9: =IF($F9="","",IFERROR(INDEX(사건마스터!$AH$5:$AH$64,MATCH($F9,사건마스터!$A$5:$A$64,0)),"")) | K9: =IF($F9="","",IFERROR(INDEX(사건마스터!$AI$5:$AI$64,MATCH($F9,사건마스터!$A$5:$A$64,0)),"")) | L9: =IF($F9="","",IFERROR(INDEX(사건마스터!$AJ$5:$AJ$64,MATCH($F9,사건마스터!$A$5:$A$64,0)),"")) | M9: =IF($F9="","",IFERROR(INDEX(사건마스터!$AK$5:$AK$64,MATCH($F9,사건마스터!$A$5:$A$64,0)),"")) | N9: =IF($F9="","",IFERROR(INDEX(사건마스터!$AL$5:$AL$64,MATCH($F9,사건마스터!$A$5:$A$64,0)),"")) | O9: =IF($I9="","",COUNTIF($I9:$N9,"?*")) | P9: =IF($I9="","",_xlfn.TEXTJOIN(", ",TRUE,$I9:$N9)) | Q9: =IF($I9="","",IFERROR(INDEX(코드설정!$D$5:$D$24,MATCH($I9,코드설정!$C$5:$C$24,0)),"")) | U9: =IF(OR($B9="",$C9=""),"",$C9-$B9+1) | W9: =IF(OR($V9="",$O9=""),"",$V9*$O9)
A10: =IF($B10="","",COUNT($B$5:$B10)) | G10: =IF($F10="","",IFERROR(INDEX(사건마스터!$B$5:$B$64,MATCH($F10,사건마스터!$A$5:$A$64,0)),"")) | H10: =IF($F10="","",IFERROR(INDEX(사건마스터!$C$5:$C$64,MATCH($F10,사건마스터!$A$5:$A$64,0)),"")) | I10: =IF($F10="","",IFERROR(INDEX(사건마스터!$H$5:$H$64,MATCH($F10,사건마스터!$A$5:$A$64,0)),"")) | J10: =IF($F10="","",IFERROR(INDEX(사건마스터!$AH$5:$AH$64,MATCH($F10,사건마스터!$A$5:$A$64,0)),"")) | K10: =IF($F10="","",IFERROR(INDEX(사건마스터!$AI$5:$AI$64,MATCH($F10,사건마스터!$A$5:$A$64,0)),"")) | L10: =IF($F10="","",IFERROR(INDEX(사건마스터!$AJ$5:$AJ$64,MATCH($F10,사건마스터!$A$5:$A$64,0)),"")) | M10: =IF($F10="","",IFERROR(INDEX(사건마스터!$AK$5:$AK$64,MATCH($F10,사건마스터!$A$5:$A$64,0)),"")) | N10: =IF($F10="","",IFERROR(INDEX(사건마스터!$AL$5:$AL$64,MATCH($F10,사건마스터!$A$5:$A$64,0)),"")) | O10: =IF($I10="","",COUNTIF($I10:$N10,"?*")) | P10: =IF($I10="","",_xlfn.TEXTJOIN(", ",TRUE,$I10:$N10)) | Q10: =IF($I10="","",IFERROR(INDEX(코드설정!$D$5:$D$24,MATCH($I10,코드설정!$C$5:$C$24,0)),"")) | U10: =IF(OR($B10="",$C10=""),"",$C10-$B10+1) | W10: =IF(OR($V10="",$O10=""),"",$V10*$O10)
A11: =IF($B11="","",COUNT($B$5:$B11)) | G11: =IF($F11="","",IFERROR(INDEX(사건마스터!$B$5:$B$64,MATCH($F11,사건마스터!$A$5:$A$64,0)),"")) | H11: =IF($F11="","",IFERROR(INDEX(사건마스터!$C$5:$C$64,MATCH($F11,사건마스터!$A$5:$A$64,0)),"")) | I11: =IF($F11="","",IFERROR(INDEX(사건마스터!$H$5:$H$64,MATCH($F11,사건마스터!$A$5:$A$64,0)),"")) | J11: =IF($F11="","",IFERROR(INDEX(사건마스터!$AH$5:$AH$64,MATCH($F11,사건마스터!$A$5:$A$64,0)),"")) | K11: =IF($F11="","",IFERROR(INDEX(사건마스터!$AI$5:$AI$64,MATCH($F11,사건마스터!$A$5:$A$64,0)),"")) | L11: =IF($F11="","",IFERROR(INDEX(사건마스터!$AJ$5:$AJ$64,MATCH($F11,사건마스터!$A$5:$A$64,0)),"")) | M11: =IF($F11="","",IFERROR(INDEX(사건마스터!$AK$5:$AK$64,MATCH($F11,사건마스터!$A$5:$A$64,0)),"")) | N11: =IF($F11="","",IFERROR(INDEX(사건마스터!$AL$5:$AL$64,MATCH($F11,사건마스터!$A$5:$A$64,0)),"")) | O11: =IF($I11="","",COUNTIF($I11:$N11,"?*")) | P11: =IF($I11="","",_xlfn.TEXTJOIN(", ",TRUE,$I11:$N11)) | Q11: =IF($I11="","",IFERROR(INDEX(코드설정!$D$5:$D$24,MATCH($I11,코드설정!$C$5:$C$24,0)),"")) | U11: =IF(OR($B11="",$C11=""),"",$C11-$B11+1) | W11: =IF(OR($V11="",$O11=""),"",$V11*$O11)
A12: =IF($B12="","",COUNT($B$5:$B12)) | G12: =IF($F12="","",IFERROR(INDEX(사건마스터!$B$5:$B$64,MATCH($F12,사건마스터!$A$5:$A$64,0)),"")) | H12: =IF($F12="","",IFERROR(INDEX(사건마스터!$C$5:$C$64,MATCH($F12,사건마스터!$A$5:$A$64,0)),"")) | I12: =IF($F12="","",IFERROR(INDEX(사건마스터!$H$5:$H$64,MATCH($F12,사건마스터!$A$5:$A$64,0)),"")) | J12: =IF($F12="","",IFERROR(INDEX(사건마스터!$AH$5:$AH$64,MATCH($F12,사건마스터!$A$5:$A$64,0)),"")) | K12: =IF($F12="","",IFERROR(INDEX(사건마스터!$AI$5:$AI$64,MATCH($F12,사건마스터!$A$5:$A$64,0)),"")) | L12: =IF($F12="","",IFERROR(INDEX(사건마스터!$AJ$5:$AJ$64,MATCH($F12,사건마스터!$A$5:$A$64,0)),"")) | M12: =IF($F12="","",IFERROR(INDEX(사건마스터!$AK$5:$AK$64,MATCH($F12,사건마스터!$A$5:$A$64,0)),"")) | N12: =IF($F12="","",IFERROR(INDEX(사건마스터!$AL$5:$AL$64,MATCH($F12,사건마스터!$A$5:$A$64,0)),"")) | O12: =IF($I12="","",COUNTIF($I12:$N12,"?*")) | P12: =IF($I12="","",_xlfn.TEXTJOIN(", ",TRUE,$I12:$N12)) | Q12: =IF($I12="","",IFERROR(INDEX(코드설정!$D$5:$D$24,MATCH($I12,코드설정!$C$5:$C$24,0)),"")) | U12: =IF(OR($B12="",$C12=""),"",$C12-$B12+1) | W12: =IF(OR($V12="",$O12=""),"",$V12*$O12)
A13: =IF($B13="","",COUNT($B$5:$B13)) | G13: =IF($F13="","",IFERROR(INDEX(사건마스터!$B$5:$B$64,MATCH($F13,사건마스터!$A$5:$A$64,0)),"")) | H13: =IF($F13="","",IFERROR(INDEX(사건마스터!$C$5:$C$64,MATCH($F13,사건마스터!$A$5:$A$64,0)),"")) | I13: =IF($F13="","",IFERROR(INDEX(사건마스터!$H$5:$H$64,MATCH($F13,사건마스터!$A$5:$A$64,0)),"")) | J13: =IF($F13="","",IFERROR(INDEX(사건마스터!$AH$5:$AH$64,MATCH($F13,사건마스터!$A$5:$A$64,0)),"")) | K13: =IF($F13="","",IFERROR(INDEX(사건마스터!$AI$5:$AI$64,MATCH($F13,사건마스터!$A$5:$A$64,0)),"")) | L13: =IF($F13="","",IFERROR(INDEX(사건마스터!$AJ$5:$AJ$64,MATCH($F13,사건마스터!$A$5:$A$64,0)),"")) | M13: =IF($F13="","",IFERROR(INDEX(사건마스터!$AK$5:$AK$64,MATCH($F13,사건마스터!$A$5:$A$64,0)),"")) | N13: =IF($F13="","",IFERROR(INDEX(사건마스터!$AL$5:$AL$64,MATCH($F13,사건마스터!$A$5:$A$64,0)),"")) | O13: =IF($I13="","",COUNTIF($I13:$N13,"?*")) | P13: =IF($I13="","",_xlfn.TEXTJOIN(", ",TRUE,$I13:$N13)) | Q13: =IF($I13="","",IFERROR(INDEX(코드설정!$D$5:$D$24,MATCH($I13,코드설정!$C$5:$C$24,0)),"")) | U13: =IF(OR($B13="",$C13=""),"",$C13-$B13+1) | W13: =IF(OR($V13="",$O13=""),"",$V13*$O13)
A14: =IF($B14="","",COUNT($B$5:$B14)) | G14: =IF($F14="","",IFERROR(INDEX(사건마스터!$B$5:$B$64,MATCH($F14,사건마스터!$A$5:$A$64,0)),"")) | H14: =IF($F14="","",IFERROR(INDEX(사건마스터!$C$5:$C$64,MATCH($F14,사건마스터!$A$5:$A$64,0)),"")) | I14: =IF($F14="","",IFERROR(INDEX(사건마스터!$H$5:$H$64,MATCH($F14,사건마스터!$A$5:$A$64,0)),"")) | J14: =IF($F14="","",IFERROR(INDEX(사건마스터!$AH$5:$AH$64,MATCH($F14,사건마스터!$A$5:$A$64,0)),"")) | K14: =IF($F14="","",IFERROR(INDEX(사건마스터!$AI$5:$AI$64,MATCH($F14,사건마스터!$A$5:$A$64,0)),"")) | L14: =IF($F14="","",IFERROR(INDEX(사건마스터!$AJ$5:$AJ$64,MATCH($F14,사건마스터!$A$5:$A$64,0)),"")) | M14: =IF($F14="","",IFERROR(INDEX(사건마스터!$AK$5:$AK$64,MATCH($F14,사건마스터!$A$5:$A$64,0)),"")) | N14: =IF($F14="","",IFERROR(INDEX(사건마스터!$AL$5:$AL$64,MATCH($F14,사건마스터!$A$5:$A$64,0)),"")) | O14: =IF($I14="","",COUNTIF($I14:$N14,"?*")) | P14: =IF($I14="","",_xlfn.TEXTJOIN(", ",TRUE,$I14:$N14)) | Q14: =IF($I14="","",IFERROR(INDEX(코드설정!$D$5:$D$24,MATCH($I14,코드설정!$C$5:$C$24,0)),"")) | U14: =IF(OR($B14="",$C14=""),"",$C14-$B14+1) | W14: =IF(OR($V14="",$O14=""),"",$V14*$O14)
A15: =IF($B15="","",COUNT($B$5:$B15)) | G15: =IF($F15="","",IFERROR(INDEX(사건마스터!$B$5:$B$64,MATCH($F15,사건마스터!$A$5:$A$64,0)),"")) | H15: =IF($F15="","",IFERROR(INDEX(사건마스터!$C$5:$C$64,MATCH($F15,사건마스터!$A$5:$A$64,0)),"")) | I15: =IF($F15="","",IFERROR(INDEX(사건마스터!$H$5:$H$64,MATCH($F15,사건마스터!$A$5:$A$64,0)),"")) | J15: =IF($F15="","",IFERROR(INDEX(사건마스터!$AH$5:$AH$64,MATCH($F15,사건마스터!$A$5:$A$64,0)),"")) | K15: =IF($F15="","",IFERROR(INDEX(사건마스터!$AI$5:$AI$64,MATCH($F15,사건마스터!$A$5:$A$64,0)),"")) | L15: =IF($F15="","",IFERROR(INDEX(사건마스터!$AJ$5:$AJ$64,MATCH($F15,사건마스터!$A$5:$A$64,0)),"")) | M15: =IF($F15="","",IFERROR(INDEX(사건마스터!$AK$5:$AK$64,MATCH($F15,사건마스터!$A$5:$A$64,0)),"")) | N15: =IF($F15="","",IFERROR(INDEX(사건마스터!$AL$5:$AL$64,MATCH($F15,사건마스터!$A$5:$A$64,0)),"")) | O15: =IF($I15="","",COUNTIF($I15:$N15,"?*")) | P15: =IF($I15="","",_xlfn.TEXTJOIN(", ",TRUE,$I15:$N15)) | Q15: =IF($I15="","",IFERROR(INDEX(코드설정!$D$5:$D$24,MATCH($I15,코드설정!$C$5:$C$24,0)),"")) | U15: =IF(OR($B15="",$C15=""),"",$C15-$B15+1) | W15: =IF(OR($V15="",$O15=""),"",$V15*$O15)
A16: =IF($B16="","",COUNT($B$5:$B16)) | G16: =IF($F16="","",IFERROR(INDEX(사건마스터!$B$5:$B$64,MATCH($F16,사건마스터!$A$5:$A$64,0)),"")) | H16: =IF($F16="","",IFERROR(INDEX(사건마스터!$C$5:$C$64,MATCH($F16,사건마스터!$A$5:$A$64,0)),"")) | I16: =IF($F16="","",IFERROR(INDEX(사건마스터!$H$5:$H$64,MATCH($F16,사건마스터!$A$5:$A$64,0)),"")) | J16: =IF($F16="","",IFERROR(INDEX(사건마스터!$AH$5:$AH$64,MATCH($F16,사건마스터!$A$5:$A$64,0)),"")) | K16: =IF($F16="","",IFERROR(INDEX(사건마스터!$AI$5:$AI$64,MATCH($F16,사건마스터!$A$5:$A$64,0)),"")) | L16: =IF($F16="","",IFERROR(INDEX(사건마스터!$AJ$5:$AJ$64,MATCH($F16,사건마스터!$A$5:$A$64,0)),"")) | M16: =IF($F16="","",IFERROR(INDEX(사건마스터!$AK$5:$AK$64,MATCH($F16,사건마스터!$A$5:$A$64,0)),"")) | N16: =IF($F16="","",IFERROR(INDEX(사건마스터!$AL$5:$AL$64,MATCH($F16,사건마스터!$A$5:$A$64,0)),"")) | O16: =IF($I16="","",COUNTIF($I16:$N16,"?*")) | P16: =IF($I16="","",_xlfn.TEXTJOIN(", ",TRUE,$I16:$N16)) | Q16: =IF($I16="","",IFERROR(INDEX(코드설정!$D$5:$D$24,MATCH($I16,코드설정!$C$5:$C$24,0)),"")) | U16: =IF(OR($B16="",$C16=""),"",$C16-$B16+1) | W16: =IF(OR($V16="",$O16=""),"",$V16*$O16)
A17: =IF($B17="","",COUNT($B$5:$B17)) | G17: =IF($F17="","",IFERROR(INDEX(사건마스터!$B$5:$B$64,MATCH($F17,사건마스터!$A$5:$A$64,0)),"")) | H17: =IF($F17="","",IFERROR(INDEX(사건마스터!$C$5:$C$64,MATCH($F17,사건마스터!$A$5:$A$64,0)),"")) | I17: =IF($F17="","",IFERROR(INDEX(사건마스터!$H$5:$H$64,MATCH($F17,사건마스터!$A$5:$A$64,0)),"")) | J17: =IF($F17="","",IFERROR(INDEX(사건마스터!$AH$5:$AH$64,MATCH($F17,사건마스터!$A$5:$A$64,0)),"")) | K17: =IF($F17="","",IFERROR(INDEX(사건마스터!$AI$5:$AI$64,MATCH($F17,사건마스터!$A$5:$A$64,0)),"")) | L17: =IF($F17="","",IFERROR(INDEX(사건마스터!$AJ$5:$AJ$64,MATCH($F17,사건마스터!$A$5:$A$64,0)),"")) | M17: =IF($F17="","",IFERROR(INDEX(사건마스터!$AK$5:$AK$64,MATCH($F17,사건마스터!$A$5:$A$64,0)),"")) | N17: =IF($F17="","",IFERROR(INDEX(사건마스터!$AL$5:$AL$64,MATCH($F17,사건마스터!$A$5:$A$64,0)),"")) | O17: =IF($I17="","",COUNTIF($I17:$N17,"?*")) | P17: =IF($I17="","",_xlfn.TEXTJOIN(", ",TRUE,$I17:$N17)) | Q17: =IF($I17="","",IFERROR(INDEX(코드설정!$D$5:$D$24,MATCH($I17,코드설정!$C$5:$C$24,0)),"")) | U17: =IF(OR($B17="",$C17=""),"",$C17-$B17+1) | W17: =IF(OR($V17="",$O17=""),"",$V17*$O17)
... A1004: =IF($B1004="","",COUNT($B$5:$B1004)) | G1004: =IF($F1004="","",IFERROR(INDEX(사건마스터!$B$5:$B$64,MATCH($F1004,사건마스터!$A$5:$A$64,0)),"")) | H1004: =IF($F1004="","",IFERROR(INDEX(사건마스터!$C$5:$C$64,MATCH($F1004,사건마스터!$A$5:$A$64,0)),"")) | I1004: =IF($F1004="","",IFERROR(INDEX(사건마스터!$H$5:$H$64,MATCH($F1004,사건마스터!$A$5:$A$64,0)),"")) | J1004: =IF($F1004="","",IFERROR(INDEX(사건마스터!$AH$5:$AH$64,MATCH($F1004,사건마스터!$A$5:$A$64,0)),"")) | K1004: =IF($F1004="","",IFERROR(INDEX(사건마스터!$AI$5:$AI$64,MATCH($F1004,사건마스터!$A$5:$A$64,0)),"")) | L1004: =IF($F1004="","",IFERROR(INDEX(사건마스터!$AJ$5:$AJ$64,MATCH($F1004,사건마스터!$A$5:$A$64,0)),"")) | M1004: =IF($F1004="","",IFERROR(INDEX(사건마스터!$AK$5:$AK$64,MATCH($F1004,사건마스터!$A$5:$A$64,0)),"")) | N1004: =IF($F1004="","",IFERROR(INDEX(사건마스터!$AL$5:$AL$64,MATCH($F1004,사건마스터!$A$5:$A$64,0)),"")) | O1004: =IF($I1004="","",COUNTIF($I1004:$N1004,"?*")) | P1004: =IF($I1004="","",_xlfn.TEXTJOIN(", ",TRUE,$I1004:$N1004)) | Q1004: =IF($I1004="","",IFERROR(INDEX(코드설정!$D$5:$D$24,MATCH($I1004,코드설정!$C$5:$C$24,0)),"")) | U1004: =IF(OR($B1004="",$C1004=""),"",$C1004-$B1004+1) | W1004: =IF(OR($V1004="",$O1004=""),"",$V1004*$O1004)

Sheet 일일실시사항
A1: 일일 실시사항 · 부서 일일 업무 기록
A2: ※ 출장·분석 외 부서의 모든 일일 업무를 여기에 기록합니다(행정·교육·회의·장비관리·당직 등). ※ 하루에 여러 건이면 여러 행으로 나눠 쓰세요. ※ 파란 글씨 칸만 입력 / 회색 칸은 자동.
A4: 연번 | B4: 일자 | C4: 요일 | D4: 담당자 | E4: 소속팀 | F4: 업무구분 | G4: 관련 사건번호 | H4: 실시 내용 | I4: 조치 · 결과 | J4: 투입시간(H) | K4: 진행상태 | L4: 특이사항 / 후속조치
A5: =IF($B5="","",COUNT($B$5:$B5)) | B5: 46087 | C5: =IF($B5="","",CHOOSE(WEEKDAY($B5),"일","월","화","수","목","금","토")) | D5: 최분석 | E5: =IF($D5="","",IFERROR(INDEX(코드설정!$D$5:$D$24,MATCH($D5,코드설정!$C$5:$C$24,0)),"")) | F5: 장비·시스템 관리 | H5: 포렌식 워크스테이션 2호기 이미징 장비 점검 및 펌웨어 업데이트 | I5: 정상 완료, 검증용 해시 테스트 통과 | J5: 3 | K5: 완료 | L5: ※ 예시 - 지우고 사용하세요
A6: =IF($B6="","",COUNT($B$5:$B6)) | C6: =IF($B6="","",CHOOSE(WEEKDAY($B6),"일","월","화","수","목","금","토")) | E6: =IF($D6="","",IFERROR(INDEX(코드설정!$D$5:$D$24,MATCH($D6,코드설정!$C$5:$C$24,0)),""))
A7: =IF($B7="","",COUNT($B$5:$B7)) | C7: =IF($B7="","",CHOOSE(WEEKDAY($B7),"일","월","화","수","목","금","토")) | E7: =IF($D7="","",IFERROR(INDEX(코드설정!$D$5:$D$24,MATCH($D7,코드설정!$C$5:$C$24,0)),""))
A8: =IF($B8="","",COUNT($B$5:$B8)) | C8: =IF($B8="","",CHOOSE(WEEKDAY($B8),"일","월","화","수","목","금","토")) | E8: =IF($D8="","",IFERROR(INDEX(코드설정!$D$5:$D$24,MATCH($D8,코드설정!$C$5:$C$24,0)),""))
A9: =IF($B9="","",COUNT($B$5:$B9)) | C9: =IF($B9="","",CHOOSE(WEEKDAY($B9),"일","월","화","수","목","금","토")) | E9: =IF($D9="","",IFERROR(INDEX(코드설정!$D$5:$D$24,MATCH($D9,코드설정!$C$5:$C$24,0)),""))
A10: =IF($B10="","",COUNT($B$5:$B10)) | C10: =IF($B10="","",CHOOSE(WEEKDAY($B10),"일","월","화","수","목","금","토")) | E10: =IF($D10="","",IFERROR(INDEX(코드설정!$D$5:$D$24,MATCH($D10,코드설정!$C$5:$C$24,0)),""))
A11: =IF($B11="","",COUNT($B$5:$B11)) | C11: =IF($B11="","",CHOOSE(WEEKDAY($B11),"일","월","화","수","목","금","토")) | E11: =IF($D11="","",IFERROR(INDEX(코드설정!$D$5:$D$24,MATCH($D11,코드설정!$C$5:$C$24,0)),""))
A12: =IF($B12="","",COUNT($B$5:$B12)) | C12: =IF($B12="","",CHOOSE(WEEKDAY($B12),"일","월","화","수","목","금","토")) | E12: =IF($D12="","",IFERROR(INDEX(코드설정!$D$5:$D$24,MATCH($D12,코드설정!$C$5:$C$24,0)),""))
A13: =IF($B13="","",COUNT($B$5:$B13)) | C13: =IF($B13="","",CHOOSE(WEEKDAY($B13),"일","월","화","수","목","금","토")) | E13: =IF($D13="","",IFERROR(INDEX(코드설정!$D$5:$D$24,MATCH($D13,코드설정!$C$5:$C$24,0)),""))
A14: =IF($B14="","",COUNT($B$5:$B14)) | C14: =IF($B14="","",CHOOSE(WEEKDAY($B14),"일","월","화","수","목","금","토")) | E14: =IF($D14="","",IFERROR(INDEX(코드설정!$D$5:$D$24,MATCH($D14,코드설정!$C$5:$C$24,0)),""))
A15: =IF($B15="","",COUNT($B$5:$B15)) | C15: =IF($B15="","",CHOOSE(WEEKDAY($B15),"일","월","화","수","목","금","토")) | E15: =IF($D15="","",IFERROR(INDEX(코드설정!$D$5:$D$24,MATCH($D15,코드설정!$C$5:$C$24,0)),""))
A16: =IF($B16="","",COUNT($B$5:$B16)) | C16: =IF($B16="","",CHOOSE(WEEKDAY($B16),"일","월","화","수","목","금","토")) | E16: =IF($D16="","",IFERROR(INDEX(코드설정!$D$5:$D$24,MATCH($D16,코드설정!$C$5:$C$24,0)),""))
A17: =IF($B17="","",COUNT($B$5:$B17)) | C17: =IF($B17="","",CHOOSE(WEEKDAY($B17),"일","월","화","수","목","금","토")) | E17: =IF($D17="","",IFERROR(INDEX(코드설정!$D$5:$D$24,MATCH($D17,코드설정!$C$5:$C$24,0)),""))
... A1004: =IF($B1004="","",COUNT($B$5:$B1004)) | C1004: =IF($B1004="","",CHOOSE(WEEKDAY($B1004),"일","월","화","수","목","금","토")) | E1004: =IF($D1004="","",IFERROR(INDEX(코드설정!$D$5:$D$24,MATCH($D1004,코드설정!$C$5:$C$24,0)),""))

Sheet 사건마스터
A1: 사건 마스터 · 사건 등록 및 담당자 배정
A2: ※ 사건을 여기 한 번만 등록하면 [업무일지]에서 사건번호만 골라도 사건명·요청처·담당자가 전부 자동으로 채워집니다. ※ L열부터 담당자별 배정칸입니다. 한 사건에 여러 명을 선택하세요 — [주담당] 1명, 나머지는 [참여] (참여자는 최대 5명까지 업무일지로 전달됩니다).
AG3: ▼ 아래 6개 열은 [업무일지]가 참조하는 자동 계산 열입니다. 지우지 마세요.
A4: 사건번호 | B4: 사건명 | C4: 요청·의뢰처 | D4: 접수일 | E4: 진행상태 | F4: 주무팀 | G4: 배정인원(명) | H4: 주담당(자동) | I4: 배정 담당자 명단(자동) | J4: 비고 | L4: =IF(코드설정!$C$5="","",코드설정!$C$5) | M4: =IF(코드설정!$C$6="","",코드설정!$C$6) | N4: =IF(코드설정!$C$7="","",코드설정!$C$7) | O4: =IF(코드설정!$C$8="","",코드설정!$C$8) | P4: =IF(코드설정!$C$9="","",코드설정!$C$9) | Q4: =IF(코드설정!$C$10="","",코드설정!$C$10) | R4: =IF(코드설정!$C$11="","",코드설정!$C$11) | S4: =IF(코드설정!$C$12="","",코드설정!$C$12) | T4: =IF(코드설정!$C$13="","",코드설정!$C$13) | U4: =IF(코드설정!$C$14="","",코드설정!$C$14) | V4: =IF(코드설정!$C$15="","",코드설정!$C$15) | W4: =IF(코드설정!$C$16="","",코드설정!$C$16) | X4: =IF(코드설정!$C$17="","",코드설정!$C$17) | Y4: =IF(코드설정!$C$18="","",코드설정!$C$18) | Z4: =IF(코드설정!$C$19="","",코드설정!$C$19) | AA4: =IF(코드설정!$C$20="","",코드설정!$C$20) | AB4: =IF(코드설정!$C$21="","",코드설정!$C$21) | AC4: =IF(코드설정!$C$22="","",코드설정!$C$22) | AD4: =IF(코드설정!$C$23="","",코드설정!$C$23) | AE4: =IF(코드설정!$C$24="","",코드설정!$C$24) | AG4: 참여자 명단(주담당 제외) | AH4: 참여자1 | AI4: 참여자2 | AJ4: 참여자3 | AK4: 참여자4 | AL4: 참여자5
A5: 2026-형제-1024 | B5: ○○ 기술유출 사건 | C5: 본청 수사과 | D5: 46083 | E5: 진행중 | F5: 포렌식1팀 | G5: =IF($A5="","",COUNTIF($L5:$AE5,"?*")) | H5: =IF($A5="","",IFERROR(INDEX($L$4:$AE$4,MATCH("주담당",$L5:$AE5,0)),"")) | I5: =IF($A5="","",_xlfn.TEXTJOIN(", ",TRUE,IF($L5="","",L$4),IF($M5="","",M$4),IF($N5="","",N$4),IF($O5="","",O$4),IF($P5="","",P$4),IF($Q5="","",Q$4),IF($R5="","",R$4),IF($S5="","",S$4),IF($T5="","",T$4),IF($U5="","",U$4),IF($V5="","",V$4),IF($W5="","",W$4),IF($X5="","",X$4),IF($Y5="","",Y$4),IF($Z5="","",Z$4),IF($AA5="","",AA$4),IF($AB5="","",AB$4),IF($AC5="","",AC$4),IF($AD5="","",AD$4),IF($AE5="","",AE$4))) | J5: ※ 예시 - 3인 배정 | L5: 주담당 | M5: 참여 | N5: 참여 | AG5: =IF($A5="","",_xlfn.TEXTJOIN(", ",TRUE,IF($L5="참여",L$4,""),IF($M5="참여",M$4,""),IF($N5="참여",N$4,""),IF($O5="참여",O$4,""),IF($P5="참여",P$4,""),IF($Q5="참여",Q$4,""),IF($R5="참여",R$4,""),IF($S5="참여",S$4,""),IF($T5="참여",T$4,""),IF($U5="참여",U$4,""),IF($V5="참여",V$4,""),IF($W5="참여",W$4,""),IF($X5="참여",X$4,""),IF($Y5="참여",Y$4,""),IF($Z5="참여",Z$4,""),IF($AA5="참여",AA$4,""),IF($AB5="참여",AB$4,""),IF($AC5="참여",AC$4,""),IF($AD5="참여",AD$4,""),IF($AE5="참여",AE$4,""))) | AH5: =IF($AG5="","",TRIM(MID(SUBSTITUTE($AG5,",",REPT(" ",100)),1,100))) | AI5: =IF($AG5="","",TRIM(MID(SUBSTITUTE($AG5,",",REPT(" ",100)),101,100))) | AJ5: =IF($AG5="","",TRIM(MID(SUBSTITUTE($AG5,",",REPT(" ",100)),201,100))) | AK5: =IF($AG5="","",TRIM(MID(SUBSTITUTE($AG5,",",REPT(" ",100)),301,100))) | AL5: =IF($AG5="","",TRIM(MID(SUBSTITUTE($AG5,",",REPT(" ",100)),401,100)))
G6: =IF($A6="","",COUNTIF($L6:$AE6,"?*")) | H6: =IF($A6="","",IFERROR(INDEX($L$4:$AE$4,MATCH("주담당",$L6:$AE6,0)),"")) | I6: =IF($A6="","",_xlfn.TEXTJOIN(", ",TRUE,IF($L6="","",L$4),IF($M6="","",M$4),IF($N6="","",N$4),IF($O6="","",O$4),IF($P6="","",P$4),IF($Q6="","",Q$4),IF($R6="","",R$4),IF($S6="","",S$4),IF($T6="","",T$4),IF($U6="","",U$4),IF($V6="","",V$4),IF($W6="","",W$4),IF($X6="","",X$4),IF($Y6="","",Y$4),IF($Z6="","",Z$4),IF($AA6="","",AA$4),IF($AB6="","",AB$4),IF($AC6="","",AC$4),IF($AD6="","",AD$4),IF($AE6="","",AE$4))) | AG6: =IF($A6="","",_xlfn.TEXTJOIN(", ",TRUE,IF($L6="참여",L$4,""),IF($M6="참여",M$4,""),IF($N6="참여",N$4,""),IF($O6="참여",O$4,""),IF($P6="참여",P$4,""),IF($Q6="참여",Q$4,""),IF($R6="참여",R$4,""),IF($S6="참여",S$4,""),IF($T6="참여",T$4,""),IF($U6="참여",U$4,""),IF($V6="참여",V$4,""),IF($W6="참여",W$4,""),IF($X6="참여",X$4,""),IF($Y6="참여",Y$4,""),IF($Z6="참여",Z$4,""),IF($AA6="참여",AA$4,""),IF($AB6="참여",AB$4,""),IF($AC6="참여",AC$4,""),IF($AD6="참여",AD$4,""),IF($AE6="참여",AE$4,""))) | AH6: =IF($AG6="","",TRIM(MID(SUBSTITUTE($AG6,",",REPT(" ",100)),1,100))) | AI6: =IF($AG6="","",TRIM(MID(SUBSTITUTE($AG6,",",REPT(" ",100)),101,100))) | AJ6: =IF($AG6="","",TRIM(MID(SUBSTITUTE($AG6,",",REPT(" ",100)),201,100))) | AK6: =IF($AG6="","",TRIM(MID(SUBSTITUTE($AG6,",",REPT(" ",100)),301,100))) | AL6: =IF($AG6="","",TRIM(MID(SUBSTITUTE($AG6,",",REPT(" ",100)),401,100)))
G7: =IF($A7="","",COUNTIF($L7:$AE7,"?*")) | H7: =IF($A7="","",IFERROR(INDEX($L$4:$AE$4,MATCH("주담당",$L7:$AE7,0)),"")) | I7: =IF($A7="","",_xlfn.TEXTJOIN(", ",TRUE,IF($L7="","",L$4),IF($M7="","",M$4),IF($N7="","",N$4),IF($O7="","",O$4),IF($P7="","",P$4),IF($Q7="","",Q$4),IF($R7="","",R$4),IF($S7="","",S$4),IF($T7="","",T$4),IF($U7="","",U$4),IF($V7="","",V$4),IF($W7="","",W$4),IF($X7="","",X$4),IF($Y7="","",Y$4),IF($Z7="","",Z$4),IF($AA7="","",AA$4),IF($AB7="","",AB$4),IF($AC7="","",AC$4),IF($AD7="","",AD$4),IF($AE7="","",AE$4))) | AG7: =IF($A7="","",_xlfn.TEXTJOIN(", ",TRUE,IF($L7="참여",L$4,""),IF($M7="참여",M$4,""),IF($N7="참여",N$4,""),IF($O7="참여",O$4,""),IF($P7="참여",P$4,""),IF($Q7="참여",Q$4,""),IF($R7="참여",R$4,""),IF($S7="참여",S$4,""),IF($T7="참여",T$4,""),IF($U7="참여",U$4,""),IF($V7="참여",V$4,""),IF($W7="참여",W$4,""),IF($X7="참여",X$4,""),IF($Y7="참여",Y$4,""),IF($Z7="참여",Z$4,""),IF($AA7="참여",AA$4,""),IF($AB7="참여",AB$4,""),IF($AC7="참여",AC$4,""),IF($AD7="참여",AD$4,""),IF($AE7="참여",AE$4,""))) | AH7: =IF($AG7="","",TRIM(MID(SUBSTITUTE($AG7,",",REPT(" ",100)),1,100))) | AI7: =IF($AG7="","",TRIM(MID(SUBSTITUTE($AG7,",",REPT(" ",100)),101,100))) | AJ7: =IF($AG7="","",TRIM(MID(SUBSTITUTE($AG7,",",REPT(" ",100)),201,100))) | AK7: =IF($AG7="","",TRIM(MID(SUBSTITUTE($AG7,",",REPT(" ",100)),301,100))) | AL7: =IF($AG7="","",TRIM(MID(SUBSTITUTE($AG7,",",REPT(" ",100)),401,100)))
G8: =IF($A8="","",COUNTIF($L8:$AE8,"?*")) | H8: =IF($A8="","",IFERROR(INDEX($L$4:$AE$4,MATCH("주담당",$L8:$AE8,0)),"")) | I8: =IF($A8="","",_xlfn.TEXTJOIN(", ",TRUE,IF($L8="","",L$4),IF($M8="","",M$4),IF($N8="","",N$4),IF($O8="","",O$4),IF($P8="","",P$4),IF($Q8="","",Q$4),IF($R8="","",R$4),IF($S8="","",S$4),IF($T8="","",T$4),IF($U8="","",U$4),IF($V8="","",V$4),IF($W8="","",W$4),IF($X8="","",X$4),IF($Y8="","",Y$4),IF($Z8="","",Z$4),IF($AA8="","",AA$4),IF($AB8="","",AB$4),IF($AC8="","",AC$4),IF($AD8="","",AD$4),IF($AE8="","",AE$4))) | AG8: =IF($A8="","",_xlfn.TEXTJOIN(", ",TRUE,IF($L8="참여",L$4,""),IF($M8="참여",M$4,""),IF($N8="참여",N$4,""),IF($O8="참여",O$4,""),IF($P8="참여",P$4,""),IF($Q8="참여",Q$4,""),IF($R8="참여",R$4,""),IF($S8="참여",S$4,""),IF($T8="참여",T$4,""),IF($U8="참여",U$4,""),IF($V8="참여",V$4,""),IF($W8="참여",W$4,""),IF($X8="참여",X$4,""),IF($Y8="참여",Y$4,""),IF($Z8="참여",Z$4,""),IF($AA8="참여",AA$4,""),IF($AB8="참여",AB$4,""),IF($AC8="참여",AC$4,""),IF($AD8="참여",AD$4,""),IF($AE8="참여",AE$4,""))) | AH8: =IF($AG8="","",TRIM(MID(SUBSTITUTE($AG8,",",REPT(" ",100)),1,100))) | AI8: =IF($AG8="","",TRIM(MID(SUBSTITUTE($AG8,",",REPT(" ",100)),101,100))) | AJ8: =IF($AG8="","",TRIM(MID(SUBSTITUTE($AG8,",",REPT(" ",100)),201,100))) | AK8: =IF($AG8="","",TRIM(MID(SUBSTITUTE($AG8,",",REPT(" ",100)),301,100))) | AL8: =IF($AG8="","",TRIM(MID(SUBSTITUTE($AG8,",",REPT(" ",100)),401,100)))
G9: =IF($A9="","",COUNTIF($L9:$AE9,"?*")) | H9: =IF($A9="","",IFERROR(INDEX($L$4:$AE$4,MATCH("주담당",$L9:$AE9,0)),"")) | I9: =IF($A9="","",_xlfn.TEXTJOIN(", ",TRUE,IF($L9="","",L$4),IF($M9="","",M$4),IF($N9="","",N$4),IF($O9="","",O$4),IF($P9="","",P$4),IF($Q9="","",Q$4),IF($R9="","",R$4),IF($S9="","",S$4),IF($T9="","",T$4),IF($U9="","",U$4),IF($V9="","",V$4),IF($W9="","",W$4),IF($X9="","",X$4),IF($Y9="","",Y$4),IF($Z9="","",Z$4),IF($AA9="","",AA$4),IF($AB9="","",AB$4),IF($AC9="","",AC$4),IF($AD9="","",AD$4),IF($AE9="","",AE$4))) | AG9: =IF($A9="","",_xlfn.TEXTJOIN(", ",TRUE,IF($L9="참여",L$4,""),IF($M9="참여",M$4,""),IF($N9="참여",N$4,""),IF($O9="참여",O$4,""),IF($P9="참여",P$4,""),IF($Q9="참여",Q$4,""),IF($R9="참여",R$4,""),IF($S9="참여",S$4,""),IF($T9="참여",T$4,""),IF($U9="참여",U$4,""),IF($V9="참여",V$4,""),IF($W9="참여",W$4,""),IF($X9="참여",X$4,""),IF($Y9="참여",Y$4,""),IF($Z9="참여",Z$4,""),IF($AA9="참여",AA$4,""),IF($AB9="참여",AB$4,""),IF($AC9="참여",AC$4,""),IF($AD9="참여",AD$4,""),IF($AE9="참여",AE$4,""))) | AH9: =IF($AG9="","",TRIM(MID(SUBSTITUTE($AG9,",",REPT(" ",100)),1,100))) | AI9: =IF($AG9="","",TRIM(MID(SUBSTITUTE($AG9,",",REPT(" ",100)),101,100))) | AJ9: =IF($AG9="","",TRIM(MID(SUBSTITUTE($AG9,",",REPT(" ",100)),201,100))) | AK9: =IF($AG9="","",TRIM(MID(SUBSTITUTE($AG9,",",REPT(" ",100)),301,100))) | AL9: =IF($AG9="","",TRIM(MID(SUBSTITUTE($AG9,",",REPT(" ",100)),401,100)))
G10: =IF($A10="","",COUNTIF($L10:$AE10,"?*")) | H10: =IF($A10="","",IFERROR(INDEX($L$4:$AE$4,MATCH("주담당",$L10:$AE10,0)),"")) | I10: =IF($A10="","",_xlfn.TEXTJOIN(", ",TRUE,IF($L10="","",L$4),IF($M10="","",M$4),IF($N10="","",N$4),IF($O10="","",O$4),IF($P10="","",P$4),IF($Q10="","",Q$4),IF($R10="","",R$4),IF($S10="","",S$4),IF($T10="","",T$4),IF($U10="","",U$4),IF($V10="","",V$4),IF($W10="","",W$4),IF($X10="","",X$4),IF($Y10="","",Y$4),IF($Z10="","",Z$4),IF($AA10="","",AA$4),IF($AB10="","",AB$4),IF($AC10="","",AC$4),IF($AD10="","",AD$4),IF($AE10="","",AE$4))) | AG10: =IF($A10="","",_xlfn.TEXTJOIN(", ",TRUE,IF($L10="참여",L$4,""),IF($M10="참여",M$4,""),IF($N10="참여",N$4,""),IF($O10="참여",O$4,""),IF($P10="참여",P$4,""),IF($Q10="참여",Q$4,""),IF($R10="참여",R$4,""),IF($S10="참여",S$4,""),IF($T10="참여",T$4,""),IF($U10="참여",U$4,""),IF($V10="참여",V$4,""),IF($W10="참여",W$4,""),IF($X10="참여",X$4,""),IF($Y10="참여",Y$4,""),IF($Z10="참여",Z$4,""),IF($AA10="참여",AA$4,""),IF($AB10="참여",AB$4,""),IF($AC10="참여",AC$4,""),IF($AD10="참여",AD$4,""),IF($AE10="참여",AE$4,""))) | AH10: =IF($AG10="","",TRIM(MID(SUBSTITUTE($AG10,",",REPT(" ",100)),1,100))) | AI10: =IF($AG10="","",TRIM(MID(SUBSTITUTE($AG10,",",REPT(" ",100)),101,100))) | AJ10: =IF($AG10="","",TRIM(MID(SUBSTITUTE($AG10,",",REPT(" ",100)),201,100))) | AK10: =IF($AG10="","",TRIM(MID(SUBSTITUTE($AG10,",",REPT(" ",100)),301,100))) | AL10: =IF($AG10="","",TRIM(MID(SUBSTITUTE($AG10,",",REPT(" ",100)),401,100)))
G11: =IF($A11="","",COUNTIF($L11:$AE11,"?*")) | H11: =IF($A11="","",IFERROR(INDEX($L$4:$AE$4,MATCH("주담당",$L11:$AE11,0)),"")) | I11: =IF($A11="","",_xlfn.TEXTJOIN(", ",TRUE,IF($L11="","",L$4),IF($M11="","",M$4),IF($N11="","",N$4),IF($O11="","",O$4),IF($P11="","",P$4),IF($Q11="","",Q$4),IF($R11="","",R$4),IF($S11="","",S$4),IF($T11="","",T$4),IF($U11="","",U$4),IF($V11="","",V$4),IF($W11="","",W$4),IF($X11="","",X$4),IF($Y11="","",Y$4),IF($Z11="","",Z$4),IF($AA11="","",AA$4),IF($AB11="","",AB$4),IF($AC11="","",AC$4),IF($AD11="","",AD$4),IF($AE11="","",AE$4))) | AG11: =IF($A11="","",_xlfn.TEXTJOIN(", ",TRUE,IF($L11="참여",L$4,""),IF($M11="참여",M$4,""),IF($N11="참여",N$4,""),IF($O11="참여",O$4,""),IF($P11="참여",P$4,""),IF($Q11="참여",Q$4,""),IF($R11="참여",R$4,""),IF($S11="참여",S$4,""),IF($T11="참여",T$4,""),IF($U11="참여",U$4,""),IF($V11="참여",V$4,""),IF($W11="참여",W$4,""),IF($X11="참여",X$4,""),IF($Y11="참여",Y$4,""),IF($Z11="참여",Z$4,""),IF($AA11="참여",AA$4,""),IF($AB11="참여",AB$4,""),IF($AC11="참여",AC$4,""),IF($AD11="참여",AD$4,""),IF($AE11="참여",AE$4,""))) | AH11: =IF($AG11="","",TRIM(MID(SUBSTITUTE($AG11,",",REPT(" ",100)),1,100))) | AI11: =IF($AG11="","",TRIM(MID(SUBSTITUTE($AG11,",",REPT(" ",100)),101,100))) | AJ11: =IF($AG11="","",TRIM(MID(SUBSTITUTE($AG11,",",REPT(" ",100)),201,100))) | AK11: =IF($AG11="","",TRIM(MID(SUBSTITUTE($AG11,",",REPT(" ",100)),301,100))) | AL11: =IF($AG11="","",TRIM(MID(SUBSTITUTE($AG11,",",REPT(" ",100)),401,100)))
G12: =IF($A12="","",COUNTIF($L12:$AE12,"?*")) | H12: =IF($A12="","",IFERROR(INDEX($L$4:$AE$4,MATCH("주담당",$L12:$AE12,0)),"")) | I12: =IF($A12="","",_xlfn.TEXTJOIN(", ",TRUE,IF($L12="","",L$4),IF($M12="","",M$4),IF($N12="","",N$4),IF($O12="","",O$4),IF($P12="","",P$4),IF($Q12="","",Q$4),IF($R12="","",R$4),IF($S12="","",S$4),IF($T12="","",T$4),IF($U12="","",U$4),IF($V12="","",V$4),IF($W12="","",W$4),IF($X12="","",X$4),IF($Y12="","",Y$4),IF($Z12="","",Z$4),IF($AA12="","",AA$4),IF($AB12="","",AB$4),IF($AC12="","",AC$4),IF($AD12="","",AD$4),IF($AE12="","",AE$4))) | AG12: =IF($A12="","",_xlfn.TEXTJOIN(", ",TRUE,IF($L12="참여",L$4,""),IF($M12="참여",M$4,""),IF($N12="참여",N$4,""),IF($O12="참여",O$4,""),IF($P12="참여",P$4,""),IF($Q12="참여",Q$4,""),IF($R12="참여",R$4,""),IF($S12="참여",S$4,""),IF($T12="참여",T$4,""),IF($U12="참여",U$4,""),IF($V12="참여",V$4,""),IF($W12="참여",W$4,""),IF($X12="참여",X$4,""),IF($Y12="참여",Y$4,""),IF($Z12="참여",Z$4,""),IF($AA12="참여",AA$4,""),IF($AB12="참여",AB$4,""),IF($AC12="참여",AC$4,""),IF($AD12="참여",AD$4,""),IF($AE12="참여",AE$4,""))) | AH12: =IF($AG12="","",TRIM(MID(SUBSTITUTE($AG12,",",REPT(" ",100)),1,100))) | AI12: =IF($AG12="","",TRIM(MID(SUBSTITUTE($AG12,",",REPT(" ",100)),101,100))) | AJ12: =IF($AG12="","",TRIM(MID(SUBSTITUTE($AG12,",",REPT(" ",100)),201,100))) | AK12: =IF($AG12="","",TRIM(MID(SUBSTITUTE($AG12,",",REPT(" ",100)),301,100))) | AL12: =IF($AG12="","",TRIM(MID(SUBSTITUTE($AG12,",",REPT(" ",100)),401,100)))
G13: =IF($A13="","",COUNTIF($L13:$AE13,"?*")) | H13: =IF($A13="","",IFERROR(INDEX($L$4:$AE$4,MATCH("주담당",$L13:$AE13,0)),"")) | I13: =IF($A13="","",_xlfn.TEXTJOIN(", ",TRUE,IF($L13="","",L$4),IF($M13="","",M$4),IF($N13="","",N$4),IF($O13="","",O$4),IF($P13="","",P$4),IF($Q13="","",Q$4),IF($R13="","",R$4),IF($S13="","",S$4),IF($T13="","",T$4),IF($U13="","",U$4),IF($V13="","",V$4),IF($W13="","",W$4),IF($X13="","",X$4),IF($Y13="","",Y$4),IF($Z13="","",Z$4),IF($AA13="","",AA$4),IF($AB13="","",AB$4),IF($AC13="","",AC$4),IF($AD13="","",AD$4),IF($AE13="","",AE$4))) | AG13: =IF($A13="","",_xlfn.TEXTJOIN(", ",TRUE,IF($L13="참여",L$4,""),IF($M13="참여",M$4,""),IF($N13="참여",N$4,""),IF($O13="참여",O$4,""),IF($P13="참여",P$4,""),IF($Q13="참여",Q$4,""),IF($R13="참여",R$4,""),IF($S13="참여",S$4,""),IF($T13="참여",T$4,""),IF($U13="참여",U$4,""),IF($V13="참여",V$4,""),IF($W13="참여",W$4,""),IF($X13="참여",X$4,""),IF($Y13="참여",Y$4,""),IF($Z13="참여",Z$4,""),IF($AA13="참여",AA$4,""),IF($AB13="참여",AB$4,""),IF($AC13="참여",AC$4,""),IF($AD13="참여",AD$4,""),IF($AE13="참여",AE$4,""))) | AH13: =IF($AG13="","",TRIM(MID(SUBSTITUTE($AG13,",",REPT(" ",100)),1,100))) | AI13: =IF($AG13="","",TRIM(MID(SUBSTITUTE($AG13,",",REPT(" ",100)),101,100))) | AJ13: =IF($AG13="","",TRIM(MID(SUBSTITUTE($AG13,",",REPT(" ",100)),201,100))) | AK13: =IF($AG13="","",TRIM(MID(SUBSTITUTE($AG13,",",REPT(" ",100)),301,100))) | AL13: =IF($AG13="","",TRIM(MID(SUBSTITUTE($AG13,",",REPT(" ",100)),401,100)))
G14: =IF($A14="","",COUNTIF($L14:$AE14,"?*")) | H14: =IF($A14="","",IFERROR(INDEX($L$4:$AE$4,MATCH("주담당",$L14:$AE14,0)),"")) | I14: =IF($A14="","",_xlfn.TEXTJOIN(", ",TRUE,IF($L14="","",L$4),IF($M14="","",M$4),IF($N14="","",N$4),IF($O14="","",O$4),IF($P14="","",P$4),IF($Q14="","",Q$4),IF($R14="","",R$4),IF($S14="","",S$4),IF($T14="","",T$4),IF($U14="","",U$4),IF($V14="","",V$4),IF($W14="","",W$4),IF($X14="","",X$4),IF($Y14="","",Y$4),IF($Z14="","",Z$4),IF($AA14="","",AA$4),IF($AB14="","",AB$4),IF($AC14="","",AC$4),IF($AD14="","",AD$4),IF($AE14="","",AE$4))) | AG14: =IF($A14="","",_xlfn.TEXTJOIN(", ",TRUE,IF($L14="참여",L$4,""),IF($M14="참여",M$4,""),IF($N14="참여",N$4,""),IF($O14="참여",O$4,""),IF($P14="참여",P$4,""),IF($Q14="참여",Q$4,""),IF($R14="참여",R$4,""),IF($S14="참여",S$4,""),IF($T14="참여",T$4,""),IF($U14="참여",U$4,""),IF($V14="참여",V$4,""),IF($W14="참여",W$4,""),IF($X14="참여",X$4,""),IF($Y14="참여",Y$4,""),IF($Z14="참여",Z$4,""),IF($AA14="참여",AA$4,""),IF($AB14="참여",AB$4,""),IF($AC14="참여",AC$4,""),IF($AD14="참여",AD$4,""),IF($AE14="참여",AE$4,""))) | AH14: =IF($AG14="","",TRIM(MID(SUBSTITUTE($AG14,",",REPT(" ",100)),1,100))) | AI14: =IF($AG14="","",TRIM(MID(SUBSTITUTE($AG14,",",REPT(" ",100)),101,100))) | AJ14: =IF($AG14="","",TRIM(MID(SUBSTITUTE($AG14,",",REPT(" ",100)),201,100))) | AK14: =IF($AG14="","",TRIM(MID(SUBSTITUTE($AG14,",",REPT(" ",100)),301,100))) | AL14: =IF($AG14="","",TRIM(MID(SUBSTITUTE($AG14,",",REPT(" ",100)),401,100)))
G15: =IF($A15="","",COUNTIF($L15:$AE15,"?*")) | H15: =IF($A15="","",IFERROR(INDEX($L$4:$AE$4,MATCH("주담당",$L15:$AE15,0)),"")) | I15: =IF($A15="","",_xlfn.TEXTJOIN(", ",TRUE,IF($L15="","",L$4),IF($M15="","",M$4),IF($N15="","",N$4),IF($O15="","",O$4),IF($P15="","",P$4),IF($Q15="","",Q$4),IF($R15="","",R$4),IF($S15="","",S$4),IF($T15="","",T$4),IF($U15="","",U$4),IF($V15="","",V$4),IF($W15="","",W$4),IF($X15="","",X$4),IF($Y15="","",Y$4),IF($Z15="","",Z$4),IF($AA15="","",AA$4),IF($AB15="","",AB$4),IF($AC15="","",AC$4),IF($AD15="","",AD$4),IF($AE15="","",AE$4))) | AG15: =IF($A15="","",_xlfn.TEXTJOIN(", ",TRUE,IF($L15="참여",L$4,""),IF($M15="참여",M$4,""),IF($N15="참여",N$4,""),IF($O15="참여",O$4,""),IF($P15="참여",P$4,""),IF($Q15="참여",Q$4,""),IF($R15="참여",R$4,""),IF($S15="참여",S$4,""),IF($T15="참여",T$4,""),IF($U15="참여",U$4,""),IF($V15="참여",V$4,""),IF($W15="참여",W$4,""),IF($X15="참여",X$4,""),IF($Y15="참여",Y$4,""),IF($Z15="참여",Z$4,""),IF($AA15="참여",AA$4,""),IF($AB15="참여",AB$4,""),IF($AC15="참여",AC$4,""),IF($AD15="참여",AD$4,""),IF($AE15="참여",AE$4,""))) | AH15: =IF($AG15="","",TRIM(MID(SUBSTITUTE($AG15,",",REPT(" ",100)),1,100))) | AI15: =IF($AG15="","",TRIM(MID(SUBSTITUTE($AG15,",",REPT(" ",100)),101,100))) | AJ15: =IF($AG15="","",TRIM(MID(SUBSTITUTE($AG15,",",REPT(" ",100)),201,100))) | AK15: =IF($AG15="","",TRIM(MID(SUBSTITUTE($AG15,",",REPT(" ",100)),301,100))) | AL15: =IF($AG15="","",TRIM(MID(SUBSTITUTE($AG15,",",REPT(" ",100)),401,100)))
G16: =IF($A16="","",COUNTIF($L16:$AE16,"?*")) | H16: =IF($A16="","",IFERROR(INDEX($L$4:$AE$4,MATCH("주담당",$L16:$AE16,0)),"")) | I16: =IF($A16="","",_xlfn.TEXTJOIN(", ",TRUE,IF($L16="","",L$4),IF($M16="","",M$4),IF($N16="","",N$4),IF($O16="","",O$4),IF($P16="","",P$4),IF($Q16="","",Q$4),IF($R16="","",R$4),IF($S16="","",S$4),IF($T16="","",T$4),IF($U16="","",U$4),IF($V16="","",V$4),IF($W16="","",W$4),IF($X16="","",X$4),IF($Y16="","",Y$4),IF($Z16="","",Z$4),IF($AA16="","",AA$4),IF($AB16="","",AB$4),IF($AC16="","",AC$4),IF($AD16="","",AD$4),IF($AE16="","",AE$4))) | AG16: =IF($A16="","",_xlfn.TEXTJOIN(", ",TRUE,IF($L16="참여",L$4,""),IF($M16="참여",M$4,""),IF($N16="참여",N$4,""),IF($O16="참여",O$4,""),IF($P16="참여",P$4,""),IF($Q16="참여",Q$4,""),IF($R16="참여",R$4,""),IF($S16="참여",S$4,""),IF($T16="참여",T$4,""),IF($U16="참여",U$4,""),IF($V16="참여",V$4,""),IF($W16="참여",W$4,""),IF($X16="참여",X$4,""),IF($Y16="참여",Y$4,""),IF($Z16="참여",Z$4,""),IF($AA16="참여",AA$4,""),IF($AB16="참여",AB$4,""),IF($AC16="참여",AC$4,""),IF($AD16="참여",AD$4,""),IF($AE16="참여",AE$4,""))) | AH16: =IF($AG16="","",TRIM(MID(SUBSTITUTE($AG16,",",REPT(" ",100)),1,100))) | AI16: =IF($AG16="","",TRIM(MID(SUBSTITUTE($AG16,",",REPT(" ",100)),101,100))) | AJ16: =IF($AG16="","",TRIM(MID(SUBSTITUTE($AG16,",",REPT(" ",100)),201,100))) | AK16: =IF($AG16="","",TRIM(MID(SUBSTITUTE($AG16,",",REPT(" ",100)),301,100))) | AL16: =IF($AG16="","",TRIM(MID(SUBSTITUTE($AG16,",",REPT(" ",100)),401,100)))
