Workbook

Sheet 업무일지
A1: 부서 업무일지 · 출장 / 분석 통합 대장
A2: ※ 출장 1건 = 1행. 여러 명이 함께 나가도 행을 늘리지 말고 J열 [동행자]에 쉼표로 나열하세요. ※ Q열은 '1인 기준' 시간입니다. 총 인시(R) = 1인 시간 × 투입인원 으로 자동 계산됩니다. ※ 파란 글씨 칸만 입력 / 회색 칸은 자동. ※ 5~7행은 예시이므로 지우고 사용하세요.
A4: 연번 | B4: 시작일 | C4: 종료일 | D4: 직무구분 | E4: 세부유형 | F4: 사건명 · 업무명 | G4: 사건번호 | H4: 요청·의뢰처 | I4: 주담당자 | J4: 동행자 (쉼표로 구분) | K4: 투입인원(명) | L4: 소속팀 | M4: 장소 / 분석실 | N4: 대상매체(건) | O4: 데이터량(GB) | P4: 소요일수 | Q4: 1인 투입시간(H) | R4: 총 인시(H) | S4: 진행상태 | T4: 출장비(원) | U4: 비고
A5: =IF($B5="","",COUNT($B$5:$B5)) -> 1 | B5: 46085 | C5: 46086 | D5: 출장 | E5: 압수·수색 집행 | F5: ○○ 기술유출 사건 압수수색 | G5: 2026-형제-1024 | H5: 본청 수사과 | I5: 김디지 | J5: 이수사, 박증거 | K5: =IF($I5="","",1+IF($J5="",0,LEN($J5)-LEN(SUBSTITUTE($J5,",",""))+1)) -> 3 | L5: 포렌식1팀 | M5: 경기 성남시 판교 | N5: 6 | O5: 3200 | P5: =IF(OR($B5="",$C5=""),"",$C5-$B5+1) -> 2 | Q5: 16 | R5: =IF(OR($Q5="",$K5=""),"",$Q5*$K5) -> 48 | S5: 완료 | T5: 552000 | U5: ※ 예시 - 3인 동시 출장
A6: =IF($B6="","",COUNT($B$5:$B6)) -> 2 | B6: 46090 | C6: 46094 | D6: 분석 | E6: 디스크 이미지 분석 | F6: ○○ 기술유출 사건 E01 분석 | G6: 2026-형제-1024 | H6: 본청 수사과 | I6: 김디지 | K6: =IF($I6="","",1+IF($J6="",0,LEN($J6)-LEN(SUBSTITUTE($J6,",",""))+1)) -> 1 | L6: 포렌식1팀 | M6: 본관 3층 분석실 | N6: 4 | O6: 2400 | P6: =IF(OR($B6="",$C6=""),"",$C6-$B6+1) -> 5 | Q6: 34 | R6: =IF(OR($Q6="",$K6=""),"",$Q6*$K6) -> 34 | S6: 완료 | T6: 0 | U6: ※ 예시 - 단독 분석
A7: =IF($B7="","",COUNT($B$5:$B7)) -> 3 | B7: 46098 | C7: 46098 | D7: 분석 | E7: 모바일 분석 | F7: △△ 사건 휴대폰 추출·분석 | G7: 2026-형제-1131 | H7: 지방청 사이버수사대 | I7: 박증거 | K7: =IF($I7="","",1+IF($J7="",0,LEN($J7)-LEN(SUBSTITUTE($J7,",",""))+1)) -> 1 | L7: 포렌식2팀 | M7: 본관 3층 분석실 | N7: 2 | O7: 480 | P7: =IF(OR($B7="",$C7=""),"",$C7-$B7+1) -> 1 | Q7: 7 | R7: =IF(OR($Q7="",$K7=""),"",$Q7*$K7) -> 7 | S7: 진행중 | T7: 0 | U7: ※ 예시 - 삭제 후 사용
A8: =IF($B8="","",COUNT($B$5:$B8)) | K8: =IF($I8="","",1+IF($J8="",0,LEN($J8)-LEN(SUBSTITUTE($J8,",",""))+1)) | P8: =IF(OR($B8="",$C8=""),"",$C8-$B8+1) | R8: =IF(OR($Q8="",$K8=""),"",$Q8*$K8)
A9: =IF($B9="","",COUNT($B$5:$B9)) | K9: =IF($I9="","",1+IF($J9="",0,LEN($J9)-LEN(SUBSTITUTE($J9,",",""))+1)) | P9: =IF(OR($B9="",$C9=""),"",$C9-$B9+1) | R9: =IF(OR($Q9="",$K9=""),"",$Q9*$K9)
A10: =IF($B10="","",COUNT($B$5:$B10)) | K10: =IF($I10="","",1+IF($J10="",0,LEN($J10)-LEN(SUBSTITUTE($J10,",",""))+1)) | P10: =IF(OR($B10="",$C10=""),"",$C10-$B10+1) | R10: =IF(OR($Q10="",$K10=""),"",$Q10*$K10)
A11: =IF($B11="","",COUNT($B$5:$B11)) | K11: =IF($I11="","",1+IF($J11="",0,LEN($J11)-LEN(SUBSTITUTE($J11,",",""))+1)) | P11: =IF(OR($B11="",$C11=""),"",$C11-$B11+1) | R11: =IF(OR($Q11="",$K11=""),"",$Q11*$K11)
A12: =IF($B12="","",COUNT($B$5:$B12)) | K12: =IF($I12="","",1+IF($J12="",0,LEN($J12)-LEN(SUBSTITUTE($J12,",",""))+1)) | P12: =IF(OR($B12="",$C12=""),"",$C12-$B12+1) | R12: =IF(OR($Q12="",$K12=""),"",$Q12*$K12)
A13: =IF($B13="","",COUNT($B$5:$B13)) | K13: =IF($I13="","",1+IF($J13="",0,LEN($J13)-LEN(SUBSTITUTE($J13,",",""))+1)) | P13: =IF(OR($B13="",$C13=""),"",$C13-$B13+1) | R13: =IF(OR($Q13="",$K13=""),"",$Q13*$K13)
A14: =IF($B14="","",COUNT($B$5:$B14)) | K14: =IF($I14="","",1+IF($J14="",0,LEN($J14)-LEN(SUBSTITUTE($J14,",",""))+1)) | P14: =IF(OR($B14="",$C14=""),"",$C14-$B14+1) | R14: =IF(OR($Q14="",$K14=""),"",$Q14*$K14)
A15: =IF($B15="","",COUNT($B$5:$B15)) | K15: =IF($I15="","",1+IF($J15="",0,LEN($J15)-LEN(SUBSTITUTE($J15,",",""))+1)) | P15: =IF(OR($B15="",$C15=""),"",$C15-$B15+1) | R15: =IF(OR($Q15="",$K15=""),"",$Q15*$K15)
A16: =IF($B16="","",COUNT($B$5:$B16)) | K16: =IF($I16="","",1+IF($J16="",0,LEN($J16)-LEN(SUBSTITUTE($J16,",",""))+1)) | P16: =IF(OR($B16="",$C16=""),"",$C16-$B16+1) | R16: =IF(OR($Q16="",$K16=""),"",$Q16*$K16)
A17: =IF($B17="","",COUNT($B$5:$B17)) | K17: =IF($I17="","",1+IF($J17="",0,LEN($J17)-LEN(SUBSTITUTE($J17,",",""))+1)) | P17: =IF(OR($B17="",$C17=""),"",$C17-$B17+1) | R17: =IF(OR($Q17="",$K17=""),"",$Q17*$K17)
A18: =IF($B18="","",COUNT($B$5:$B18)) | K18: =IF($I18="","",1+IF($J18="",0,LEN($J18)-LEN(SUBSTITUTE($J18,",",""))+1)) | P18: =IF(OR($B18="",$C18=""),"",$C18-$B18+1) | R18: =IF(OR($Q18="",$K18=""),"",$Q18*$K18)
A19: =IF($B19="","",COUNT($B$5:$B19)) | K19: =IF($I19="","",1+IF($J19="",0,LEN($J19)-LEN(SUBSTITUTE($J19,",",""))+1)) | P19: =IF(OR($B19="",$C19=""),"",$C19-$B19+1) | R19: =IF(OR($Q19="",$K19=""),"",$Q19*$K19)
... A1004: =IF($B1004="","",COUNT($B$5:$B1004)) | K1004: =IF($I1004="","",1+IF($J1004="",0,LEN($J1004)-LEN(SUBSTITUTE($J1004,",",""))+1)) | P1004: =IF(OR($B1004="",$C1004=""),"",$C1004-$B1004+1) | R1004: =IF(OR($Q1004="",$K1004=""),"",$Q1004*$K1004)

Sheet 부서 전체현황
A1: 부서 전체 현황 · 출장 / 분석
A2: ※ 노란 칸(기준연도)만 바꾸면 전체 표가 다시 계산됩니다. ※ 건수 = 출장·분석 '건' 단위 / 연인원 = 참여 인원 누계 / 총 인시 = 실제 투입 공수(1인시간 × 인원).
A3: 기준연도 | B3: 2026
A5: 1. 월별 추이
A6: 월 | B6: 출장 건수 | C6: 분석 건수 | D6: 전체 건수 | E6: 출장 소요일수 | F6: 연인원(명) | G6: 총 인시(H) | H6: 대상매체(건) | I6: 출장비(원) | J6: 1건당 인시(H)
A7: 1월 | B7: =COUNTIFS(업무일지!$B$5:$B$1004,">="&DATE($B$3,1,1),업무일지!$B$5:$B$1004,"<"&DATE($B$3,1+1,1),업무일지!$D$5:$D$1004,"출장") -> 0 | C7: =COUNTIFS(업무일지!$B$5:$B$1004,">="&DATE($B$3,1,1),업무일지!$B$5:$B$1004,"<"&DATE($B$3,1+1,1),업무일지!$D$5:$D$1004,"분석") -> 0 | D7: =B7+C7 -> 0 | E7: =SUMIFS(업무일지!$P$5:$P$1004,업무일지!$B$5:$B$1004,">="&DATE($B$3,1,1),업무일지!$B$5:$B$1004,"<"&DATE($B$3,1+1,1),업무일지!$D$5:$D$1004,"출장") -> 0 | F7: =SUMIFS(업무일지!$K$5:$K$1004,업무일지!$B$5:$B$1004,">="&DATE($B$3,1,1),업무일지!$B$5:$B$1004,"<"&DATE($B$3,1+1,1)) -> 0 | G7: =SUMIFS(업무일지!$R$5:$R$1004,업무일지!$B$5:$B$1004,">="&DATE($B$3,1,1),업무일지!$B$5:$B$1004,"<"&DATE($B$3,1+1,1)) -> 0 | H7: =SUMIFS(업무일지!$N$5:$N$1004,업무일지!$B$5:$B$1004,">="&DATE($B$3,1,1),업무일지!$B$5:$B$1004,"<"&DATE($B$3,1+1,1)) -> 0 | I7: =SUMIFS(업무일지!$T$5:$T$1004,업무일지!$B$5:$B$1004,">="&DATE($B$3,1,1),업무일지!$B$5:$B$1004,"<"&DATE($B$3,1+1,1)) -> 0 | J7: =IFERROR(G7/D7,0) -> 0
A8: 2월 | B8: =COUNTIFS(업무일지!$B$5:$B$1004,">="&DATE($B$3,2,1),업무일지!$B$5:$B$1004,"<"&DATE($B$3,2+1,1),업무일지!$D$5:$D$1004,"출장") -> 0 | C8: =COUNTIFS(업무일지!$B$5:$B$1004,">="&DATE($B$3,2,1),업무일지!$B$5:$B$1004,"<"&DATE($B$3,2+1,1),업무일지!$D$5:$D$1004,"분석") -> 0 | D8: =B8+C8 -> 0 | E8: =SUMIFS(업무일지!$P$5:$P$1004,업무일지!$B$5:$B$1004,">="&DATE($B$3,2,1),업무일지!$B$5:$B$1004,"<"&DATE($B$3,2+1,1),업무일지!$D$5:$D$1004,"출장") -> 0 | F8: =SUMIFS(업무일지!$K$5:$K$1004,업무일지!$B$5:$B$1004,">="&DATE($B$3,2,1),업무일지!$B$5:$B$1004,"<"&DATE($B$3,2+1,1)) -> 0 | G8: =SUMIFS(업무일지!$R$5:$R$1004,업무일지!$B$5:$B$1004,">="&DATE($B$3,2,1),업무일지!$B$5:$B$1004,"<"&DATE($B$3,2+1,1)) -> 0 | H8: =SUMIFS(업무일지!$N$5:$N$1004,업무일지!$B$5:$B$1004,">="&DATE($B$3,2,1),업무일지!$B$5:$B$1004,"<"&DATE($B$3,2+1,1)) -> 0 | I8: =SUMIFS(업무일지!$T$5:$T$1004,업무일지!$B$5:$B$1004,">="&DATE($B$3,2,1),업무일지!$B$5:$B$1004,"<"&DATE($B$3,2+1,1)) -> 0 | J8: =IFERROR(G8/D8,0) -> 0
A9: 3월 | B9: =COUNTIFS(업무일지!$B$5:$B$1004,">="&DATE($B$3,3,1),업무일지!$B$5:$B$1004,"<"&DATE($B$3,3+1,1),업무일지!$D$5:$D$1004,"출장") -> 1 | C9: =COUNTIFS(업무일지!$B$5:$B$1004,">="&DATE($B$3,3,1),업무일지!$B$5:$B$1004,"<"&DATE($B$3,3+1,1),업무일지!$D$5:$D$1004,"분석") -> 2 | D9: =B9+C9 -> 3 | E9: =SUMIFS(업무일지!$P$5:$P$1004,업무일지!$B$5:$B$1004,">="&DATE($B$3,3,1),업무일지!$B$5:$B$1004,"<"&DATE($B$3,3+1,1),업무일지!$D$5:$D$1004,"출장") -> 2 | F9: =SUMIFS(업무일지!$K$5:$K$1004,업무일지!$B$5:$B$1004,">="&DATE($B$3,3,1),업무일지!$B$5:$B$1004,"<"&DATE($B$3,3+1,1)) -> 5 | G9: =SUMIFS(업무일지!$R$5:$R$1004,업무일지!$B$5:$B$1004,">="&DATE($B$3,3,1),업무일지!$B$5:$B$1004,"<"&DATE($B$3,3+1,1)) -> 89 | H9: =SUMIFS(업무일지!$N$5:$N$1004,업무일지!$B$5:$B$1004,">="&DATE($B$3,3,1),업무일지!$B$5:$B$1004,"<"&DATE($B$3,3+1,1)) -> 12 | I9: =SUMIFS(업무일지!$T$5:$T$1004,업무일지!$B$5:$B$1004,">="&DATE($B$3,3,1),업무일지!$B$5:$B$1004,"<"&DATE($B$3,3+1,1)) -> 552000 | J9: =IFERROR(G9/D9,0) -> 29.666667
A10: 4월 | B10: =COUNTIFS(업무일지!$B$5:$B$1004,">="&DATE($B$3,4,1),업무일지!$B$5:$B$1004,"<"&DATE($B$3,4+1,1),업무일지!$D$5:$D$1004,"출장") -> 0 | C10: =COUNTIFS(업무일지!$B$5:$B$1004,">="&DATE($B$3,4,1),업무일지!$B$5:$B$1004,"<"&DATE($B$3,4+1,1),업무일지!$D$5:$D$1004,"분석") -> 0 | D10: =B10+C10 -> 0 | E10: =SUMIFS(업무일지!$P$5:$P$1004,업무일지!$B$5:$B$1004,">="&DATE($B$3,4,1),업무일지!$B$5:$B$1004,"<"&DATE($B$3,4+1,1),업무일지!$D$5:$D$1004,"출장") -> 0 | F10: =SUMIFS(업무일지!$K$5:$K$1004,업무일지!$B$5:$B$1004,">="&DATE($B$3,4,1),업무일지!$B$5:$B$1004,"<"&DATE($B$3,4+1,1)) -> 0 | G10: =SUMIFS(업무일지!$R$5:$R$1004,업무일지!$B$5:$B$1004,">="&DATE($B$3,4,1),업무일지!$B$5:$B$1004,"<"&DATE($B$3,4+1,1)) -> 0 | H10: =SUMIFS(업무일지!$N$5:$N$1004,업무일지!$B$5:$B$1004,">="&DATE($B$3,4,1),업무일지!$B$5:$B$1004,"<"&DATE($B$3,4+1,1)) -> 0 | I10: =SUMIFS(업무일지!$T$5:$T$1004,업무일지!$B$5:$B$1004,">="&DATE($B$3,4,1),업무일지!$B$5:$B$1004,"<"&DATE($B$3,4+1,1)) -> 0 | J10: =IFERROR(G10/D10,0) -> 0
A11: 5월 | B11: =COUNTIFS(업무일지!$B$5:$B$1004,">="&DATE($B$3,5,1),업무일지!$B$5:$B$1004,"<"&DATE($B$3,5+1,1),업무일지!$D$5:$D$1004,"출장") -> 0 | C11: =COUNTIFS(업무일지!$B$5:$B$1004,">="&DATE($B$3,5,1),업무일지!$B$5:$B$1004,"<"&DATE($B$3,5+1,1),업무일지!$D$5:$D$1004,"분석") -> 0 | D11: =B11+C11 -> 0 | E11: =SUMIFS(업무일지!$P$5:$P$1004,업무일지!$B$5:$B$1004,">="&DATE($B$3,5,1),업무일지!$B$5:$B$1004,"<"&DATE($B$3,5+1,1),업무일지!$D$5:$D$1004,"출장") -> 0 | F11: =SUMIFS(업무일지!$K$5:$K$1004,업무일지!$B$5:$B$1004,">="&DATE($B$3,5,1),업무일지!$B$5:$B$1004,"<"&DATE($B$3,5+1,1)) -> 0 | G11: =SUMIFS(업무일지!$R$5:$R$1004,업무일지!$B$5:$B$1004,">="&DATE($B$3,5,1),업무일지!$B$5:$B$1004,"<"&DATE($B$3,5+1,1)) -> 0 | H11: =SUMIFS(업무일지!$N$5:$N$1004,업무일지!$B$5:$B$1004,">="&DATE($B$3,5,1),업무일지!$B$5:$B$1004,"<"&DATE($B$3,5+1,1)) -> 0 | I11: =SUMIFS(업무일지!$T$5:$T$1004,업무일지!$B$5:$B$1004,">="&DATE($B$3,5,1),업무일지!$B$5:$B$1004,"<"&DATE($B$3,5+1,1)) -> 0 | J11: =IFERROR(G11/D11,0) -> 0
A12: 6월 | B12: =COUNTIFS(업무일지!$B$5:$B$1004,">="&DATE($B$3,6,1),업무일지!$B$5:$B$1004,"<"&DATE($B$3,6+1,1),업무일지!$D$5:$D$1004,"출장") -> 0 | C12: =COUNTIFS(업무일지!$B$5:$B$1004,">="&DATE($B$3,6,1),업무일지!$B$5:$B$1004,"<"&DATE($B$3,6+1,1),업무일지!$D$5:$D$1004,"분석") -> 0 | D12: =B12+C12 -> 0 | E12: =SUMIFS(업무일지!$P$5:$P$1004,업무일지!$B$5:$B$1004,">="&DATE($B$3,6,1),업무일지!$B$5:$B$1004,"<"&DATE($B$3,6+1,1),업무일지!$D$5:$D$1004,"출장") -> 0 | F12: =SUMIFS(업무일지!$K$5:$K$1004,업무일지!$B$5:$B$1004,">="&DATE($B$3,6,1),업무일지!$B$5:$B$1004,"<"&DATE($B$3,6+1,1)) -> 0 | G12: =SUMIFS(업무일지!$R$5:$R$1004,업무일지!$B$5:$B$1004,">="&DATE($B$3,6,1),업무일지!$B$5:$B$1004,"<"&DATE($B$3,6+1,1)) -> 0 | H12: =SUMIFS(업무일지!$N$5:$N$1004,업무일지!$B$5:$B$1004,">="&DATE($B$3,6,1),업무일지!$B$5:$B$1004,"<"&DATE($B$3,6+1,1)) -> 0 | I12: =SUMIFS(업무일지!$T$5:$T$1004,업무일지!$B$5:$B$1004,">="&DATE($B$3,6,1),업무일지!$B$5:$B$1004,"<"&DATE($B$3,6+1,1)) -> 0 | J12: =IFERROR(G12/D12,0) -> 0
A13: 7월 | B13: =COUNTIFS(업무일지!$B$5:$B$1004,">="&DATE($B$3,7,1),업무일지!$B$5:$B$1004,"<"&DATE($B$3,7+1,1),업무일지!$D$5:$D$1004,"출장") -> 0 | C13: =COUNTIFS(업무일지!$B$5:$B$1004,">="&DATE($B$3,7,1),업무일지!$B$5:$B$1004,"<"&DATE($B$3,7+1,1),업무일지!$D$5:$D$1004,"분석") -> 0 | D13: =B13+C13 -> 0 | E13: =SUMIFS(업무일지!$P$5:$P$1004,업무일지!$B$5:$B$1004,">="&DATE($B$3,7,1),업무일지!$B$5:$B$1004,"<"&DATE($B$3,7+1,1),업무일지!$D$5:$D$1004,"출장") -> 0 | F13: =SUMIFS(업무일지!$K$5:$K$1004,업무일지!$B$5:$B$1004,">="&DATE($B$3,7,1),업무일지!$B$5:$B$1004,"<"&DATE($B$3,7+1,1)) -> 0 | G13: =SUMIFS(업무일지!$R$5:$R$1004,업무일지!$B$5:$B$1004,">="&DATE($B$3,7,1),업무일지!$B$5:$B$1004,"<"&DATE($B$3,7+1,1)) -> 0 | H13: =SUMIFS(업무일지!$N$5:$N$1004,업무일지!$B$5:$B$1004,">="&DATE($B$3,7,1),업무일지!$B$5:$B$1004,"<"&DATE($B$3,7+1,1)) -> 0 | I13: =SUMIFS(업무일지!$T$5:$T$1004,업무일지!$B$5:$B$1004,">="&DATE($B$3,7,1),업무일지!$B$5:$B$1004,"<"&DATE($B$3,7+1,1)) -> 0 | J13: =IFERROR(G13/D13,0) -> 0
A14: 8월 | B14: =COUNTIFS(업무일지!$B$5:$B$1004,">="&DATE($B$3,8,1),업무일지!$B$5:$B$1004,"<"&DATE($B$3,8+1,1),업무일지!$D$5:$D$1004,"출장") -> 0 | C14: =COUNTIFS(업무일지!$B$5:$B$1004,">="&DATE($B$3,8,1),업무일지!$B$5:$B$1004,"<"&DATE($B$3,8+1,1),업무일지!$D$5:$D$1004,"분석") -> 0 | D14: =B14+C14 -> 0 | E14: =SUMIFS(업무일지!$P$5:$P$1004,업무일지!$B$5:$B$1004,">="&DATE($B$3,8,1),업무일지!$B$5:$B$1004,"<"&DATE($B$3,8+1,1),업무일지!$D$5:$D$1004,"출장") -> 0 | F14: =SUMIFS(업무일지!$K$5:$K$1004,업무일지!$B$5:$B$1004,">="&DATE($B$3,8,1),업무일지!$B$5:$B$1004,"<"&DATE($B$3,8+1,1)) -> 0 | G14: =SUMIFS(업무일지!$R$5:$R$1004,업무일지!$B$5:$B$1004,">="&DATE($B$3,8,1),업무일지!$B$5:$B$1004,"<"&DATE($B$3,8+1,1)) -> 0 | H14: =SUMIFS(업무일지!$N$5:$N$1004,업무일지!$B$5:$B$1004,">="&DATE($B$3,8,1),업무일지!$B$5:$B$1004,"<"&DATE($B$3,8+1,1)) -> 0 | I14: =SUMIFS(업무일지!$T$5:$T$1004,업무일지!$B$5:$B$1004,">="&DATE($B$3,8,1),업무일지!$B$5:$B$1004,"<"&DATE($B$3,8+1,1)) -> 0 | J14: =IFERROR(G14/D14,0) -> 0
A15: 9월 | B15: =COUNTIFS(업무일지!$B$5:$B$1004,">="&DATE($B$3,9,1),업무일지!$B$5:$B$1004,"<"&DATE($B$3,9+1,1),업무일지!$D$5:$D$1004,"출장") -> 0 | C15: =COUNTIFS(업무일지!$B$5:$B$1004,">="&DATE($B$3,9,1),업무일지!$B$5:$B$1004,"<"&DATE($B$3,9+1,1),업무일지!$D$5:$D$1004,"분석") -> 0 | D15: =B15+C15 -> 0 | E15: =SUMIFS(업무일지!$P$5:$P$1004,업무일지!$B$5:$B$1004,">="&DATE($B$3,9,1),업무일지!$B$5:$B$1004,"<"&DATE($B$3,9+1,1),업무일지!$D$5:$D$1004,"출장") -> 0 | F15: =SUMIFS(업무일지!$K$5:$K$1004,업무일지!$B$5:$B$1004,">="&DATE($B$3,9,1),업무일지!$B$5:$B$1004,"<"&DATE($B$3,9+1,1)) -> 0 | G15: =SUMIFS(업무일지!$R$5:$R$1004,업무일지!$B$5:$B$1004,">="&DATE($B$3,9,1),업무일지!$B$5:$B$1004,"<"&DATE($B$3,9+1,1)) -> 0 | H15: =SUMIFS(업무일지!$N$5:$N$1004,업무일지!$B$5:$B$1004,">="&DATE($B$3,9,1),업무일지!$B$5:$B$1004,"<"&DATE($B$3,9+1,1)) -> 0 | I15: =SUMIFS(업무일지!$T$5:$T$1004,업무일지!$B$5:$B$1004,">="&DATE($B$3,9,1),업무일지!$B$5:$B$1004,"<"&DATE($B$3,9+1,1)) -> 0 | J15: =IFERROR(G15/D15,0) -> 0
A16: 10월 | B16: =COUNTIFS(업무일지!$B$5:$B$1004,">="&DATE($B$3,10,1),업무일지!$B$5:$B$1004,"<"&DATE($B$3,10+1,1),업무일지!$D$5:$D$1004,"출장") -> 0 | C16: =COUNTIFS(업무일지!$B$5:$B$1004,">="&DATE($B$3,10,1),업무일지!$B$5:$B$1004,"<"&DATE($B$3,10+1,1),업무일지!$D$5:$D$1004,"분석") -> 0 | D16: =B16+C16 -> 0 | E16: =SUMIFS(업무일지!$P$5:$P$1004,업무일지!$B$5:$B$1004,">="&DATE($B$3,10,1),업무일지!$B$5:$B$1004,"<"&DATE($B$3,10+1,1),업무일지!$D$5:$D$1004,"출장") -> 0 | F16: =SUMIFS(업무일지!$K$5:$K$1004,업무일지!$B$5:$B$1004,">="&DATE($B$3,10,1),업무일지!$B$5:$B$1004,"<"&DATE($B$3,10+1,1)) -> 0 | G16: =SUMIFS(업무일지!$R$5:$R$1004,업무일지!$B$5:$B$1004,">="&DATE($B$3,10,1),업무일지!$B$5:$B$1004,"<"&DATE($B$3,10+1,1)) -> 0 | H16: =SUMIFS(업무일지!$N$5:$N$1004,업무일지!$B$5:$B$1004,">="&DATE($B$3,10,1),업무일지!$B$5:$B$1004,"<"&DATE($B$3,10+1,1)) -> 0 | I16: =SUMIFS(업무일지!$T$5:$T$1004,업무일지!$B$5:$B$1004,">="&DATE($B$3,10,1),업무일지!$B$5:$B$1004,"<"&DATE($B$3,10+1,1)) -> 0 | J16: =IFERROR(G16/D16,0) -> 0
A17: 11월 | B17: =COUNTIFS(업무일지!$B$5:$B$1004,">="&DATE($B$3,11,1),업무일지!$B$5:$B$1004,"<"&DATE($B$3,11+1,1),업무일지!$D$5:$D$1004,"출장") -> 0 | C17: =COUNTIFS(업무일지!$B$5:$B$1004,">="&DATE($B$3,11,1),업무일지!$B$5:$B$1004,"<"&DATE($B$3,11+1,1),업무일지!$D$5:$D$1004,"분석") -> 0 | D17: =B17+C17 -> 0 | E17: =SUMIFS(업무일지!$P$5:$P$1004,업무일지!$B$5:$B$1004,">="&DATE($B$3,11,1),업무일지!$B$5:$B$1004,"<"&DATE($B$3,11+1,1),업무일지!$D$5:$D$1004,"출장") -> 0 | F17: =SUMIFS(업무일지!$K$5:$K$1004,업무일지!$B$5:$B$1004,">="&DATE($B$3,11,1),업무일지!$B$5:$B$1004,"<"&DATE($B$3,11+1,1)) -> 0 | G17: =SUMIFS(업무일지!$R$5:$R$1004,업무일지!$B$5:$B$1004,">="&DATE($B$3,11,1),업무일지!$B$5:$B$1004,"<"&DATE($B$3,11+1,1)) -> 0 | H17: =SUMIFS(업무일지!$N$5:$N$1004,업무일지!$B$5:$B$1004,">="&DATE($B$3,11,1),업무일지!$B$5:$B$1004,"<"&DATE($B$3,11+1,1)) -> 0 | I17: =SUMIFS(업무일지!$T$5:$T$1004,업무일지!$B$5:$B$1004,">="&DATE($B$3,11,1),업무일지!$B$5:$B$1004,"<"&DATE($B$3,11+1,1)) -> 0 | J17: =IFERROR(G17/D17,0) -> 0
A18: 12월 | B18: =COUNTIFS(업무일지!$B$5:$B$1004,">="&DATE($B$3,12,1),업무일지!$B$5:$B$1004,"<"&DATE($B$3,12+1,1),업무일지!$D$5:$D$1004,"출장") -> 0 | C18: =COUNTIFS(업무일지!$B$5:$B$1004,">="&DATE($B$3,12,1),업무일지!$B$5:$B$1004,"<"&DATE($B$3,12+1,1),업무일지!$D$5:$D$1004,"분석") -> 0 | D18: =B18+C18 -> 0 | E18: =SUMIFS(업무일지!$P$5:$P$1004,업무일지!$B$5:$B$1004,">="&DATE($B$3,12,1),업무일지!$B$5:$B$1004,"<"&DATE($B$3,12+1,1),업무일지!$D$5:$D$1004,"출장") -> 0 | F18: =SUMIFS(업무일지!$K$5:$K$1004,업무일지!$B$5:$B$1004,">="&DATE($B$3,12,1),업무일지!$B$5:$B$1004,"<"&DATE($B$3,12+1,1)) -> 0 | G18: =SUMIFS(업무일지!$R$5:$R$1004,업무일지!$B$5:$B$1004,">="&DATE($B$3,12,1),업무일지!$B$5:$B$1004,"<"&DATE($B$3,12+1,1)) -> 0 | H18: =SUMIFS(업무일지!$N$5:$N$1004,업무일지!$B$5:$B$1004,">="&DATE($B$3,12,1),업무일지!$B$5:$B$1004,"<"&DATE($B$3,12+1,1)) -> 0 | I18: =SUMIFS(업무일지!$T$5:$T$1004,업무일지!$B$5:$B$1004,">="&DATE($B$3,12,1),업무일지!$B$5:$B$1004,"<"&DATE($B$3,12+1,1)) -> 0 | J18: =IFERROR(G18/D18,0) -> 0
A19: 합계 | B19: =SUM(B7:B18) -> 1 | C19: =SUM(C7:C18) -> 2 | D19: =SUM(D7:D18) -> 3 | E19: =SUM(E7:E18) -> 2 | F19: =SUM(F7:F18) -> 5 | G19: =SUM(G7:G18) -> 89 | H19: =SUM(H7:H18) -> 12 | I19: =SUM(I7:I18) -> 552000 | J19: =IFERROR(G19/D19,0) -> 29.666667
A22: 2. 직무구분 · 세부유형별 현황 (연간 누계)
A23: 직무구분 | B23: 세부유형 | C23: 건수 | D23: 비중 | E23: 연인원(명) | F23: 총 인시(H) | G23: 대상매체(건) | H23: 데이터량(GB) | I23: 출장비(원) | J23: 평균 소요일수
A24: 출장 | B24: 압수·수색 집행 | C24: =COUNTIFS(업무일지!$B$5:$B$1004,">="&DATE($B$3,1,1),업무일지!$B$5:$B$1004,"<"&DATE($B$3+1,1,1),업무일지!$E$5:$E$1004,$B24) -> 1 | D24: =IFERROR(C24/$C$37,0) -> 0.33333333 | E24: =SUMIFS(업무일지!$K$5:$K$1004,업무일지!$B$5:$B$1004,">="&DATE($B$3,1,1),업무일지!$B$5:$B$1004,"<"&DATE($B$3+1,1,1),업무일지!$E$5:$E$1004,$B24) -> 3 | F24: =SUMIFS(업무일지!$R$5:$R$1004,업무일지!$B$5:$B$1004,">="&DATE($B$3,1,1),업무일지!$B$5:$B$1004,"<"&DATE($B$3+1,1,1),업무일지!$E$5:$E$1004,$B24) -> 48 | G24: =SUMIFS(업무일지!$N$5:$N$1004,업무일지!$B$5:$B$1004,">="&DATE($B$3,1,1),업무일지!$B$5:$B$1004,"<"&DATE($B$3+1,1,1),업무일지!$E$5:$E$1004,$B24) -> 6 | H24: =SUMIFS(업무일지!$O$5:$O$1004,업무일지!$B$5:$B$1004,">="&DATE($B$3,1,1),업무일지!$B$5:$B$1004,"<"&DATE($B$3+1,1,1),업무일지!$E$5:$E$1004,$B24) -> 3200 | I24: =SUMIFS(업무일지!$T$5:$T$1004,업무일지!$B$5:$B$1004,">="&DATE($B$3,1,1),업무일지!$B$5:$B$1004,"<"&DATE($B$3+1,1,1),업무일지!$E$5:$E$1004,$B24) -> 552000 | J24: =IFERROR(SUMIFS(업무일지!$P$5:$P$1004,업무일지!$B$5:$B$1004,">="&DATE($B$3,1,1),업무일지!$B$5:$B$1004,"<"&DATE($B$3+1,1,1),업무일지!$E$5:$E$1004,$B24)/C24,0) -> 2
A25: 출장 | B25: 현장 증거수집 | C25: =COUNTIFS(업무일지!$B$5:$B$1004,">="&DATE($B$3,1,1),업무일지!$B$5:$B$1004,"<"&DATE($B$3+1,1,1),업무일지!$E$5:$E$1004,$B25) -> 0 | D25: =IFERROR(C25/$C$37,0) -> 0 | E25: =SUMIFS(업무일지!$K$5:$K$1004,업무일지!$B$5:$B$1004,">="&DATE($B$3,1,1),업무일지!$B$5:$B$1004,"<"&DATE($B$3+1,1,1),업무일지!$E$5:$E$1004,$B25) -> 0 | F25: =SUMIFS(업무일지!$R$5:$R$1004,업무일지!$B$5:$B$1004,">="&DATE($B$3,1,1),업무일지!$B$5:$B$1004,"<"&DATE($B$3+1,1,1),업무일지!$E$5:$E$1004,$B25) -> 0 | G25: =SUMIFS(업무일지!$N$5:$N$1004,업무일지!$B$5:$B$1004,">="&DATE($B$3,1,1),업무일지!$B$5:$B$1004,"<"&DATE($B$3+1,1,1),업무일지!$E$5:$E$1004,$B25) -> 0 | H25: =SUMIFS(업무일지!$O$5:$O$1004,업무일지!$B$5:$B$1004,">="&DATE($B$3,1,1),업무일지!$B$5:$B$1004,"<"&DATE($B$3+1,1,1),업무일지!$E$5:$E$1004,$B25) -> 0 | I25: =SUMIFS(업무일지!$T$5:$T$1004,업무일지!$B$5:$B$1004,">="&DATE($B$3,1,1),업무일지!$B$5:$B$1004,"<"&DATE($B$3+1,1,1),업무일지!$E$5:$E$1004,$B25) -> 0 | J25: =IFERROR(SUMIFS(업무일지!$P$5:$P$1004,업무일지!$B$5:$B$1004,">="&DATE($B$3,1,1),업무일지!$B$5:$B$1004,"<"&DATE($B$3+1,1,1),업무일지!$E$5:$E$1004,$B25)/C25,0) -> 0
A26: 출장 | B26: 현장 지원·입회 | C26: =COUNTIFS(업무일지!$B$5:$B$1004,">="&DATE($B$3,1,1),업무일지!$B$5:$B$1004,"<"&DATE($B$3+1,1,1),업무일지!$E$5:$E$1004,$B26) -> 0 | D26: =IFERROR(C26/$C$37,0) -> 0 | E26: =SUMIFS(업무일지!$K$5:$K$1004,업무일지!$B$5:$B$1004,">="&DATE($B$3,1,1),업무일지!$B$5:$B$1004,"<"&DATE($B$3+1,1,1),업무일지!$E$5:$E$1004,$B26) -> 0 | F26: =SUMIFS(업무일지!$R$5:$R$1004,업무일지!$B$5:$B$1004,">="&DATE($B$3,1,1),업무일지!$B$5:$B$1004,"<"&DATE($B$3+1,1,1),업무일지!$E$5:$E$1004,$B26) -> 0 | G26: =SUMIFS(업무일지!$N$5:$N$1004,업무일지!$B$5:$B$1004,">="&DATE($B$3,1,1),업무일지!$B$5:$B$1004,"<"&DATE($B$3+1,1,1),업무일지!$E$5:$E$1004,$B26) -> 0 | H26: =SUMIFS(업무일지!$O$5:$O$1004,업무일지!$B$5:$B$1004,">="&DATE($B$3,1,1),업무일지!$B$5:$B$1004,"<"&DATE($B$3+1,1,1),업무일지!$E$5:$E$1004,$B26) -> 0 | I26: =SUMIFS(업무일지!$T$5:$T$1004,업무일지!$B$5:$B$1004,">="&DATE($B$3,1,1),업무일지!$B$5:$B$1004,"<"&DATE($B$3+1,1,1),업무일지!$E$5:$E$1004,$B26) -> 0 | J26: =IFERROR(SUMIFS(업무일지!$P$5:$P$1004,업무일지!$B$5:$B$1004,">="&DATE($B$3,1,1),업무일지!$B$5:$B$1004,"<"&DATE($B$3+1,1,1),업무일지!$E$5:$E$1004,$B26)/C26,0) -> 0
A27: 출장 | B27: 회의·협의 | C27: =COUNTIFS(업무일지!$B$5:$B$1004,">="&DATE($B$3,1,1),업무일지!$B$5:$B$1004,"<"&DATE($B$3+1,1,1),업무일지!$E$5:$E$1004,$B27) -> 0 | D27: =IFERROR(C27/$C$37,0) -> 0 | E27: =SUMIFS(업무일지!$K$5:$K$1004,업무일지!$B$5:$B$1004,">="&DATE($B$3,1,1),업무일지!$B$5:$B$1004,"<"&DATE($B$3+1,1,1),업무일지!$E$5:$E$1004,$B27) -> 0 | F27: =SUMIFS(업무일지!$R$5:$R$1004,업무일지!$B$5:$B$1004,">="&DATE($B$3,1,1),업무일지!$B$5:$B$1004,"<"&DATE($B$3+1,1,1),업무일지!$E$5:$E$1004,$B27) -> 0 | G27: =SUMIFS(업무일지!$N$5:$N$1004,업무일지!$B$5:$B$1004,">="&DATE($B$3,1,1),업무일지!$B$5:$B$1004,"<"&DATE($B$3+1,1,1),업무일지!$E$5:$E$1004,$B27) -> 0 | H27: =SUMIFS(업무일지!$O$5:$O$1004,업무일지!$B$5:$B$1004,">="&DATE($B$3,1,1),업무일지!$B$5:$B$1004,"<"&DATE($B$3+1,1,1),업무일지!$E$5:$E$1004,$B27) -> 0 | I27: =SUMIFS(업무일지!$T$5:$T$1004,업무일지!$B$5:$B$1004,">="&DATE($B$3,1,1),업무일지!$B$5:$B$1004,"<"&DATE($B$3+1,1,1),업무일지!$E$5:$E$1004,$B27) -> 0 | J27: =IFERROR(SUMIFS(업무일지!$P$5:$P$1004,업무일지!$B$5:$B$1004,">="&DATE($B$3,1,1),업무일지!$B$5:$B$1004,"<"&DATE($B$3+1,1,1),업무일지!$E$5:$E$1004,$B27)/C27,0) -> 0
A28: 출장 | B28: 교육·세미나 | C28: =COUNTIFS(업무일지!$B$5:$B$1004,">="&DATE($B$3,1,1),업무일지!$B$5:$B$1004,"<"&DATE($B$3+1,1,1),업무일지!$E$5:$E$1004,$B28) -> 0 | D28: =IFERROR(C28/$C$37,0) -> 0 | E28: =SUMIFS(업무일지!$K$5:$K$1004,업무일지!$B$5:$B$1004,">="&DATE($B$3,1,1),업무일지!$B$5:$B$1004,"<"&DATE($B$3+1,1,1),업무일지!$E$5:$E$1004,$B28) -> 0 | F28: =SUMIFS(업무일지!$R$5:$R$1004,업무일지!$B$5:$B$1004,">="&DATE($B$3,1,1),업무일지!$B$5:$B$1004,"<"&DATE($B$3+1,1,1),업무일지!$E$5:$E$1004,$B28) -> 0 | G28: =SUMIFS(업무일지!$N$5:$N$1004,업무일지!$B$5:$B$1004,">="&DATE($B$3,1,1),업무일지!$B$5:$B$1004,"<"&DATE($B$3+1,1,1),업무일지!$E$5:$E$1004,$B28) -> 0 | H28: =SUMIFS(업무일지!$O$5:$O$1004,업무일지!$B$5:$B$1004,">="&DATE($B$3,1,1),업무일지!$B$5:$B$1004,"<"&DATE($B$3+1,1,1),업무일지!$E$5:$E$1004,$B28) -> 0 | I28: =SUMIFS(업무일지!$T$5:$T$1004,업무일지!$B$5:$B$1004,">="&DATE($B$3,1,1),업무일지!$B$5:$B$1004,"<"&DATE($B$3+1,1,1),업무일지!$E$5:$E$1004,$B28) -> 0 | J28: =IFERROR(SUMIFS(업무일지!$P$5:$P$1004,업무일지!$B$5:$B$1004,">="&DATE($B$3,1,1),업무일지!$B$5:$B$1004,"<"&DATE($B$3+1,1,1),업무일지!$E$5:$E$1004,$B28)/C28,0) -> 0
A29: 출장 | B29: 기타 출장 | C29: =COUNTIFS(업무일지!$B$5:$B$1004,">="&DATE($B$3,1,1),업무일지!$B$5:$B$1004,"<"&DATE($B$3+1,1,1),업무일지!$E$5:$E$1004,$B29) -> 0 | D29: =IFERROR(C29/$C$37,0) -> 0 | E29: =SUMIFS(업무일지!$K$5:$K$1004,업무일지!$B$5:$B$1004,">="&DATE($B$3,1,1),업무일지!$B$5:$B$1004,"<"&DATE($B$3+1,1,1),업무일지!$E$5:$E$1004,$B29) -> 0 | F29: =SUMIFS(업무일지!$R$5:$R$1004,업무일지!$B$5:$B$1004,">="&DATE($B$3,1,1),업무일지!$B$5:$B$1004,"<"&DATE($B$3+1,1,1),업무일지!$E$5:$E$1004,$B29) -> 0 | G29: =SUMIFS(업무일지!$N$5:$N$1004,업무일지!$B$5:$B$1004,">="&DATE($B$3,1,1),업무일지!$B$5:$B$1004,"<"&DATE($B$3+1,1,1),업무일지!$E$5:$E$1004,$B29) -> 0 | H29: =SUMIFS(업무일지!$O$5:$O$1004,업무일지!$B$5:$B$1004,">="&DATE($B$3,1,1),업무일지!$B$5:$B$1004,"<"&DATE($B$3+1,1,1),업무일지!$E$5:$E$1004,$B29) -> 0 | I29: =SUMIFS(업무일지!$T$5:$T$1004,업무일지!$B$5:$B$1004,">="&DATE($B$3,1,1),업무일지!$B$5:$B$1004,"<"&DATE($B$3+1,1,1),업무일지!$E$5:$E$1004,$B29) -> 0 | J29: =IFERROR(SUMIFS(업무일지!$P$5:$P$1004,업무일지!$B$5:$B$1004,">="&DATE($B$3,1,1),업무일지!$B$5:$B$1004,"<"&DATE($B$3+1,1,1),업무일지!$E$5:$E$1004,$B29)/C29,0) -> 0
A30: 분석 | B30: 디스크 이미지 분석 | C30: =COUNTIFS(업무일지!$B$5:$B$1004,">="&DATE($B$3,1,1),업무일지!$B$5:$B$1004,"<"&DATE($B$3+1,1,1),업무일지!$E$5:$E$1004,$B30) -> 1 | D30: =IFERROR(C30/$C$37,0) -> 0.33333333 | E30: =SUMIFS(업무일지!$K$5:$K$1004,업무일지!$B$5:$B$1004,">="&DATE($B$3,1,1),업무일지!$B$5:$B$1004,"<"&DATE($B$3+1,1,1),업무일지!$E$5:$E$1004,$B30) -> 1 | F30: =SUMIFS(업무일지!$R$5:$R$1004,업무일지!$B$5:$B$1004,">="&DATE($B$3,1,1),업무일지!$B$5:$B$1004,"<"&DATE($B$3+1,1,1),업무일지!$E$5:$E$1004,$B30) -> 34 | G30: =SUMIFS(업무일지!$N$5:$N$1004,업무일지!$B$5:$B$1004,">="&DATE($B$3,1,1),업무일지!$B$5:$B$1004,"<"&DATE($B$3+1,1,1),업무일지!$E$5:$E$1004,$B30) -> 4 | H30: =SUMIFS(업무일지!$O$5:$O$1004,업무일지!$B$5:$B$1004,">="&DATE($B$3,1,1),업무일지!$B$5:$B$1004,"<"&DATE($B$3+1,1,1),업무일지!$E$5:$E$1004,$B30) -> 2400 | I30: =SUMIFS(업무일지!$T$5:$T$1004,업무일지!$B$5:$B$1004,">="&DATE($B$3,1,1),업무일지!$B$5:$B$1004,"<"&DATE($B$3+1,1,1),업무일지!$E$5:$E$1004,$B30) -> 0 | J30: =IFERROR(SUMIFS(업무일지!$P$5:$P$1004,업무일지!$B$5:$B$1004,">="&DATE($B$3,1,1),업무일지!$B$5:$B$1004,"<"&DATE($B$3+1,1,1),업무일지!$E$5:$E$1004,$B30)/C30,0) -> 5
A31: 분석 | B31: 모바일 분석 | C31: =COUNTIFS(업무일지!$B$5:$B$1004,">="&DATE($B$3,1,1),업무일지!$B$5:$B$1004,"<"&DATE($B$3+1,1,1),업무일지!$E$5:$E$1004,$B31) -> 1 | D31: =IFERROR(C31/$C$37,0) -> 0.33333333 | E31: =SUMIFS(업무일지!$K$5:$K$1004,업무일지!$B$5:$B$1004,">="&DATE($B$3,1,1),업무일지!$B$5:$B$1004,"<"&DATE($B$3+1,1,1),업무일지!$E$5:$E$1004,$B31) -> 1 | F31: =SUMIFS(업무일지!$R$5:$R$1004,업무일지!$B$5:$B$1004,">="&DATE($B$3,1,1),업무일지!$B$5:$B$1004,"<"&DATE($B$3+1,1,1),업무일지!$E$5:$E$1004,$B31) -> 7 | G31: =SUMIFS(업무일지!$N$5:$N$1004,업무일지!$B$5:$B$1004,">="&DATE($B$3,1,1),업무일지!$B$5:$B$1004,"<"&DATE($B$3+1,1,1),업무일지!$E$5:$E$1004,$B31) -> 2 | H31: =SUMIFS(업무일지!$O$5:$O$1004,업무일지!$B$5:$B$1004,">="&DATE($B$3,1,1),업무일지!$B$5:$B$1004,"<"&DATE($B$3+1,1,1),업무일지!$E$5:$E$1004,$B31) -> 480 | I31: =SUMIFS(업무일지!$T$5:$T$1004,업무일지!$B$5:$B$1004,">="&DATE($B$3,1,1),업무일지!$B$5:$B$1004,"<"&DATE($B$3+1,1,1),업무일지!$E$5:$E$1004,$B31) -> 0 | J31: =IFERROR(SUMIFS(업무일지!$P$5:$P$1004,업무일지!$B$5:$B$1004,">="&DATE($B$3,1,1),업무일지!$B$5:$B$1004,"<"&DATE($B$3+1,1,1),업무일지!$E$5:$E$1004,$B31)/C31,0) -> 1
A32: 분석 | B32: 영상·이미지 분석 | C32: =COUNTIFS(업무일지!$B$5:$B$1004,">="&DATE($B$3,1,1),업무일지!$B$5:$B$1004,"<"&DATE($B$3+1,1,1),업무일지!$E$5:$E$1004,$B32) -> 0 | D32: =IFERROR(C32/$C$37,0) -> 0 | E32: =SUMIFS(업무일지!$K$5:$K$1004,업무일지!$B$5:$B$1004,">="&DATE($B$3,1,1),업무일지!$B$5:$B$1004,"<"&DATE($B$3+1,1,1),업무일지!$E$5:$E$1004,$B32) -> 0 | F32: =SUMIFS(업무일지!$R$5:$R$1004,업무일지!$B$5:$B$1004,">="&DATE($B$3,1,1),업무일지!$B$5:$B$1004,"<"&DATE($B$3+1,1,1),업무일지!$E$5:$E$1004,$B32) -> 0 | G32: =SUMIFS(업무일지!$N$5:$N$1004,업무일지!$B$5:$B$1004,">="&DATE($B$3,1,1),업무일지!$B$5:$B$1004,"<"&DATE($B$3+1,1,1),업무일지!$E$5:$E$1004,$B32) -> 0 | H32: =SUMIFS(업무일지!$O$5:$O$1004,업무일지!$B$5:$B$1004,">="&DATE($B$3,1,1),업무일지!$B$5:$B$1004,"<"&DATE($B$3+1,1,1),업무일지!$E$5:$E$1004,$B32) -> 0 | I32: =SUMIFS(업무일지!$T$5:$T$1004,업무일지!$B$5:$B$1004,">="&DATE($B$3,1,1),업무일지!$B$5:$B$1004,"<"&DATE($B$3+1,1,1),업무일지!$E$5:$E$1004,$B32) -> 0 | J32: =IFERROR(SUMIFS(업무일지!$P$5:$P$1004,업무일지!$B$5:$B$1004,">="&DATE($B$3,1,1),업무일지!$B$5:$B$1004,"<"&DATE($B$3+1,1,1),업무일지!$E$5:$E$1004,$B32)/C32,0) -> 0
A33: 분석 | B33: 로그·네트워크 분석 | C33: =COUNTIFS(업무일지!$B$5:$B$1004,">="&DATE($B$3,1,1),업무일지!$B$5:$B$1004,"<"&DATE($B$3+1,1,1),업무일지!$E$5:$E$1004,$B33) -> 0 | D33: =IFERROR(C33/$C$37,0) -> 0 | E33: =SUMIFS(업무일지!$K$5:$K$1004,업무일지!$B$5:$B$1004,">="&DATE($B$3,1,1),업무일지!$B$5:$B$1004,"<"&DATE($B$3+1,1,1),업무일지!$E$5:$E$1004,$B33) -> 0 | F33: =SUMIFS(업무일지!$R$5:$R$1004,업무일지!$B$5:$B$1004,">="&DATE($B$3,1,1),업무일지!$B$5:$B$1004,"<"&DATE($B$3+1,1,1),업무일지!$E$5:$E$1004,$B33) -> 0 | G33: =SUMIFS(업무일지!$N$5:$N$1004,업무일지!$B$5:$B$1004,">="&DATE($B$3,1,1),업무일지!$B$5:$B$1004,"<"&DATE($B$3+1,1,1),업무일지!$E$5:$E$1004,$B33) -> 0 | H33: =SUMIFS(업무일지!$O$5:$O$1004,업무일지!$B$5:$B$1004,">="&DATE($B$3,1,1),업무일지!$B$5:$B$1004,"<"&DATE($B$3+1,1,1),업무일지!$E$5:$E$1004,$B33) -> 0 | I33: =SUMIFS(업무일지!$T$5:$T$1004,업무일지!$B$5:$B$1004,">="&DATE($B$3,1,1),업무일지!$B$5:$B$1004,"<"&DATE($B$3+1,1,1),업무일지!$E$5:$E$1004,$B33) -> 0 | J33: =IFERROR(SUMIFS(업무일지!$P$5:$P$1004,업무일지!$B$5:$B$1004,">="&DATE($B$3,1,1),업무일지!$B$5:$B$1004,"<"&DATE($B$3+1,1,1),업무일지!$E$5:$E$1004,$B33)/C33,0) -> 0
A34: 분석 | B34: 악성코드 분석 | C34: =COUNTIFS(업무일지!$B$5:$B$1004,">="&DATE($B$3,1,1),업무일지!$B$5:$B$1004,"<"&DATE($B$3+1,1,1),업무일지!$E$5:$E$1004,$B34) -> 0 | D34: =IFERROR(C34/$C$37,0) -> 0 | E34: =SUMIFS(업무일지!$K$5:$K$1004,업무일지!$B$5:$B$1004,">="&DATE($B$3,1,1),업무일지!$B$5:$B$1004,"<"&DATE($B$3+1,1,1),업무일지!$E$5:$E$1004,$B34) -> 0 | F34: =SUMIFS(업무일지!$R$5:$R$1004,업무일지!$B$5:$B$1004,">="&DATE($B$3,1,1),업무일지!$B$5:$B$1004,"<"&DATE($B$3+1,1,1),업무일지!$E$5:$E$1004,$B34) -> 0 | G34: =SUMIFS(업무일지!$N$5:$N$1004,업무일지!$B$5:$B$1004,">="&DATE($B$3,1,1),업무일지!$B$5:$B$1004,"<"&DATE($B$3+1,1,1),업무일지!$E$5:$E$1004,$B34) -> 0 | H34: =SUMIFS(업무일지!$O$5:$O$1004,업무일지!$B$5:$B$1004,">="&DATE($B$3,1,1),업무일지!$B$5:$B$1004,"<"&DATE($B$3+1,1,1),업무일지!$E$5:$E$1004,$B34) -> 0 | I34: =SUMIFS(업무일지!$T$5:$T$1004,업무일지!$B$5:$B$1004,">="&DATE($B$3,1,1),업무일지!$B$5:$B$1004,"<"&DATE($B$3+1,1,1),업무일지!$E$5:$E$1004,$B34) -> 0 | J34: =IFERROR(SUMIFS(업무일지!$P$5:$P$1004,업무일지!$B$5:$B$1004,">="&DATE($B$3,1,1),업무일지!$B$5:$B$1004,"<"&DATE($B$3+1,1,1),업무일지!$E$5:$E$1004,$B34)/C34,0) -> 0
A35: 분석 | B35: 보고서 작성·검증 | C35: =COUNTIFS(업무일지!$B$5:$B$1004,">="&DATE($B$3,1,1),업무일지!$B$5:$B$1004,"<"&DATE($B$3+1,1,1),업무일지!$E$5:$E$1004,$B35) -> 0 | D35: =IFERROR(C35/$C$37,0) -> 0 | E35: =SUMIFS(업무일지!$K$5:$K$1004,업무일지!$B$5:$B$1004,">="&DATE($B$3,1,1),업무일지!$B$5:$B$1004,"<"&DATE($B$3+1,1,1),업무일지!$E$5:$E$1004,$B35) -> 0 | F35: =SUMIFS(업무일지!$R$5:$R$1004,업무일지!$B$5:$B$1004,">="&DATE($B$3,1,1),업무일지!$B$5:$B$1004,"<"&DATE($B$3+1,1,1),업무일지!$E$5:$E$1004,$B35) -> 0 | G35: =SUMIFS(업무일지!$N$5:$N$1004,업무일지!$B$5:$B$1004,">="&DATE($B$3,1,1),업무일지!$B$5:$B$1004,"<"&DATE($B$3+1,1,1),업무일지!$E$5:$E$1004,$B35) -> 0 | H35: =SUMIFS(업무일지!$O$5:$O$1004,업무일지!$B$5:$B$1004,">="&DATE($B$3,1,1),업무일지!$B$5:$B$1004,"<"&DATE($B$3+1,1,1),업무일지!$E$5:$E$1004,$B35) -> 0 | I35: =SUMIFS(업무일지!$T$5:$T$1004,업무일지!$B$5:$B$1004,">="&DATE($B$3,1,1),업무일지!$B$5:$B$1004,"<"&DATE($B$3+1,1,1),업무일지!$E$5:$E$1004,$B35) -> 0 | J35: =IFERROR(SUMIFS(업무일지!$P$5:$P$1004,업무일지!$B$5:$B$1004,">="&DATE($B$3,1,1),업무일지!$B$5:$B$1004,"<"&DATE($B$3+1,1,1),업무일지!$E$5:$E$1004,$B35)/C35,0) -> 0
A36: 분석 | B36: 기타 분석 | C36: =COUNTIFS(업무일지!$B$5:$B$1004,">="&DATE($B$3,1,1),업무일지!$B$5:$B$1004,"<"&DATE($B$3+1,1,1),업무일지!$E$5:$E$1004,$B36) -> 0 | D36: =IFERROR(C36/$C$37,0) -> 0 | E36: =SUMIFS(업무일지!$K$5:$K$1004,업무일지!$B$5:$B$1004,">="&DATE($B$3,1,1),업무일지!$B$5:$B$1004,"<"&DATE($B$3+1,1,1),업무일지!$E$5:$E$1004,$B36) -> 0 | F36: =SUMIFS(업무일지!$R$5:$R$1004,업무일지!$B$5:$B$1004,">="&DATE($B$3,1,1),업무일지!$B$5:$B$1004,"<"&DATE($B$3+1,1,1),업무일지!$E$5:$E$1004,$B36) -> 0 | G36: =SUMIFS(업무일지!$N$5:$N$1004,업무일지!$B$5:$B$1004,">="&DATE($B$3,1,1),업무일지!$B$5:$B$1004,"<"&DATE($B$3+1,1,1),업무일지!$E$5:$E$1004,$B36) -> 0 | H36: =SUMIFS(업무일지!$O$5:$O$1004,업무일지!$B$5:$B$1004,">="&DATE($B$3,1,1),업무일지!$B$5:$B$1004,"<"&DATE($B$3+1,1,1),업무일지!$E$5:$E$1004,$B36) -> 0 | I36: =SUMIFS(업무일지!$T$5:$T$1004,업무일지!$B$5:$B$1004,">="&DATE($B$3,1,1),업무일지!$B$5:$B$1004,"<"&DATE($B$3+1,1,1),업무일지!$E$5:$E$1004,$B36) -> 0 | J36: =IFERROR(SUMIFS(업무일지!$P$5:$P$1004,업무일지!$B$5:$B$1004,">="&DATE($B$3,1,1),업무일지!$B$5:$B$1004,"<"&DATE($B$3+1,1,1),업무일지!$E$5:$E$1004,$B36)/C36,0) -> 0
A37: 합계 | C37: =SUM(C24:C36) -> 3 | D37: =IFERROR(C37/$C$37,0) -> 1 | E37: =SUM(E24:E36) -> 5 | F37: =SUM(F24:F36) -> 89 | G37: =SUM(G24:G36) -> 12 | H37: =SUM(H24:H36) -> 6080 | I37: =SUM(I24:I36) -> 552000
A40: 3. 팀별 현황 (연간 누계) ※ 주담당 기준
A41: 소속팀 | B41: 출장 건수 | C41: 분석 건수 | D41: 전체 건수 | E41: 출장 소요일수 | F41: 연인원(명) | G41: 총 인시(H) | H41: 대상매체(건) | I41: 출장비(원) | J41: 진행중
A42: 포렌식1팀 | B42: =COUNTIFS(업무일지!$B$5:$B$1004,">="&DATE($B$3,1,1),업무일지!$B$5:$B$1004,"<"&DATE($B$3+1,1,1),업무일지!$L$5:$L$1004,$A42,업무일지!$D$5:$D$1004,"출장") -> 1 | C42: =COUNTIFS(업무일지!$B$5:$B$1004,">="&DATE($B$3,1,1),업무일지!$B$5:$B$1004,"<"&DATE($B$3+1,1,1),업무일지!$L$5:$L$1004,$A42,업무일지!$D$5:$D$1004,"분석") -> 1 | D42: =B42+C42 -> 2 | E42: =SUMIFS(업무일지!$P$5:$P$1004,업무일지!$B$5:$B$1004,">="&DATE($B$3,1,1),업무일지!$B$5:$B$1004,"<"&DATE($B$3+1,1,1),업무일지!$L$5:$L$1004,$A42,업무일지!$D$5:$D$1004,"출장") -> 2 | F42: =SUMIFS(업무일지!$K$5:$K$1004,업무일지!$B$5:$B$1004,">="&DATE($B$3,1,1),업무일지!$B$5:$B$1004,"<"&DATE($B$3+1,1,1),업무일지!$L$5:$L$1004,$A42) -> 4 | G42: =SUMIFS(업무일지!$R$5:$R$1004,업무일지!$B$5:$B$1004,">="&DATE($B$3,1,1),업무일지!$B$5:$B$1004,"<"&DATE($B$3+1,1,1),업무일지!$L$5:$L$1004,$A42) -> 82 | H42: =SUMIFS(업무일지!$N$5:$N$1004,업무일지!$B$5:$B$1004,">="&DATE($B$3,1,1),업무일지!$B$5:$B$1004,"<"&DATE($B$3+1,1,1),업무일지!$L$5:$L$1004,$A42) -> 10 | I42: =SUMIFS(업무일지!$T$5:$T$1004,업무일지!$B$5:$B$1004,">="&DATE($B$3,1,1),업무일지!$B$5:$B$1004,"<"&DATE($B$3+1,1,1),업무일지!$L$5:$L$1004,$A42) -> 552000 | J42: =COUNTIFS(업무일지!$B$5:$B$1004,">="&DATE($B$3,1,1),업무일지!$B$5:$B$1004,"<"&DATE($B$3+1,1,1),업무일지!$L$5:$L$1004,$A42,업무일지!$S$5:$S$1004,"진행중") -> 0
A43: 포렌식2팀 | B43: =COUNTIFS(업무일지!$B$5:$B$1004,">="&DATE($B$3,1,1),업무일지!$B$5:$B$1004,"<"&DATE($B$3+1,1,1),업무일지!$L$5:$L$1004,$A43,업무일지!$D$5:$D$1004,"출장") -> 0 | C43: =COUNTIFS(업무일지!$B$5:$B$1004,">="&DATE($B$3,1,1),업무일지!$B$5:$B$1004,"<"&DATE($B$3+1,1,1),업무일지!$L$5:$L$1004,$A43,업무일지!$D$5:$D$1004,"분석") -> 1 | D43: =B43+C43 -> 1 | E43: =SUMIFS(업무일지!$P$5:$P$1004,업무일지!$B$5:$B$1004,">="&DATE($B$3,1,1),업무일지!$B$5:$B$1004,"<"&DATE($B$3+1,1,1),업무일지!$L$5:$L$1004,$A43,업무일지!$D$5:$D$1004,"출장") -> 0 | F43: =SUMIFS(업무일지!$K$5:$K$1004,업무일지!$B$5:$B$1004,">="&DATE($B$3,1,1),업무일지!$B$5:$B$1004,"<"&DATE($B$3+1,1,1),업무일지!$L$5:$L$1004,$A43) -> 1 | G43: =SUMIFS(업무일지!$R$5:$R$1004,업무일지!$B$5:$B$1004,">="&DATE($B$3,1,1),업무일지!$B$5:$B$1004,"<"&DATE($B$3+1,1,1),업무일지!$L$5:$L$1004,$A43) -> 7 | H43: =SUMIFS(업무일지!$N$5:$N$1004,업무일지!$B$5:$B$1004,">="&DATE($B$3,1,1),업무일지!$B$5:$B$1004,"<"&DATE($B$3+1,1,1),업무일지!$L$5:$L$1004,$A43) -> 2 | I43: =SUMIFS(업무일지!$T$5:$T$1004,업무일지!$B$5:$B$1004,">="&DATE($B$3,1,1),업무일지!$B$5:$B$1004,"<"&DATE($B$3+1,1,1),업무일지!$L$5:$L$1004,$A43) -> 0 | J43: =COUNTIFS(업무일지!$B$5:$B$1004,">="&DATE($B$3,1,1),업무일지!$B$5:$B$1004,"<"&DATE($B$3+1,1,1),업무일지!$L$5:$L$1004,$A43,업무일지!$S$5:$S$1004,"진행중") -> 1
A44: 침해대응팀 | B44: =COUNTIFS(업무일지!$B$5:$B$1004,">="&DATE($B$3,1,1),업무일지!$B$5:$B$1004,"<"&DATE($B$3+1,1,1),업무일지!$L$5:$L$1004,$A44,업무일지!$D$5:$D$1004,"출장") -> 0 | C44: =COUNTIFS(업무일지!$B$5:$B$1004,">="&DATE($B$3,1,1),업무일지!$B$5:$B$1004,"<"&DATE($B$3+1,1,1),업무일지!$L$5:$L$1004,$A44,업무일지!$D$5:$D$1004,"분석") -> 0 | D44: =B44+C44 -> 0 | E44: =SUMIFS(업무일지!$P$5:$P$1004,업무일지!$B$5:$B$1004,">="&DATE($B$3,1,1),업무일지!$B$5:$B$1004,"<"&DATE($B$3+1,1,1),업무일지!$L$5:$L$1004,$A44,업무일지!$D$5:$D$1004,"출장") -> 0 | F44: =SUMIFS(업무일지!$K$5:$K$1004,업무일지!$B$5:$B$1004,">="&DATE($B$3,1,1),업무일지!$B$5:$B$1004,"<"&DATE($B$3+1,1,1),업무일지!$L$5:$L$1004,$A44) -> 0 | G44: =SUMIFS(업무일지!$R$5:$R$1004,업무일지!$B$5:$B$1004,">="&DATE($B$3,1,1),업무일지!$B$5:$B$1004,"<"&DATE($B$3+1,1,1),업무일지!$L$5:$L$1004,$A44) -> 0 | H44: =SUMIFS(업무일지!$N$5:$N$1004,업무일지!$B$5:$B$1004,">="&DATE($B$3,1,1),업무일지!$B$5:$B$1004,"<"&DATE($B$3+1,1,1),업무일지!$L$5:$L$1004,$A44) -> 0 | I44: =SUMIFS(업무일지!$T$5:$T$1004,업무일지!$B$5:$B$1004,">="&DATE($B$3,1,1),업무일지!$B$5:$B$1004,"<"&DATE($B$3+1,1,1),업무일지!$L$5:$L$1004,$A44) -> 0 | J44: =COUNTIFS(업무일지!$B$5:$B$1004,">="&DATE($B$3,1,1),업무일지!$B$5:$B$1004,"<"&DATE($B$3+1,1,1),업무일지!$L$5:$L$1004,$A44,업무일지!$S$5:$S$1004,"진행중") -> 0
A45: 합계 | B45: =SUM(B42:B44) -> 1 | C45: =SUM(C42:C44) -> 2 | D45: =SUM(D42:D44) -> 3 | E45: =SUM(E42:E44) -> 2 | F45: =SUM(F42:F44) -> 5 | G45: =SUM(G42:G44) -> 89 | H45: =SUM(H42:H44) -> 12 | I45: =SUM(I42:I44) -> 552000 | J45: =SUM(J42:J44) -> 1
...

Sheet 사건별 현황
A1: 사건별 현황 · 사건번호 기준 통합
A2: ※ A열에 사건번호만 입력하면 나머지는 자동입니다. (연도 구분 없이 전체 기간 누계 — 해를 넘긴 사건도 한 줄) ※ 투입인원 = 주담당·동행자를 합쳐 중복 제거한 실인원.
A4: 1. 사건별 종합
A5: 사건번호 | B5: 사건명 · 업무명 | C5: 요청·의뢰처 | D5: 주담당자 | E5: 투입인원(명) | F5: 출장 건수 | G5: 분석 건수 | H5: 전체 건수 | I5: 출장 소요일수 | J5: 총 인시(H) | K5: 대상매체(건) | L5: 데이터량(GB) | M5: 출장비(원) | N5: 최초 착수일 | O5: 최종 종료일 | P5: 처리기간(일) | Q5: 진행상태
A6: 2026-형제-1024 | B6: =IFERROR(INDEX(업무일지!$F$5:$F$1004,MATCH($A6,업무일지!$G$5:$G$1004,0)),"") -> ○○ 기술유출 사건 압수수색 | C6: =IFERROR(INDEX(업무일지!$H$5:$H$1004,MATCH($A6,업무일지!$G$5:$G$1004,0)),"") -> 본청 수사과 | D6: =IFERROR(INDEX(업무일지!$I$5:$I$1004,MATCH($A6,업무일지!$G$5:$G$1004,0)),"") -> 김디지 | E6: =IF($A6="","",SUMPRODUCT((코드설정!$C$5:$C$24<>"")*((COUNTIFS(업무일지!$G$5:$G$1004,$A6,업무일지!$I$5:$I$1004,코드설정!$C$5:$C$24)+COUNTIFS(업무일지!$G$5:$G$1004,$A6,업무일지!$J$5:$J$1004,"*"&코드설정!$C$5:$C$24&"*"))>0))) -> 3 | F6: =IF($A6="","",COUNTIFS(업무일지!$G$5:$G$1004,$A6,업무일지!$D$5:$D$1004,"출장")) -> 1 | G6: =IF($A6="","",COUNTIFS(업무일지!$G$5:$G$1004,$A6,업무일지!$D$5:$D$1004,"분석")) -> 1 | H6: =IF($A6="","",F6+G6) -> 2 | I6: =IF($A6="","",SUMIFS(업무일지!$P$5:$P$1004,업무일지!$G$5:$G$1004,$A6,업무일지!$D$5:$D$1004,"출장")) -> 2 | J6: =IF($A6="","",SUMIFS(업무일지!$R$5:$R$1004,업무일지!$G$5:$G$1004,$A6)) -> 82 | K6: =IF($A6="","",SUMIFS(업무일지!$N$5:$N$1004,업무일지!$G$5:$G$1004,$A6)) -> 10 | L6: =IF($A6="","",SUMIFS(업무일지!$O$5:$O$1004,업무일지!$G$5:$G$1004,$A6)) -> 5600 | M6: =IF($A6="","",SUMIFS(업무일지!$T$5:$T$1004,업무일지!$G$5:$G$1004,$A6)) -> 552000 | N6: =IF($A6="","",IFERROR(_xlfn.MINIFS(업무일지!$B$5:$B$1004,업무일지!$G$5:$G$1004,$A6),"")) -> 46085 | O6: =IF($A6="","",IFERROR(_xlfn.MAXIFS(업무일지!$C$5:$C$1004,업무일지!$G$5:$G$1004,$A6),"")) -> 46094 | P6: =IF($A6="","",IF(OR(N6="",O6="",O6=0),"",O6-N6+1)) -> 10 | Q6: =IF($A6="","",IF(H6=0,"미기록",IF(COUNTIFS(업무일지!$G$5:$G$1004,$A6,업무일지!$S$5:$S$1004,"진행중")>0,"진행중",IF(COUNTIFS(업무일지!$G$5:$G$1004,$A6,업무일지!$S$5:$S$1004,"보류")>0,"보류","완료")))) -> 완료
A7: 2026-형제-1131 | B7: =IFERROR(INDEX(업무일지!$F$5:$F$1004,MATCH($A7,업무일지!$G$5:$G$1004,0)),"") -> △△ 사건 휴대폰 추출·분석 | C7: =IFERROR(INDEX(업무일지!$H$5:$H$1004,MATCH($A7,업무일지!$G$5:$G$1004,0)),"") -> 지방청 사이버수사대 | D7: =IFERROR(INDEX(업무일지!$I$5:$I$1004,MATCH($A7,업무일지!$G$5:$G$1004,0)),"") -> 박증거 | E7: =IF($A7="","",SUMPRODUCT((코드설정!$C$5:$C$24<>"")*((COUNTIFS(업무일지!$G$5:$G$1004,$A7,업무일지!$I$5:$I$1004,코드설정!$C$5:$C$24)+COUNTIFS(업무일지!$G$5:$G$1004,$A7,업무일지!$J$5:$J$1004,"*"&코드설정!$C$5:$C$24&"*"))>0))) -> 1 | F7: =IF($A7="","",COUNTIFS(업무일지!$G$5:$G$1004,$A7,업무일지!$D$5:$D$1004,"출장")) -> 0 | G7: =IF($A7="","",COUNTIFS(업무일지!$G$5:$G$1004,$A7,업무일지!$D$5:$D$1004,"분석")) -> 1 | H7: =IF($A7="","",F7+G7) -> 1 | I7: =IF($A7="","",SUMIFS(업무일지!$P$5:$P$1004,업무일지!$G$5:$G$1004,$A7,업무일지!$D$5:$D$1004,"출장")) -> 0 | J7: =IF($A7="","",SUMIFS(업무일지!$R$5:$R$1004,업무일지!$G$5:$G$1004,$A7)) -> 7 | K7: =IF($A7="","",SUMIFS(업무일지!$N$5:$N$1004,업무일지!$G$5:$G$1004,$A7)) -> 2 | L7: =IF($A7="","",SUMIFS(업무일지!$O$5:$O$1004,업무일지!$G$5:$G$1004,$A7)) -> 480 | M7: =IF($A7="","",SUMIFS(업무일지!$T$5:$T$1004,업무일지!$G$5:$G$1004,$A7)) -> 0 | N7: =IF($A7="","",IFERROR(_xlfn.MINIFS(업무일지!$B$5:$B$1004,업무일지!$G$5:$G$1004,$A7),"")) -> 46098 | O7: =IF($A7="","",IFERROR(_xlfn.MAXIFS(업무일지!$C$5:$C$1004,업무일지!$G$5:$G$1004,$A7),"")) -> 46098 | P7: =IF($A7="","",IF(OR(N7="",O7="",O7=0),"",O7-N7+1)) -> 1 | Q7: =IF($A7="","",IF(H7=0,"미기록",IF(COUNTIFS(업무일지!$G$5:$G$1004,$A7,업무일지!$S$5:$S$1004,"진행중")>0,"진행중",IF(COUNTIFS(업무일지!$G$5:$G$1004,$A7,업무일지!$S$5:$S$1004,"보류")>0,"보류","완료")))) -> 진행중
B8: =IFERROR(INDEX(업무일지!$F$5:$F$1004,MATCH($A8,업무일지!$G$5:$G$1004,0)),"") | C8: =IFERROR(INDEX(업무일지!$H$5:$H$1004,MATCH($A8,업무일지!$G$5:$G$1004,0)),"") | D8: =IFERROR(INDEX(업무일지!$I$5:$I$1004,MATCH($A8,업무일지!$G$5:$G$1004,0)),"") | E8: =IF($A8="","",SUMPRODUCT((코드설정!$C$5:$C$24<>"")*((COUNTIFS(업무일지!$G$5:$G$1004,$A8,업무일지!$I$5:$I$1004,코드설정!$C$5:$C$24)+COUNTIFS(업무일지!$G$5:$G$1004,$A8,업무일지!$J$5:$J$1004,"*"&코드설정!$C$5:$C$24&"*"))>0))) | F8: =IF($A8="","",COUNTIFS(업무일지!$G$5:$G$1004,$A8,업무일지!$D$5:$D$1004,"출장")) | G8: =IF($A8="","",COUNTIFS(업무일지!$G$5:$G$1004,$A8,업무일지!$D$5:$D$1004,"분석")) | H8: =IF($A8="","",F8+G8) | I8: =IF($A8="","",SUMIFS(업무일지!$P$5:$P$1004,업무일지!$G$5:$G$1004,$A8,업무일지!$D$5:$D$1004,"출장")) | J8: =IF($A8="","",SUMIFS(업무일지!$R$5:$R$1004,업무일지!$G$5:$G$1004,$A8)) | K8: =IF($A8="","",SUMIFS(업무일지!$N$5:$N$1004,업무일지!$G$5:$G$1004,$A8)) | L8: =IF($A8="","",SUMIFS(업무일지!$O$5:$O$1004,업무일지!$G$5:$G$1004,$A8)) | M8: =IF($A8="","",SUMIFS(업무일지!$T$5:$T$1004,업무일지!$G$5:$G$1004,$A8)) | N8: =IF($A8="","",IFERROR(_xlfn.MINIFS(업무일지!$B$5:$B$1004,업무일지!$G$5:$G$1004,$A8),"")) | O8: =IF($A8="","",IFERROR(_xlfn.MAXIFS(업무일지!$C$5:$C$1004,업무일지!$G$5:$G$1004,$A8),"")) | P8: =IF($A8="","",IF(OR(N8="",O8="",O8=0),"",O8-N8+1)) | Q8: =IF($A8="","",IF(H8=0,"미기록",IF(COUNTIFS(업무일지!$G$5:$G$1004,$A8,업무일지!$S$5:$S$1004,"진행중")>0,"진행중",IF(COUNTIFS(업무일지!$G$5:$G$1004,$A8,업무일지!$S$5:$S$1004,"보류")>0,"보류","완료"))))
B9: =IFERROR(INDEX(업무일지!$F$5:$F$1004,MATCH($A9,업무일지!$G$5:$G$1004,0)),"") | C9: =IFERROR(INDEX(업무일지!$H$5:$H$1004,MATCH($A9,업무일지!$G$5:$G$1004,0)),"") | D9: =IFERROR(INDEX(업무일지!$I$5:$I$1004,MATCH($A9,업무일지!$G$5:$G$1004,0)),"") | E9: =IF($A9="","",SUMPRODUCT((코드설정!$C$5:$C$24<>"")*((COUNTIFS(업무일지!$G$5:$G$1004,$A9,업무일지!$I$5:$I$1004,코드설정!$C$5:$C$24)+COUNTIFS(업무일지!$G$5:$G$1004,$A9,업무일지!$J$5:$J$1004,"*"&코드설정!$C$5:$C$24&"*"))>0))) | F9: =IF($A9="","",COUNTIFS(업무일지!$G$5:$G$1004,$A9,업무일지!$D$5:$D$1004,"출장")) | G9: =IF($A9="","",COUNTIFS(업무일지!$G$5:$G$1004,$A9,업무일지!$D$5:$D$1004,"분석")) | H9: =IF($A9="","",F9+G9) | I9: =IF($A9="","",SUMIFS(업무일지!$P$5:$P$1004,업무일지!$G$5:$G$1004,$A9,업무일지!$D$5:$D$1004,"출장")) | J9: =IF($A9="","",SUMIFS(업무일지!$R$5:$R$1004,업무일지!$G$5:$G$1004,$A9)) | K9: =IF($A9="","",SUMIFS(업무일지!$N$5:$N$1004,업무일지!$G$5:$G$1004,$A9)) | L9: =IF($A9="","",SUMIFS(업무일지!$O$5:$O$1004,업무일지!$G$5:$G$1004,$A9)) | M9: =IF($A9="","",SUMIFS(업무일지!$T$5:$T$1004,업무일지!$G$5:$G$1004,$A9)) | N9: =IF($A9="","",IFERROR(_xlfn.MINIFS(업무일지!$B$5:$B$1004,업무일지!$G$5:$G$1004,$A9),"")) | O9: =IF($A9="","",IFERROR(_xlfn.MAXIFS(업무일지!$C$5:$C$1004,업무일지!$G$5:$G$1004,$A9),"")) | P9: =IF($A9="","",IF(OR(N9="",O9="",O9=0),"",O9-N9+1)) | Q9: =IF($A9="","",IF(H9=0,"미기록",IF(COUNTIFS(업무일지!$G$5:$G$1004,$A9,업무일지!$S$5:$S$1004,"진행중")>0,"진행중",IF(COUNTIFS(업무일지!$G$5:$G$1004,$A9,업무일지!$S$5:$S$1004,"보류")>0,"보류","완료"))))
B10: =IFERROR(INDEX(업무일지!$F$5:$F$1004,MATCH($A10,업무일지!$G$5:$G$1004,0)),"") | C10: =IFERROR(INDEX(업무일지!$H$5:$H$1004,MATCH($A10,업무일지!$G$5:$G$1004,0)),"") | D10: =IFERROR(INDEX(업무일지!$I$5:$I$1004,MATCH($A10,업무일지!$G$5:$G$1004,0)),"") | E10: =IF($A10="","",SUMPRODUCT((코드설정!$C$5:$C$24<>"")*((COUNTIFS(업무일지!$G$5:$G$1004,$A10,업무일지!$I$5:$I$1004,코드설정!$C$5:$C$24)+COUNTIFS(업무일지!$G$5:$G$1004,$A10,업무일지!$J$5:$J$1004,"*"&코드설정!$C$5:$C$24&"*"))>0))) | F10: =IF($A10="","",COUNTIFS(업무일지!$G$5:$G$1004,$A10,업무일지!$D$5:$D$1004,"출장")) | G10: =IF($A10="","",COUNTIFS(업무일지!$G$5:$G$1004,$A10,업무일지!$D$5:$D$1004,"분석")) | H10: =IF($A10="","",F10+G10) | I10: =IF($A10="","",SUMIFS(업무일지!$P$5:$P$1004,업무일지!$G$5:$G$1004,$A10,업무일지!$D$5:$D$1004,"출장")) | J10: =IF($A10="","",SUMIFS(업무일지!$R$5:$R$1004,업무일지!$G$5:$G$1004,$A10)) | K10: =IF($A10="","",SUMIFS(업무일지!$N$5:$N$1004,업무일지!$G$5:$G$1004,$A10)) | L10: =IF($A10="","",SUMIFS(업무일지!$O$5:$O$1004,업무일지!$G$5:$G$1004,$A10)) | M10: =IF($A10="","",SUMIFS(업무일지!$T$5:$T$1004,업무일지!$G$5:$G$1004,$A10)) | N10: =IF($A10="","",IFERROR(_xlfn.MINIFS(업무일지!$B$5:$B$1004,업무일지!$G$5:$G$1004,$A10),"")) | O10: =IF($A10="","",IFERROR(_xlfn.MAXIFS(업무일지!$C$5:$C$1004,업무일지!$G$5:$G$1004,$A10),"")) | P10: =IF($A10="","",IF(OR(N10="",O10="",O10=0),"",O10-N10+1)) | Q10: =IF($A10="","",IF(H10=0,"미기록",IF(COUNTIFS(업무일지!$G$5:$G$1004,$A10,업무일지!$S$5:$S$1004,"진행중")>0,"진행중",IF(COUNTIFS(업무일지!$G$5:$G$1004,$A10,업무일지!$S$5:$S$1004,"보류")>0,"보류","완료"))))
B11: =IFERROR(INDEX(업무일지!$F$5:$F$1004,MATCH($A11,업무일지!$G$5:$G$1004,0)),"") | C11: =IFERROR(INDEX(업무일지!$H$5:$H$1004,MATCH($A11,업무일지!$G$5:$G$1004,0)),"") | D11: =IFERROR(INDEX(업무일지!$I$5:$I$1004,MATCH($A11,업무일지!$G$5:$G$1004,0)),"") | E11: =IF($A11="","",SUMPRODUCT((코드설정!$C$5:$C$24<>"")*((COUNTIFS(업무일지!$G$5:$G$1004,$A11,업무일지!$I$5:$I$1004,코드설정!$C$5:$C$24)+COUNTIFS(업무일지!$G$5:$G$1004,$A11,업무일지!$J$5:$J$1004,"*"&코드설정!$C$5:$C$24&"*"))>0))) | F11: =IF($A11="","",COUNTIFS(업무일지!$G$5:$G$1004,$A11,업무일지!$D$5:$D$1004,"출장")) | G11: =IF($A11="","",COUNTIFS(업무일지!$G$5:$G$1004,$A11,업무일지!$D$5:$D$1004,"분석")) | H11: =IF($A11="","",F11+G11) | I11: =IF($A11="","",SUMIFS(업무일지!$P$5:$P$1004,업무일지!$G$5:$G$1004,$A11,업무일지!$D$5:$D$1004,"출장")) | J11: =IF($A11="","",SUMIFS(업무일지!$R$5:$R$1004,업무일지!$G$5:$G$1004,$A11)) | K11: =IF($A11="","",SUMIFS(업무일지!$N$5:$N$1004,업무일지!$G$5:$G$1004,$A11)) | L11: =IF($A11="","",SUMIFS(업무일지!$O$5:$O$1004,업무일지!$G$5:$G$1004,$A11)) | M11: =IF($A11="","",SUMIFS(업무일지!$T$5:$T$1004,업무일지!$G$5:$G$1004,$A11)) | N11: =IF($A11="","",IFERROR(_xlfn.MINIFS(업무일지!$B$5:$B$1004,업무일지!$G$5:$G$1004,$A11),"")) | O11: =IF($A11="","",IFERROR(_xlfn.MAXIFS(업무일지!$C$5:$C$1004,업무일지!$G$5:$G$1004,$A11),"")) | P11: =IF($A11="","",IF(OR(N11="",O11="",O11=0),"",O11-N11+1)) | Q11: =IF($A11="","",IF(H11=0,"미기록",IF(COUNTIFS(업무일지!$G$5:$G$1004,$A11,업무일지!$S$5:$S$1004,"진행중")>0,"진행중",IF(COUNTIFS(업무일지!$G$5:$G$1004,$A11,업무일지!$S$5:$S$1004,"보류")>0,"보류","완료"))))
B12: =IFERROR(INDEX(업무일지!$F$5:$F$1004,MATCH($A12,업무일지!$G$5:$G$1004,0)),"") | C12: =IFERROR(INDEX(업무일지!$H$5:$H$1004,MATCH($A12,업무일지!$G$5:$G$1004,0)),"") | D12: =IFERROR(INDEX(업무일지!$I$5:$I$1004,MATCH($A12,업무일지!$G$5:$G$1004,0)),"") | E12: =IF($A12="","",SUMPRODUCT((코드설정!$C$5:$C$24<>"")*((COUNTIFS(업무일지!$G$5:$G$1004,$A12,업무일지!$I$5:$I$1004,코드설정!$C$5:$C$24)+COUNTIFS(업무일지!$G$5:$G$1004,$A12,업무일지!$J$5:$J$1004,"*"&코드설정!$C$5:$C$24&"*"))>0))) | F12: =IF($A12="","",COUNTIFS(업무일지!$G$5:$G$1004,$A12,업무일지!$D$5:$D$1004,"출장")) | G12: =IF($A12="","",COUNTIFS(업무일지!$G$5:$G$1004,$A12,업무일지!$D$5:$D$1004,"분석")) | H12: =IF($A12="","",F12+G12) | I12: =IF($A12="","",SUMIFS(업무일지!$P$5:$P$1004,업무일지!$G$5:$G$1004,$A12,업무일지!$D$5:$D$1004,"출장")) | J12: =IF($A12="","",SUMIFS(업무일지!$R$5:$R$1004,업무일지!$G$5:$G$1004,$A12)) | K12: =IF($A12="","",SUMIFS(업무일지!$N$5:$N$1004,업무일지!$G$5:$G$1004,$A12)) | L12: =IF($A12="","",SUMIFS(업무일지!$O$5:$O$1004,업무일지!$G$5:$G$1004,$A12)) | M12: =IF($A12="","",SUMIFS(업무일지!$T$5:$T$1004,업무일지!$G$5:$G$1004,$A12)) | N12: =IF($A12="","",IFERROR(_xlfn.MINIFS(업무일지!$B$5:$B$1004,업무일지!$G$5:$G$1004,$A12),"")) | O12: =IF($A12="","",IFERROR(_xlfn.MAXIFS(업무일지!$C$5:$C$1004,업무일지!$G$5:$G$1004,$A12),"")) | P12: =IF($A12="","",IF(OR(N12="",O12="",O12=0),"",O12-N12+1)) | Q12: =IF($A12="","",IF(H12=0,"미기록",IF(COUNTIFS(업무일지!$G$5:$G$1004,$A12,업무일지!$S$5:$S$1004,"진행중")>0,"진행중",IF(COUNTIFS(업무일지!$G$5:$G$1004,$A12,업무일지!$S$5:$S$1004,"보류")>0,"보류","완료"))))
B13: =IFERROR(INDEX(업무일지!$F$5:$F$1004,MATCH($A13,업무일지!$G$5:$G$1004,0)),"") | C13: =IFERROR(INDEX(업무일지!$H$5:$H$1004,MATCH($A13,업무일지!$G$5:$G$1004,0)),"") | D13: =IFERROR(INDEX(업무일지!$I$5:$I$1004,MATCH($A13,업무일지!$G$5:$G$1004,0)),"") | E13: =IF($A13="","",SUMPRODUCT((코드설정!$C$5:$C$24<>"")*((COUNTIFS(업무일지!$G$5:$G$1004,$A13,업무일지!$I$5:$I$1004,코드설정!$C$5:$C$24)+COUNTIFS(업무일지!$G$5:$G$1004,$A13,업무일지!$J$5:$J$1004,"*"&코드설정!$C$5:$C$24&"*"))>0))) | F13: =IF($A13="","",COUNTIFS(업무일지!$G$5:$G$1004,$A13,업무일지!$D$5:$D$1004,"출장")) | G13: =IF($A13="","",COUNTIFS(업무일지!$G$5:$G$1004,$A13,업무일지!$D$5:$D$1004,"분석")) | H13: =IF($A13="","",F13+G13) | I13: =IF($A13="","",SUMIFS(업무일지!$P$5:$P$1004,업무일지!$G$5:$G$1004,$A13,업무일지!$D$5:$D$1004,"출장")) | J13: =IF($A13="","",SUMIFS(업무일지!$R$5:$R$1004,업무일지!$G$5:$G$1004,$A13)) | K13: =IF($A13="","",SUMIFS(업무일지!$N$5:$N$1004,업무일지!$G$5:$G$1004,$A13)) | L13: =IF($A13="","",SUMIFS(업무일지!$O$5:$O$1004,업무일지!$G$5:$G$1004,$A13)) | M13: =IF($A13="","",SUMIFS(업무일지!$T$5:$T$1004,업무일지!$G$5:$G$1004,$A13)) | N13: =IF($A13="","",IFERROR(_xlfn.MINIFS(업무일지!$B$5:$B$1004,업무일지!$G$5:$G$1004,$A13),"")) | O13: =IF($A13="","",IFERROR(_xlfn.MAXIFS(업무일지!$C$5:$C$1004,업무일지!$G$5:$G$1004,$A13),"")) | P13: =IF($A13="","",IF(OR(N13="",O13="",O13=0),"",O13-N13+1)) | Q13: =IF($A13="","",IF(H13=0,"미기록",IF(COUNTIFS(업무일지!$G$5:$G$1004,$A13,업무일지!$S$5:$S$1004,"진행중")>0,"진행중",IF(COUNTIFS(업무일지!$G$5:$G$1004,$A13,업무일지!$S$5:$S$1004,"보류")>0,"보류","완료"))))
B14: =IFERROR(INDEX(업무일지!$F$5:$F$1004,MATCH($A14,업무일지!$G$5:$G$1004,0)),"") | C14: =IFERROR(INDEX(업무일지!$H$5:$H$1004,MATCH($A14,업무일지!$G$5:$G$1004,0)),"") | D14: =IFERROR(INDEX(업무일지!$I$5:$I$1004,MATCH($A14,업무일지!$G$5:$G$1004,0)),"") | E14: =IF($A14="","",SUMPRODUCT((코드설정!$C$5:$C$24<>"")*((COUNTIFS(업무일지!$G$5:$G$1004,$A14,업무일지!$I$5:$I$1004,코드설정!$C$5:$C$24)+COUNTIFS(업무일지!$G$5:$G$1004,$A14,업무일지!$J$5:$J$1004,"*"&코드설정!$C$5:$C$24&"*"))>0))) | F14: =IF($A14="","",COUNTIFS(업무일지!$G$5:$G$1004,$A14,업무일지!$D$5:$D$1004,"출장")) | G14: =IF($A14="","",COUNTIFS(업무일지!$G$5:$G$1004,$A14,업무일지!$D$5:$D$1004,"분석")) | H14: =IF($A14="","",F14+G14) | I14: =IF($A14="","",SUMIFS(업무일지!$P$5:$P$1004,업무일지!$G$5:$G$1004,$A14,업무일지!$D$5:$D$1004,"출장")) | J14: =IF($A14="","",SUMIFS(업무일지!$R$5:$R$1004,업무일지!$G$5:$G$1004,$A14)) | K14: =IF($A14="","",SUMIFS(업무일지!$N$5:$N$1004,업무일지!$G$5:$G$1004,$A14)) | L14: =IF($A14="","",SUMIFS(업무일지!$O$5:$O$1004,업무일지!$G$5:$G$1004,$A14)) | M14: =IF($A14="","",SUMIFS(업무일지!$T$5:$T$1004,업무일지!$G$5:$G$1004,$A14)) | N14: =IF($A14="","",IFERROR(_xlfn.MINIFS(업무일지!$B$5:$B$1004,업무일지!$G$5:$G$1004,$A14),"")) | O14: =IF($A14="","",IFERROR(_xlfn.MAXIFS(업무일지!$C$5:$C$1004,업무일지!$G$5:$G$1004,$A14),"")) | P14: =IF($A14="","",IF(OR(N14="",O14="",O14=0),"",O14-N14+1)) | Q14: =IF($A14="","",IF(H14=0,"미기록",IF(COUNTIFS(업무일지!$G$5:$G$1004,$A14,업무일지!$S$5:$S$1004,"진행중")>0,"진행중",IF(COUNTIFS(업무일지!$G$5:$G$1004,$A14,업무일지!$S$5:$S$1004,"보류")>0,"보류","완료"))))
B15: =IFERROR(INDEX(업무일지!$F$5:$F$1004,MATCH($A15,업무일지!$G$5:$G$1004,0)),"") | C15: =IFERROR(INDEX(업무일지!$H$5:$H$1004,MATCH($A15,업무일지!$G$5:$G$1004,0)),"") | D15: =IFERROR(INDEX(업무일지!$I$5:$I$1004,MATCH($A15,업무일지!$G$5:$G$1004,0)),"") | E15: =IF($A15="","",SUMPRODUCT((코드설정!$C$5:$C$24<>"")*((COUNTIFS(업무일지!$G$5:$G$1004,$A15,업무일지!$I$5:$I$1004,코드설정!$C$5:$C$24)+COUNTIFS(업무일지!$G$5:$G$1004,$A15,업무일지!$J$5:$J$1004,"*"&코드설정!$C$5:$C$24&"*"))>0))) | F15: =IF($A15="","",COUNTIFS(업무일지!$G$5:$G$1004,$A15,업무일지!$D$5:$D$1004,"출장")) | G15: =IF($A15="","",COUNTIFS(업무일지!$G$5:$G$1004,$A15,업무일지!$D$5:$D$1004,"분석")) | H15: =IF($A15="","",F15+G15) | I15: =IF($A15="","",SUMIFS(업무일지!$P$5:$P$1004,업무일지!$G$5:$G$1004,$A15,업무일지!$D$5:$D$1004,"출장")) | J15: =IF($A15="","",SUMIFS(업무일지!$R$5:$R$1004,업무일지!$G$5:$G$1004,$A15)) | K15: =IF($A15="","",SUMIFS(업무일지!$N$5:$N$1004,업무일지!$G$5:$G$1004,$A15)) | L15: =IF($A15="","",SUMIFS(업무일지!$O$5:$O$1004,업무일지!$G$5:$G$1004,$A15)) | M15: =IF($A15="","",SUMIFS(업무일지!$T$5:$T$1004,업무일지!$G$5:$G$1004,$A15)) | N15: =IF($A15="","",IFERROR(_xlfn.MINIFS(업무일지!$B$5:$B$1004,업무일지!$G$5:$G$1004,$A15),"")) | O15: =IF($A15="","",IFERROR(_xlfn.MAXIFS(업무일지!$C$5:$C$1004,업무일지!$G$5:$G$1004,$A15),"")) | P15: =IF($A15="","",IF(OR(N15="",O15="",O15=0),"",O15-N15+1)) | Q15: =IF($A15="","",IF(H15=0,"미기록",IF(COUNTIFS(업무일지!$G$5:$G$1004,$A15,업무일지!$S$5:$S$1004,"진행중")>0,"진행중",IF(COUNTIFS(업무일지!$G$5:$G$1004,$A15,업무일지!$S$5:$S$1004,"보류")>0,"보류","완료"))))
B16: =IFERROR(INDEX(업무일지!$F$5:$F$1004,MATCH($A16,업무일지!$G$5:$G$1004,0)),"") | C16: =IFERROR(INDEX(업무일지!$H$5:$H$1004,MATCH($A16,업무일지!$G$5:$G$1004,0)),"") | D16: =IFERROR(INDEX(업무일지!$I$5:$I$1004,MATCH($A16,업무일지!$G$5:$G$1004,0)),"") | E16: =IF($A16="","",SUMPRODUCT((코드설정!$C$5:$C$24<>"")*((COUNTIFS(업무일지!$G$5:$G$1004,$A16,업무일지!$I$5:$I$1004,코드설정!$C$5:$C$24)+COUNTIFS(업무일지!$G$5:$G$1004,$A16,업무일지!$J$5:$J$1004,"*"&코드설정!$C$5:$C$24&"*"))>0))) | F16: =IF($A16="","",COUNTIFS(업무일지!$G$5:$G$1004,$A16,업무일지!$D$5:$D$1004,"출장")) | G16: =IF($A16="","",COUNTIFS(업무일지!$G$5:$G$1004,$A16,업무일지!$D$5:$D$1004,"분석")) | H16: =IF($A16="","",F16+G16) | I16: =IF($A16="","",SUMIFS(업무일지!$P$5:$P$1004,업무일지!$G$5:$G$1004,$A16,업무일지!$D$5:$D$1004,"출장")) | J16: =IF($A16="","",SUMIFS(업무일지!$R$5:$R$1004,업무일지!$G$5:$G$1004,$A16)) | K16: =IF($A16="","",SUMIFS(업무일지!$N$5:$N$1004,업무일지!$G$5:$G$1004,$A16)) | L16: =IF($A16="","",SUMIFS(업무일지!$O$5:$O$1004,업무일지!$G$5:$G$1004,$A16)) | M16: =IF($A16="","",SUMIFS(업무일지!$T$5:$T$1004,업무일지!$G$5:$G$1004,$A16)) | N16: =IF($A16="","",IFERROR(_xlfn.MINIFS(업무일지!$B$5:$B$1004,업무일지!$G$5:$G$1004,$A16),"")) | O16: =IF($A16="","",IFERROR(_xlfn.MAXIFS(업무일지!$C$5:$C$1004,업무일지!$G$5:$G$1004,$A16),"")) | P16: =IF($A16="","",IF(OR(N16="",O16="",O16=0),"",O16-N16+1)) | Q16: =IF($A16="","",IF(H16=0,"미기록",IF(COUNTIFS(업무일지!$G$5:$G$1004,$A16,업무일지!$S$5:$S$1004,"진행중")>0,"진행중",IF(COUNTIFS(업무일지!$G$5:$G$1004,$A16,업무일지!$S$5:$S$1004,"보류")>0,"보류","완료"))))
B17: =IFERROR(INDEX(업무일지!$F$5:$F$1004,MATCH($A17,업무일지!$G$5:$G$1004,0)),"") | C17: =IFERROR(INDEX(업무일지!$H$5:$H$1004,MATCH($A17,업무일지!$G$5:$G$1004,0)),"") | D17: =IFERROR(INDEX(업무일지!$I$5:$I$1004,MATCH($A17,업무일지!$G$5:$G$1004,0)),"") | E17: =IF($A17="","",SUMPRODUCT((코드설정!$C$5:$C$24<>"")*((COUNTIFS(업무일지!$G$5:$G$1004,$A17,업무일지!$I$5:$I$1004,코드설정!$C$5:$C$24)+COUNTIFS(업무일지!$G$5:$G$1004,$A17,업무일지!$J$5:$J$1004,"*"&코드설정!$C$5:$C$24&"*"))>0))) | F17: =IF($A17="","",COUNTIFS(업무일지!$G$5:$G$1004,$A17,업무일지!$D$5:$D$1004,"출장")) | G17: =IF($A17="","",COUNTIFS(업무일지!$G$5:$G$1004,$A17,업무일지!$D$5:$D$1004,"분석")) | H17: =IF($A17="","",F17+G17) | I17: =IF($A17="","",SUMIFS(업무일지!$P$5:$P$1004,업무일지!$G$5:$G$1004,$A17,업무일지!$D$5:$D$1004,"출장")) | J17: =IF($A17="","",SUMIFS(업무일지!$R$5:$R$1004,업무일지!$G$5:$G$1004,$A17)) | K17: =IF($A17="","",SUMIFS(업무일지!$N$5:$N$1004,업무일지!$G$5:$G$1004,$A17)) | L17: =IF($A17="","",SUMIFS(업무일지!$O$5:$O$1004,업무일지!$G$5:$G$1004,$A17)) | M17: =IF($A17="","",SUMIFS(업무일지!$T$5:$T$1004,업무일지!$G$5:$G$1004,$A17)) | N17: =IF($A17="","",IFERROR(_xlfn.MINIFS(업무일지!$B$5:$B$1004,업무일지!$G$5:$G$1004,$A17),"")) | O17: =IF($A17="","",IFERROR(_xlfn.MAXIFS(업무일지!$C$5:$C$1004,업무일지!$G$5:$G$1004,$A17),"")) | P17: =IF($A17="","",IF(OR(N17="",O17="",O17=0),"",O17-N17+1)) | Q17: =IF($A17="","",IF(H17=0,"미기록",IF(COUNTIFS(업무일지!$G$5:$G$1004,$A17,업무일지!$S$5:$S$1004,"진행중")>0,"진행중",IF(COUNTIFS(업무일지!$G$5:$G$1004,$A17,업무일지!$S$5:$S$1004,"보류")>0,"보류","완료"))))
B18: =IFERROR(INDEX(업무일지!$F$5:$F$1004,MATCH($A18,업무일지!$G$5:$G$1004,0)),"") | C18: =IFERROR(INDEX(업무일지!$H$5:$H$1004,MATCH($A18,업무일지!$G$5:$G$1004,0)),"") | D18: =IFERROR(INDEX(업무일지!$I$5:$I$1004,MATCH($A18,업무일지!$G$5:$G$1004,0)),"") | E18: =IF($A18="","",SUMPRODUCT((코드설정!$C$5:$C$24<>"")*((COUNTIFS(업무일지!$G$5:$G$1004,$A18,업무일지!$I$5:$I$1004,코드설정!$C$5:$C$24)+COUNTIFS(업무일지!$G$5:$G$1004,$A18,업무일지!$J$5:$J$1004,"*"&코드설정!$C$5:$C$24&"*"))>0))) | F18: =IF($A18="","",COUNTIFS(업무일지!$G$5:$G$1004,$A18,업무일지!$D$5:$D$1004,"출장")) | G18: =IF($A18="","",COUNTIFS(업무일지!$G$5:$G$1004,$A18,업무일지!$D$5:$D$1004,"분석")) | H18: =IF($A18="","",F18+G18) | I18: =IF($A18="","",SUMIFS(업무일지!$P$5:$P$1004,업무일지!$G$5:$G$1004,$A18,업무일지!$D$5:$D$1004,"출장")) | J18: =IF($A18="","",SUMIFS(업무일지!$R$5:$R$1004,업무일지!$G$5:$G$1004,$A18)) | K18: =IF($A18="","",SUMIFS(업무일지!$N$5:$N$1004,업무일지!$G$5:$G$1004,$A18)) | L18: =IF($A18="","",SUMIFS(업무일지!$O$5:$O$1004,업무일지!$G$5:$G$1004,$A18)) | M18: =IF($A18="","",SUMIFS(업무일지!$T$5:$T$1004,업무일지!$G$5:$G$1004,$A18)) | N18: =IF($A18="","",IFERROR(_xlfn.MINIFS(업무일지!$B$5:$B$1004,업무일지!$G$5:$G$1004,$A18),"")) | O18: =IF($A18="","",IFERROR(_xlfn.MAXIFS(업무일지!$C$5:$C$1004,업무일지!$G$5:$G$1004,$A18),"")) | P18: =IF($A18="","",IF(OR(N18="",O18="",O18=0),"",O18-N18+1)) | Q18: =IF($A18="","",IF(H18=0,"미기록",IF(COUNTIFS(업무일지!$G$5:$G$1004,$A18,업무일지!$S$5:$S$1004,"진행중")>0,"진행중",IF(COUNTIFS(업무일지!$G$5:$G$1004,$A18,업무일지!$S$5:$S$1004,"보류")>0,"보류","완료"))))
B19: =IFERROR(INDEX(업무일지!$F$5:$F$1004,MATCH($A19,업무일지!$G$5:$G$1004,0)),"") | C19: =IFERROR(INDEX(업무일지!$H$5:$H$1004,MATCH($A19,업무일지!$G$5:$G$1004,0)),"") | D19: =IFERROR(INDEX(업무일지!$I$5:$I$1004,MATCH($A19,업무일지!$G$5:$G$1004,0)),"") | E19: =IF($A19="","",SUMPRODUCT((코드설정!$C$5:$C$24<>"")*((COUNTIFS(업무일지!$G$5:$G$1004,$A19,업무일지!$I$5:$I$1004,코드설정!$C$5:$C$24)+COUNTIFS(업무일지!$G$5:$G$1004,$A19,업무일지!$J$5:$J$1004,"*"&코드설정!$C$5:$C$24&"*"))>0))) | F19: =IF($A19="","",COUNTIFS(업무일지!$G$5:$G$1004,$A19,업무일지!$D$5:$D$1004,"출장")) | G19: =IF($A19="","",COUNTIFS(업무일지!$G$5:$G$1004,$A19,업무일지!$D$5:$D$1004,"분석")) | H19: =IF($A19="","",F19+G19) | I19: =IF($A19="","",SUMIFS(업무일지!$P$5:$P$1004,업무일지!$G$5:$G$1004,$A19,업무일지!$D$5:$D$1004,"출장")) | J19: =IF($A19="","",SUMIFS(업무일지!$R$5:$R$1004,업무일지!$G$5:$G$1004,$A19)) | K19: =IF($A19="","",SUMIFS(업무일지!$N$5:$N$1004,업무일지!$G$5:$G$1004,$A19)) | L19: =IF($A19="","",SUMIFS(업무일지!$O$5:$O$1004,업무일지!$G$5:$G$1004,$A19)) | M19: =IF($A19="","",SUMIFS(업무일지!$T$5:$T$1004,업무일지!$G$5:$G$1004,$A19)) | N19: =IF($A19="","",IFERROR(_xlfn.MINIFS(업무일지!$B$5:$B$1004,업무일지!$G$5:$G$1004,$A19),"")) | O19: =IF($A19="","",IFERROR(_xlfn.MAXIFS(업무일지!$C$5:$C$1004,업무일지!$G$5:$G$1004,$A19),"")) | P19: =IF($A19="","",IF(OR(N19="",O19="",O19=0),"",O19-N19+1)) | Q19: =IF($A19="","",IF(H19=0,"미기록",IF(COUNTIFS(업무일지!$G$5:$G$1004,$A19,업무일지!$S$5:$S$1004,"진행중")>0,"진행중",IF(COUNTIFS(업무일지!$G$5:$G$1004,$A19,업무일지!$S$5:$S$1004,"보류")>0,"보류","완료"))))
... B65: =IFERROR(INDEX(업무일지!$F$5:$F$1004,MATCH($A65,업무일지!$G$5:$G$1004,0)),"") | C65: =IFERROR(INDEX(업무일지!$H$5:$H$1004,MATCH($A65,업무일지!$G$5:$G$1004,0)),"") | D65: =IFERROR(INDEX(업무일지!$I$5:$I$1004,MATCH($A65,업무일지!$G$5:$G$1004,0)),"") | E65: =IF($A65="","",SUMPRODUCT((코드설정!$C$5:$C$24<>"")*((COUNTIFS(업무일지!$G$5:$G$1004,$A65,업무일지!$I$5:$I$1004,코드설정!$C$5:$C$24)+COUNTIFS(업무일지!$G$5:$G$1004,$A65,업무일지!$J$5:$J$1004,"*"&코드설정!$C$5:$C$24&"*"))>0))) | F65: =IF($A65="","",COUNTIFS(업무일지!$G$5:$G$1004,$A65,업무일지!$D$5:$D$1004,"출장")) | G65: =IF($A65="","",COUNTIFS(업무일지!$G$5:$G$1004,$A65,업무일지!$D$5:$D$1004,"분석")) | H65: =IF($A65="","",F65+G65) | I65: =IF($A65="","",SUMIFS(업무일지!$P$5:$P$1004,업무일지!$G$5:$G$1004,$A65,업무일지!$D$5:$D$1004,"출장")) | J65: =IF($A65="","",SUMIFS(업무일지!$R$5:$R$1004,업무일지!$G$5:$G$1004,$A65)) | K65: =IF($A65="","",SUMIFS(업무일지!$N$5:$N$1004,업무일지!$G$5:$G$1004,$A65)) | L65: =IF($A65="","",SUMIFS(업무일지!$O$5:$O$1004,업무일지!$G$5:$G$1004,$A65)) | M65: =IF($A65="","",SUMIFS(업무일지!$T$5:$T$1004,업무일지!$G$5:$G$1004,$A65)) | N65: =IF($A65="","",IFERROR(_xlfn.MINIFS(업무일지!$B$5:$B$1004,업무일지!$G$5:$G$1004,$A65),"")) | O65: =IF($A65="","",IFERROR(_xlfn.MAXIFS(업무일지!$C$5:$C$1004,업무일지!$G$5:$G$1004,$A65),"")) | P65: =IF($A65="","",IF(OR(N65="",O65="",O65=0),"",O65-N65+1)) | Q65: =IF($A65="","",IF(H65=0,"미기록",IF(COUNTIFS(업무일지!$G$5:$G$1004,$A65,업무일지!$S$5:$S$1004,"진행중")>0,"진행중",IF(COUNTIFS(업무일지!$G$5:$G$1004,$A65,업무일지!$S$5:$S$1004,"보류")>0,"보류","완료"))))
A66: 합계 | E66: =COUNTA(A6:A65)&" 건 사건" -> 2 건 사건 | F66: =SUM(F6:F65) -> 1 | G66: =SUM(G6:G65) -> 2 | H66: =SUM(H6:H65) -> 3 | I66: =SUM(I6:I65) -> 2 | J66: =SUM(J6:J65) -> 89 | K66: =SUM(K6:K65) -> 12 | L66: =SUM(L6:L65) -> 6080 | M66: =SUM(M6:M65) -> 552000
A69: 2. 사건 상세 조회 | C69: 사건번호 선택 → | D69: 2026-형제-1024 | F69: =IFERROR(INDEX(B6:B65,MATCH($D$69,A6:A65,0)),"") -> ○○ 기술유출 사건 압수수색
A70: 담당자 | B70: 주담당 건 | C70: 동행 건 | D70: 총 참여건 | E70: 본인 투입시간(H) | G70: 세부유형 | H70: 건수 | I70: 총 인시(H)
A71: =IF(코드설정!$C5="","",코드설정!$C5) -> 김디지 | B71: =IF($A71="","",COUNTIFS(업무일지!$G$5:$G$1004,$D$69,업무일지!$I$5:$I$1004,$A71)) -> 2 | C71: =IF($A71="","",COUNTIFS(업무일지!$G$5:$G$1004,$D$69,업무일지!$J$5:$J$1004,"*"&$A71&"*")) -> 0 | D71: =IF($A71="","",B71+C71) -> 2 | E71: =IF($A71="","",SUMIFS(업무일지!$Q$5:$Q$1004,업무일지!$G$5:$G$1004,$D$69,업무일지!$I$5:$I$1004,$A71)+SUMIFS(업무일지!$Q$5:$Q$1004,업무일지!$G$5:$G$1004,$D$69,업무일지!$J$5:$J$1004,"*"&$A71&"*")) -> 50 | G71: 압수·수색 집행 | H71: =COUNTIFS(업무일지!$G$5:$G$1004,$D$69,업무일지!$E$5:$E$1004,$G71) -> 1 | I71: =SUMIFS(업무일지!$R$5:$R$1004,업무일지!$G$5:$G$1004,$D$69,업무일지!$E$5:$E$1004,$G71) -> 48
A72: =IF(코드설정!$C6="","",코드설정!$C6) -> 이수사 | B72: =IF($A72="","",COUNTIFS(업무일지!$G$5:$G$1004,$D$69,업무일지!$I$5:$I$1004,$A72)) -> 0 | C72: =IF($A72="","",COUNTIFS(업무일지!$G$5:$G$1004,$D$69,업무일지!$J$5:$J$1004,"*"&$A72&"*")) -> 1 | D72: =IF($A72="","",B72+C72) -> 1 | E72: =IF($A72="","",SUMIFS(업무일지!$Q$5:$Q$1004,업무일지!$G$5:$G$1004,$D$69,업무일지!$I$5:$I$1004,$A72)+SUMIFS(업무일지!$Q$5:$Q$1004,업무일지!$G$5:$G$1004,$D$69,업무일지!$J$5:$J$1004,"*"&$A72&"*")) -> 16 | G72: 현장 증거수집 | H72: =COUNTIFS(업무일지!$G$5:$G$1004,$D$69,업무일지!$E$5:$E$1004,$G72) -> 0 | I72: =SUMIFS(업무일지!$R$5:$R$1004,업무일지!$G$5:$G$1004,$D$69,업무일지!$E$5:$E$1004,$G72) -> 0
A73: =IF(코드설정!$C7="","",코드설정!$C7) -> 박증거 | B73: =IF($A73="","",COUNTIFS(업무일지!$G$5:$G$1004,$D$69,업무일지!$I$5:$I$1004,$A73)) -> 0 | C73: =IF($A73="","",COUNTIFS(업무일지!$G$5:$G$1004,$D$69,업무일지!$J$5:$J$1004,"*"&$A73&"*")) -> 1 | D73: =IF($A73="","",B73+C73) -> 1 | E73: =IF($A73="","",SUMIFS(업무일지!$Q$5:$Q$1004,업무일지!$G$5:$G$1004,$D$69,업무일지!$I$5:$I$1004,$A73)+SUMIFS(업무일지!$Q$5:$Q$1004,업무일지!$G$5:$G$1004,$D$69,업무일지!$J$5:$J$1004,"*"&$A73&"*")) -> 16 | G73: 현장 지원·입회 | H73: =COUNTIFS(업무일지!$G$5:$G$1004,$D$69,업무일지!$E$5:$E$1004,$G73) -> 0 | I73: =SUMIFS(업무일지!$R$5:$R$1004,업무일지!$G$5:$G$1004,$D$69,업무일지!$E$5:$E$1004,$G73) -> 0
A74: =IF(코드설정!$C8="","",코드설정!$C8) -> 최분석 | B74: =IF($A74="","",COUNTIFS(업무일지!$G$5:$G$1004,$D$69,업무일지!$I$5:$I$1004,$A74)) -> 0 | C74: =IF($A74="","",COUNTIFS(업무일지!$G$5:$G$1004,$D$69,업무일지!$J$5:$J$1004,"*"&$A74&"*")) -> 0 | D74: =IF($A74="","",B74+C74) -> 0 | E74: =IF($A74="","",SUMIFS(업무일지!$Q$5:$Q$1004,업무일지!$G$5:$G$1004,$D$69,업무일지!$I$5:$I$1004,$A74)+SUMIFS(업무일지!$Q$5:$Q$1004,업무일지!$G$5:$G$1004,$D$69,업무일지!$J$5:$J$1004,"*"&$A74&"*")) -> 0 | G74: 회의·협의 | H74: =COUNTIFS(업무일지!$G$5:$G$1004,$D$69,업무일지!$E$5:$E$1004,$G74) -> 0 | I74: =SUMIFS(업무일지!$R$5:$R$1004,업무일지!$G$5:$G$1004,$D$69,업무일지!$E$5:$E$1004,$G74) -> 0
A75: =IF(코드설정!$C9="","",코드설정!$C9) -> 정현장 | B75: =IF($A75="","",COUNTIFS(업무일지!$G$5:$G$1004,$D$69,업무일지!$I$5:$I$1004,$A75)) -> 0 | C75: =IF($A75="","",COUNTIFS(업무일지!$G$5:$G$1004,$D$69,업무일지!$J$5:$J$1004,"*"&$A75&"*")) -> 0 | D75: =IF($A75="","",B75+C75) -> 0 | E75: =IF($A75="","",SUMIFS(업무일지!$Q$5:$Q$1004,업무일지!$G$5:$G$1004,$D$69,업무일지!$I$5:$I$1004,$A75)+SUMIFS(업무일지!$Q$5:$Q$1004,업무일지!$G$5:$G$1004,$D$69,업무일지!$J$5:$J$1004,"*"&$A75&"*")) -> 0 | G75: 교육·세미나 | H75: =COUNTIFS(업무일지!$G$5:$G$1004,$D$69,업무일지!$E$5:$E$1004,$G75) -> 0 | I75: =SUMIFS(업무일지!$R$5:$R$1004,업무일지!$G$5:$G$1004,$D$69,업무일지!$E$5:$E$1004,$G75) -> 0
A76: =IF(코드설정!$C10="","",코드설정!$C10) | B76: =IF($A76="","",COUNTIFS(업무일지!$G$5:$G$1004,$D$69,업무일지!$I$5:$I$1004,$A76)) | C76: =IF($A76="","",COUNTIFS(업무일지!$G$5:$G$1004,$D$69,업무일지!$J$5:$J$1004,"*"&$A76&"*")) | D76: =IF($A76="","",B76+C76) | E76: =IF($A76="","",SUMIFS(업무일지!$Q$5:$Q$1004,업무일지!$G$5:$G$1004,$D$69,업무일지!$I$5:$I$1004,$A76)+SUMIFS(업무일지!$Q$5:$Q$1004,업무일지!$G$5:$G$1004,$D$69,업무일지!$J$5:$J$1004,"*"&$A76&"*")) | G76: 기타 출장 | H76: =COUNTIFS(업무일지!$G$5:$G$1004,$D$69,업무일지!$E$5:$E$1004,$G76) -> 0 | I76: =SUMIFS(업무일지!$R$5:$R$1004,업무일지!$G$5:$G$1004,$D$69,업무일지!$E$5:$E$1004,$G76) -> 0
