Workbook
Name 목록_직무구분: 코드설정!$H$5:$H$7
Name 목록_세부유형: 코드설정!$B$5:$B$21
Name 목록_담당자: 코드설정!$C$5:$C$24
Name 목록_요청처: 코드설정!$E$5:$E$14
Name 목록_진행상태: 코드설정!$F$5:$F$7
Name 목록_일일구분: 코드설정!$G$5:$G$14
Name 목록_팀: 코드설정!$I$5:$I$14
Name 목록_사건번호: 사건마스터!$A$5:$A$64
Name 목록_장비구분: 코드설정!$M$5:$M$14
Name 목록_장비상태: 코드설정!$O$5:$O$8
Name 목록_관리번호: '장비·매체 관리'!$A$6:$A$105
Name 목록_사업구분: 코드설정!$Q$5:$Q$14
Name 목록_추진단계: 코드설정!$S$5:$S$10
Name 목록_사업번호: 사업마스터!$A$5:$A$34

Sheet 대시보드
A1: 대시보드 · 부서 업무 현황
A2: ※ 노란 칸(연도·월)만 바꾸면 아래 전부 다시 계산됩니다. ※ 파일을 열 때마다 오늘 날짜 기준으로 갱신됩니다. ※ 회차 = 업무일지 줄 수 / 사건 = 고유 사건 수.
A4: 조회 연도 | B4: 2026 | C4: 조회 월 | D4: 3 | E4: =TEXT(DATE($B$4,$D$4,1),"yyyy-mm-dd")&" ~ "&TEXT(DATE($B$4,$D$4+1,1)-1,"yyyy-mm-dd") | H4: 오늘 | I4: =TODAY()
A6: 1. 이번 달 한눈에
A7: 구분 | B7: 출장 회차 | C7: 분석 회차 | D7: 교육 회차 | E7: 전체 회차 | F7: 진행중 | G7: 일일실시 | H7: 대상매체(건)
A8: 이번 달 | B8: =COUNTIFS(업무일지!$B$5:$B$1004,">="&DATE($B$4,$D$4,1),업무일지!$B$5:$B$1004,"<"&DATE($B$4,$D$4+1,1),업무일지!$D$5:$D$1004,"출장") | C8: =COUNTIFS(업무일지!$B$5:$B$1004,">="&DATE($B$4,$D$4,1),업무일지!$B$5:$B$1004,"<"&DATE($B$4,$D$4+1,1),업무일지!$D$5:$D$1004,"분석") | D8: =COUNTIFS(업무일지!$B$5:$B$1004,">="&DATE($B$4,$D$4,1),업무일지!$B$5:$B$1004,"<"&DATE($B$4,$D$4+1,1),업무일지!$D$5:$D$1004,"교육") | E8: =B8+C8+D8 | F8: =COUNTIF(업무일지!$AG$5:$AG$1004,"진행중") | G8: =COUNTIFS(일일실시사항!$B$5:$B$1004,">="&DATE($B$4,$D$4,1),일일실시사항!$B$5:$B$1004,"<"&DATE($B$4,$D$4+1,1)) | H8: =SUMIFS(업무일지!$AD$5:$AD$1004,업무일지!$B$5:$B$1004,">="&DATE($B$4,$D$4,1),업무일지!$B$5:$B$1004,"<"&DATE($B$4,$D$4+1,1))
A9: 전월 대비 | B9: =IF(B10=0,"",IF(B8>=B10,"▲ ","▼ ")&TEXT(ABS(B8-B10),"#,##0")&" (전월 "&B10&")") | C9: =IF(C10=0,"",IF(C8>=C10,"▲ ","▼ ")&TEXT(ABS(C8-C10),"#,##0")&" (전월 "&C10&")") | D9: =IF(D10=0,"",IF(D8>=D10,"▲ ","▼ ")&TEXT(ABS(D8-D10),"#,##0")&" (전월 "&D10&")") | E9: =IF(E10=0,"",IF(E8>=E10,"▲ ","▼ ")&TEXT(ABS(E8-E10),"#,##0")&" (전월 "&E10&")") | G9: =IF(G10=0,"",IF(G8>=G10,"▲ ","▼ ")&TEXT(ABS(G8-G10),"#,##0")&" (전월 "&G10&")") | H9: =IF(H10=0,"",IF(H8>=H10,"▲ ","▼ ")&TEXT(ABS(H8-H10),"#,##0")&" (전월 "&H10&")")
B10: =COUNTIFS(업무일지!$B$5:$B$1004,">="&DATE($B$4,$D$4-1,1),업무일지!$B$5:$B$1004,"<"&DATE($B$4,$D$4,1),업무일지!$D$5:$D$1004,"출장") | C10: =COUNTIFS(업무일지!$B$5:$B$1004,">="&DATE($B$4,$D$4-1,1),업무일지!$B$5:$B$1004,"<"&DATE($B$4,$D$4,1),업무일지!$D$5:$D$1004,"분석") | D10: =COUNTIFS(업무일지!$B$5:$B$1004,">="&DATE($B$4,$D$4-1,1),업무일지!$B$5:$B$1004,"<"&DATE($B$4,$D$4,1),업무일지!$D$5:$D$1004,"교육") | E10: =B10+C10+D10 | G10: =COUNTIFS(일일실시사항!$B$5:$B$1004,">="&DATE($B$4,$D$4-1,1),일일실시사항!$B$5:$B$1004,"<"&DATE($B$4,$D$4,1)) | H10: =SUMIFS(업무일지!$AD$5:$AD$1004,업무일지!$B$5:$B$1004,">="&DATE($B$4,$D$4-1,1),업무일지!$B$5:$B$1004,"<"&DATE($B$4,$D$4,1))
A12: 2. 확인이 필요한 것 | H12: 3. 사건 기준 집계
A13: 항목 | B13: 건수 | C13: 상태 | D13: 확인할 곳 | H13: 구분 | I13: 회차 | J13: 사건 수 | K13: 비고
A14: 입력검증 오류 | B14: ='입력검증'!$C$9 | C14: =IF($B14=0,"이상 없음","확인 필요") | D14: [입력검증] | H14: 출장 | I14: =INDEX('부서 전체현황'!$B$7:$B$18,$D$4) | J14: =INDEX('부서 전체현황'!$C$7:$C$18,$D$4)
A15: 장비 반납 연체 | B15: =COUNTIF('장비·매체 관리'!$J$109:$J$508,"연체") | C15: =IF($B15=0,"이상 없음","확인 필요") | D15: [장비·매체 관리] | H15: 분석 | I15: =INDEX('부서 전체현황'!$D$7:$D$18,$D$4) | J15: =INDEX('부서 전체현황'!$E$7:$E$18,$D$4)
A16: 30일 초과 진행중 | B16: ='진행중 보드'!$C$10 | C16: =IF($B16=0,"이상 없음","확인 필요") | D16: [진행중 보드] | H16: 교육 | I16: =INDEX('부서 전체현황'!$F$7:$F$18,$D$4) | J16: "-" | K16: 사건과 묶이지 않음
A17: 사업 완료예정일 경과 | B17: =SUMPRODUCT((사업마스터!$L$5:$L$34>0)*(사업마스터!$L$5:$L$34<TODAY())*(사업마스터!$P$5:$P$34<>"완료")) | C17: =IF($B17=0,"이상 없음","확인 필요") | D17: [사업마스터] | H17: 전체 | I17: =INDEX('부서 전체현황'!$G$7:$G$18,$D$4) | J17: =INDEX('부서 전체현황'!$H$7:$H$18,$D$4) | K17: =INDEX('부서 전체현황'!$I$7:$I$18,$D$4)&" 건 신규 착수"
A19: 4. 진행중 · 오래된 순 TOP 5 ※ 전체는 [진행중 보드]
A20: 경과일 | B20: 사건번호 | C20: 회차 | D20: 사건명 | E20: 직무 | F20: 세부유형 | G20: 주담당 | H20: 인원 | I20: 시작일 | J20: 장소 | K20: 진행상태 | L20: 대상매체 | M20: 데이터량
A21: =IF('진행중 보드'!$A13="","",'진행중 보드'!$B13) | B21: =IF('진행중 보드'!$A13="","",'진행중 보드'!$G13) | C21: =IF('진행중 보드'!$A13="","","-") | D21: =IF('진행중 보드'!$A13="","",'진행중 보드'!$H13) | E21: =IF('진행중 보드'!$A13="","",'진행중 보드'!$E13) | F21: =IF('진행중 보드'!$A13="","",'진행중 보드'!$F13) | G21: =IF('진행중 보드'!$A13="","",'진행중 보드'!$I13) | H21: =IF('진행중 보드'!$A13="","",'진행중 보드'!$J13) | I21: =IF('진행중 보드'!$A13="","",'진행중 보드'!$C13) | J21: =IF('진행중 보드'!$A13="","",'진행중 보드'!$K13) | K21: =IF('진행중 보드'!$A13="","","진행중") | L21: =IF('진행중 보드'!$A13="","","-") | M21: =IF('진행중 보드'!$A13="","","-")
A22: =IF('진행중 보드'!$A14="","",'진행중 보드'!$B14) | B22: =IF('진행중 보드'!$A14="","",'진행중 보드'!$G14) | C22: =IF('진행중 보드'!$A14="","","-") | D22: =IF('진행중 보드'!$A14="","",'진행중 보드'!$H14) | E22: =IF('진행중 보드'!$A14="","",'진행중 보드'!$E14) | F22: =IF('진행중 보드'!$A14="","",'진행중 보드'!$F14) | G22: =IF('진행중 보드'!$A14="","",'진행중 보드'!$I14) | H22: =IF('진행중 보드'!$A14="","",'진행중 보드'!$J14) | I22: =IF('진행중 보드'!$A14="","",'진행중 보드'!$C14) | J22: =IF('진행중 보드'!$A14="","",'진행중 보드'!$K14) | K22: =IF('진행중 보드'!$A14="","","진행중") | L22: =IF('진행중 보드'!$A14="","","-") | M22: =IF('진행중 보드'!$A14="","","-")
A23: =IF('진행중 보드'!$A15="","",'진행중 보드'!$B15) | B23: =IF('진행중 보드'!$A15="","",'진행중 보드'!$G15) | C23: =IF('진행중 보드'!$A15="","","-") | D23: =IF('진행중 보드'!$A15="","",'진행중 보드'!$H15) | E23: =IF('진행중 보드'!$A15="","",'진행중 보드'!$E15) | F23: =IF('진행중 보드'!$A15="","",'진행중 보드'!$F15) | G23: =IF('진행중 보드'!$A15="","",'진행중 보드'!$I15) | H23: =IF('진행중 보드'!$A15="","",'진행중 보드'!$J15) | I23: =IF('진행중 보드'!$A15="","",'진행중 보드'!$C15) | J23: =IF('진행중 보드'!$A15="","",'진행중 보드'!$K15) | K23: =IF('진행중 보드'!$A15="","","진행중") | L23: =IF('진행중 보드'!$A15="","","-") | M23: =IF('진행중 보드'!$A15="","","-")
A24: =IF('진행중 보드'!$A16="","",'진행중 보드'!$B16) | B24: =IF('진행중 보드'!$A16="","",'진행중 보드'!$G16) | C24: =IF('진행중 보드'!$A16="","","-") | D24: =IF('진행중 보드'!$A16="","",'진행중 보드'!$H16) | E24: =IF('진행중 보드'!$A16="","",'진행중 보드'!$E16) | F24: =IF('진행중 보드'!$A16="","",'진행중 보드'!$F16) | G24: =IF('진행중 보드'!$A16="","",'진행중 보드'!$I16) | H24: =IF('진행중 보드'!$A16="","",'진행중 보드'!$J16) | I24: =IF('진행중 보드'!$A16="","",'진행중 보드'!$C16) | J24: =IF('진행중 보드'!$A16="","",'진행중 보드'!$K16) | K24: =IF('진행중 보드'!$A16="","","진행중") | L24: =IF('진행중 보드'!$A16="","","-") | M24: =IF('진행중 보드'!$A16="","","-")
A25: =IF('진행중 보드'!$A17="","",'진행중 보드'!$B17) | B25: =IF('진행중 보드'!$A17="","",'진행중 보드'!$G17) | C25: =IF('진행중 보드'!$A17="","","-") | D25: =IF('진행중 보드'!$A17="","",'진행중 보드'!$H17) | E25: =IF('진행중 보드'!$A17="","",'진행중 보드'!$E17) | F25: =IF('진행중 보드'!$A17="","",'진행중 보드'!$F17) | G25: =IF('진행중 보드'!$A17="","",'진행중 보드'!$I17) | H25: =IF('진행중 보드'!$A17="","",'진행중 보드'!$J17) | I25: =IF('진행중 보드'!$A17="","",'진행중 보드'!$C17) | J25: =IF('진행중 보드'!$A17="","",'진행중 보드'!$K17) | K25: =IF('진행중 보드'!$A17="","","진행중") | L25: =IF('진행중 보드'!$A17="","","-") | M25: =IF('진행중 보드'!$A17="","","-")
A27: 5. 팀별 실적 (연간 누계)
A28: 소속팀 | B28: 출장 회차 | C28: 분석 회차 | D28: 교육 회차 | E28: 전체 회차 | F28: 구성비 | G28: 출장 사건 | H28: 분석 사건 | I28: 전체 사건 | J28: 소요일수 | K28: 연인원 | L28: 대상매체 | M28: 진행중
A29: =IF('부서 전체현황'!$A44="","",'부서 전체현황'!$A44) | B29: =IF('부서 전체현황'!$A44="","",'부서 전체현황'!$B44) | C29: =IF('부서 전체현황'!$A44="","",'부서 전체현황'!$C44) | D29: =IF('부서 전체현황'!$A44="","",'부서 전체현황'!$D44) | E29: =IF('부서 전체현황'!$A44="","",'부서 전체현황'!$E44) | F29: =IF(OR($E29="",'부서 전체현황'!$E$54=0),"",REPT("|",ROUND($E29/'부서 전체현황'!$E$54*20,0))&" "&TEXT($E29/'부서 전체현황'!$E$54,"0%")) | G29: =IF('부서 전체현황'!$A44="","",'부서 전체현황'!$J44) | H29: =IF('부서 전체현황'!$A44="","",'부서 전체현황'!$K44) | I29: =IF('부서 전체현황'!$A44="","",'부서 전체현황'!$L44) | J29: =IF('부서 전체현황'!$A44="","",'부서 전체현황'!$F44) | K29: =IF('부서 전체현황'!$A44="","",'부서 전체현황'!$G44) | L29: =IF('부서 전체현황'!$A44="","",'부서 전체현황'!$H44) | M29: =IF('부서 전체현황'!$A44="","",'부서 전체현황'!$I44)
A30: =IF('부서 전체현황'!$A45="","",'부서 전체현황'!$A45) | B30: =IF('부서 전체현황'!$A45="","",'부서 전체현황'!$B45) | C30: =IF('부서 전체현황'!$A45="","",'부서 전체현황'!$C45) | D30: =IF('부서 전체현황'!$A45="","",'부서 전체현황'!$D45) | E30: =IF('부서 전체현황'!$A45="","",'부서 전체현황'!$E45) | F30: =IF(OR($E30="",'부서 전체현황'!$E$54=0),"",REPT("|",ROUND($E30/'부서 전체현황'!$E$54*20,0))&" "&TEXT($E30/'부서 전체현황'!$E$54,"0%")) | G30: =IF('부서 전체현황'!$A45="","",'부서 전체현황'!$J45) | H30: =IF('부서 전체현황'!$A45="","",'부서 전체현황'!$K45) | I30: =IF('부서 전체현황'!$A45="","",'부서 전체현황'!$L45) | J30: =IF('부서 전체현황'!$A45="","",'부서 전체현황'!$F45) | K30: =IF('부서 전체현황'!$A45="","",'부서 전체현황'!$G45) | L30: =IF('부서 전체현황'!$A45="","",'부서 전체현황'!$H45) | M30: =IF('부서 전체현황'!$A45="","",'부서 전체현황'!$I45)
A31: =IF('부서 전체현황'!$A46="","",'부서 전체현황'!$A46) | B31: =IF('부서 전체현황'!$A46="","",'부서 전체현황'!$B46) | C31: =IF('부서 전체현황'!$A46="","",'부서 전체현황'!$C46) | D31: =IF('부서 전체현황'!$A46="","",'부서 전체현황'!$D46) | E31: =IF('부서 전체현황'!$A46="","",'부서 전체현황'!$E46) | F31: =IF(OR($E31="",'부서 전체현황'!$E$54=0),"",REPT("|",ROUND($E31/'부서 전체현황'!$E$54*20,0))&" "&TEXT($E31/'부서 전체현황'!$E$54,"0%")) | G31: =IF('부서 전체현황'!$A46="","",'부서 전체현황'!$J46) | H31: =IF('부서 전체현황'!$A46="","",'부서 전체현황'!$K46) | I31: =IF('부서 전체현황'!$A46="","",'부서 전체현황'!$L46) | J31: =IF('부서 전체현황'!$A46="","",'부서 전체현황'!$F46) | K31: =IF('부서 전체현황'!$A46="","",'부서 전체현황'!$G46) | L31: =IF('부서 전체현황'!$A46="","",'부서 전체현황'!$H46) | M31: =IF('부서 전체현황'!$A46="","",'부서 전체현황'!$I46)
A32: 합계 | B32: ='부서 전체현황'!$B$54 | C32: ='부서 전체현황'!$C$54 | D32: ='부서 전체현황'!$D$54 | E32: ='부서 전체현황'!$E$54 | F32: 100% | G32: ='부서 전체현황'!$J$54 | H32: ='부서 전체현황'!$K$54 | I32: ='부서 전체현황'!$L$54 | J32: ='부서 전체현황'!$F$54 | K32: ='부서 전체현황'!$G$54 | L32: ='부서 전체현황'!$H$54 | M32: ='부서 전체현황'!$I$54
A34: 6. 사업 현황
A35: 사업번호 | B35: 사업명 | C35: 구분 | D35: 주관팀 | E35: 현재 단계 | F35: 진척률 | G35: 예산액(원) | H35: 집행액(원) | I35: 집행률 | J35: 추진 건수 | K35: 완료예정일 | L35: 진행상태 | M35: 비고
A36: =IF(사업마스터!$A5="","",사업마스터!$A5) | B36: =IF(사업마스터!$A5="","",사업마스터!$B5) | C36: =IF(사업마스터!$A5="","",사업마스터!$D5) | D36: =IF(사업마스터!$A5="","",사업마스터!$E5) | E36: =IF(사업마스터!$A5="","",사업마스터!$M5) | F36: =IF(사업마스터!$A5="","",사업마스터!$N5) | G36: =IF(사업마스터!$A5="","",사업마스터!$G5) | H36: =IF(사업마스터!$A5="","",사업마스터!$H5) | I36: =IF(사업마스터!$A5="","",사업마스터!$I5) | J36: =IF(사업마스터!$A5="","",사업마스터!$O5) | K36: =IF(사업마스터!$A5="","",사업마스터!$L5) | L36: =IF(사업마스터!$A5="","",사업마스터!$P5) | M36: =IF(사업마스터!$A5="","",사업마스터!$Q5)
A37: =IF(사업마스터!$A6="","",사업마스터!$A6) | B37: =IF(사업마스터!$A6="","",사업마스터!$B6) | C37: =IF(사업마스터!$A6="","",사업마스터!$D6) | D37: =IF(사업마스터!$A6="","",사업마스터!$E6) | E37: =IF(사업마스터!$A6="","",사업마스터!$M6) | F37: =IF(사업마스터!$A6="","",사업마스터!$N6) | G37: =IF(사업마스터!$A6="","",사업마스터!$G6) | H37: =IF(사업마스터!$A6="","",사업마스터!$H6) | I37: =IF(사업마스터!$A6="","",사업마스터!$I6) | J37: =IF(사업마스터!$A6="","",사업마스터!$O6) | K37: =IF(사업마스터!$A6="","",사업마스터!$L6) | L37: =IF(사업마스터!$A6="","",사업마스터!$P6) | M37: =IF(사업마스터!$A6="","",사업마스터!$Q6)
A38: =IF(사업마스터!$A7="","",사업마스터!$A7) | B38: =IF(사업마스터!$A7="","",사업마스터!$B7) | C38: =IF(사업마스터!$A7="","",사업마스터!$D7) | D38: =IF(사업마스터!$A7="","",사업마스터!$E7) | E38: =IF(사업마스터!$A7="","",사업마스터!$M7) | F38: =IF(사업마스터!$A7="","",사업마스터!$N7) | G38: =IF(사업마스터!$A7="","",사업마스터!$G7) | H38: =IF(사업마스터!$A7="","",사업마스터!$H7) | I38: =IF(사업마스터!$A7="","",사업마스터!$I7) | J38: =IF(사업마스터!$A7="","",사업마스터!$O7) | K38: =IF(사업마스터!$A7="","",사업마스터!$L7) | L38: =IF(사업마스터!$A7="","",사업마스터!$P7) | M38: =IF(사업마스터!$A7="","",사업마스터!$Q7)
A39: =IF(사업마스터!$A8="","",사업마스터!$A8) | B39: =IF(사업마스터!$A8="","",사업마스터!$B8) | C39: =IF(사업마스터!$A8="","",사업마스터!$D8) | D39: =IF(사업마스터!$A8="","",사업마스터!$E8) | E39: =IF(사업마스터!$A8="","",사업마스터!$M8) | F39: =IF(사업마스터!$A8="","",사업마스터!$N8) | G39: =IF(사업마스터!$A8="","",사업마스터!$G8) | H39: =IF(사업마스터!$A8="","",사업마스터!$H8) | I39: =IF(사업마스터!$A8="","",사업마스터!$I8) | J39: =IF(사업마스터!$A8="","",사업마스터!$O8) | K39: =IF(사업마스터!$A8="","",사업마스터!$L8) | L39: =IF(사업마스터!$A8="","",사업마스터!$P8) | M39: =IF(사업마스터!$A8="","",사업마스터!$Q8)
A40: =IF(사업마스터!$A9="","",사업마스터!$A9) | B40: =IF(사업마스터!$A9="","",사업마스터!$B9) | C40: =IF(사업마스터!$A9="","",사업마스터!$D9) | D40: =IF(사업마스터!$A9="","",사업마스터!$E9) | E40: =IF(사업마스터!$A9="","",사업마스터!$M9) | F40: =IF(사업마스터!$A9="","",사업마스터!$N9) | G40: =IF(사업마스터!$A9="","",사업마스터!$G9) | H40: =IF(사업마스터!$A9="","",사업마스터!$H9) | I40: =IF(사업마스터!$A9="","",사업마스터!$I9) | J40: =IF(사업마스터!$A9="","",사업마스터!$O9) | K40: =IF(사업마스터!$A9="","",사업마스터!$L9) | L40: =IF(사업마스터!$A9="","",사업마스터!$P9) | M40: =IF(사업마스터!$A9="","",사업마스터!$Q9)
A41: =IF(사업마스터!$A10="","",사업마스터!$A10) | B41: =IF(사업마스터!$A10="","",사업마스터!$B10) | C41: =IF(사업마스터!$A10="","",사업마스터!$D10) | D41: =IF(사업마스터!$A10="","",사업마스터!$E10) | E41: =IF(사업마스터!$A10="","",사업마스터!$M10) | F41: =IF(사업마스터!$A10="","",사업마스터!$N10) | G41: =IF(사업마스터!$A10="","",사업마스터!$G10) | H41: =IF(사업마스터!$A10="","",사업마스터!$H10) | I41: =IF(사업마스터!$A10="","",사업마스터!$I10) | J41: =IF(사업마스터!$A10="","",사업마스터!$O10) | K41: =IF(사업마스터!$A10="","",사업마스터!$L10) | L41: =IF(사업마스터!$A10="","",사업마스터!$P10) | M41: =IF(사업마스터!$A10="","",사업마스터!$Q10)
A42: =IF(사업마스터!$A11="","",사업마스터!$A11) | B42: =IF(사업마스터!$A11="","",사업마스터!$B11) | C42: =IF(사업마스터!$A11="","",사업마스터!$D11) | D42: =IF(사업마스터!$A11="","",사업마스터!$E11) | E42: =IF(사업마스터!$A11="","",사업마스터!$M11) | F42: =IF(사업마스터!$A11="","",사업마스터!$N11) | G42: =IF(사업마스터!$A11="","",사업마스터!$G11) | H42: =IF(사업마스터!$A11="","",사업마스터!$H11) | I42: =IF(사업마스터!$A11="","",사업마스터!$I11) | J42: =IF(사업마스터!$A11="","",사업마스터!$O11) | K42: =IF(사업마스터!$A11="","",사업마스터!$L11) | L42: =IF(사업마스터!$A11="","",사업마스터!$P11) | M42: =IF(사업마스터!$A11="","",사업마스터!$Q11)
A43: =IF(사업마스터!$A12="","",사업마스터!$A12) | B43: =IF(사업마스터!$A12="","",사업마스터!$B12) | C43: =IF(사업마스터!$A12="","",사업마스터!$D12) | D43: =IF(사업마스터!$A12="","",사업마스터!$E12) | E43: =IF(사업마스터!$A12="","",사업마스터!$M12) | F43: =IF(사업마스터!$A12="","",사업마스터!$N12) | G43: =IF(사업마스터!$A12="","",사업마스터!$G12) | H43: =IF(사업마스터!$A12="","",사업마스터!$H12) | I43: =IF(사업마스터!$A12="","",사업마스터!$I12) | J43: =IF(사업마스터!$A12="","",사업마스터!$O12) | K43: =IF(사업마스터!$A12="","",사업마스터!$L12) | L43: =IF(사업마스터!$A12="","",사업마스터!$P12) | M43: =IF(사업마스터!$A12="","",사업마스터!$Q12)
A44: 합계 | B44: =IF(COUNTBLANK(사업마스터!$A$5:$A$34)=30,"등록된 사업 없음",(30)-COUNTBLANK(사업마스터!$A$5:$A$34)&" 개 사업") | G44: =SUM(사업마스터!$G$5:$G$34) | H44: =SUM(사업마스터!$H$5:$H$34) | I44: =IF($G$44=0,"",$H$44/$G$44) | J44: =SUM(사업마스터!$O$5:$O$34)
A46: ※ 상위 8개 사업만 표시합니다. 전체는 [사업마스터], 사업별 경과는 [사업별 현황]을 보세요. ※ 집행률 합계는 예산이 배정된 사업만 기준으로 계산됩니다.
A47: ※ 팀별 실적은 연간 누계입니다(이번 달이 아님). 월별 추이는 [부서 전체현황]을 보세요.

Sheet 사용안내
B2: 부서 업무일지 v4 · 사건 / 사업 / 교육 통합 관리
B4: 시트 구성 — 한눈에 보기
B5: 대시보드 | C5: 연도·월만 고르면 이번 달 현황·경고·사건·팀별·사업이 한 장에 모입니다. 입력할 것 없음.
B6: 월력표 | C6: 연·월을 고르면 달력이 그려집니다. 날짜 칸의 파란 줄은 자동 집계, 흰 칸은 자유 메모.
B8: 입력하는 시트
B9: 사건마스터 | C9: 사건을 한 번 등록하고 담당자 배정표에서 참여자를 모두 고릅니다 → 업무일지로 전달.
B10: 업무일지 | C10: 출장·분석·교육 1건 = 1행. 사건번호를 고르면 사건명·요청처·담당자가 통째로 자동.
B11: 일일실시사항 | C11: 출장·분석·교육 외 부서의 일일 업무(행정·회의·장비관리·당직 등).
B12: 사업마스터 | C12: 사업을 한 번 등록합니다. 예산 없는 사업은 예산액을 비워 두세요.
B13: 사업추진일지 | C13: 사업이 언제 무슨 일을 했는지 날짜별로 기록합니다. 추진 단계는 선택 입력.
B14: 장비·매체 관리 | C14: 장비 대장 + 불출·반납 이력. 반납일을 비우면 '사용중', 예정일이 지나면 '연체'.
B16: 보는 시트 — 입력할 것 없음
B17: 진행중 보드 | C17: 진행상태가 '진행중'인 건을 오래된 순으로. 30일 초과 주황, 60일 초과 빨강.
B18: 사건 이력 조회 | C18: 사건번호 하나를 고르면 그 사건의 모든 업무를 날짜순 타임라인으로.
B19: 사업별 현황 | C19: 사업번호 하나를 고르면 예산 집행 · 단계별 진척 · 추진 타임라인이 정리됩니다.
B20: 부서 전체현황 | C20: 기준연도 1칸으로 월별 추이·세부유형·팀별·요청처별·일일 집계가 전부 갱신.
B21: 사건별 현황 | C21: 사건번호 기준 누계(전체 기간). 아래쪽에서 사건 하나를 골라 상세 조회.
B22: 개인별 현황 | C22: 담당자별 주담당/참여 분리 집계, 참여 사건수, 월별 참여회차 매트릭스.
B23: 교육 이수 현황 | C23: 담당자별 연간 교육 횟수와 이수 판정. 이수 기준 횟수는 노란 칸에서 조정.
B24: 입력검증 | C24: 누락·오타·불일치를 자동으로 모아 줍니다. 월말 마감 전 확인용.
B25: 코드설정 | C25: 모든 드롭다운의 원본. 담당자·팀·유형·사업구분·추진단계·장비·공휴일.
B27: 입력 순서
B28: ① 코드설정 | C28: 담당자·소속팀·팀 마스터·요청처를 우리 부서에 맞게 고칩니다.
B29: ② 사건마스터 / 사업마스터 | C29: 사건과 사업을 등록합니다. 사건은 담당자 배정까지, 사업은 예산까지.
B30: ③ 업무일지 / 사업추진일지 | C30: 날짜별로 한 줄씩 기록합니다. 사건번호·사업번호만 고르면 나머지는 자동.
B31: ④ 일일실시사항 | C31: 사건·사업과 무관한 일일 업무를 그날그날 기록합니다.
B32: ⑤ 마감 전 | C32: [입력검증]에서 오류 행이 0인지 확인한 뒤 [대시보드]로 보고합니다.
B34: 색상 규칙
B35: 파란 글씨 | C35: 직접 입력하는 칸
B36: 검정 글씨 | C36: 같은 시트 안에서 자동 계산되는 칸 (덮어쓰지 마세요)
B37: 초록 글씨 | C37: 다른 시트에서 자동으로 끌어온 칸 (업무일지 담당자칸은 덮어써서 그 행만 바꿀 수 있음)
B38: 노란 배경 | C38: 반드시 확인·변경해야 하는 핵심 입력값 (기준연도, 조회 연·월, 이수 기준, 사건·사업 선택)
B39: 행 배경색 | C39: 완료 = 연녹색 / 보류 = 주황 / 기한이 지났는데 미완료 = 빨강
B41: 집계 기준 — 헷갈리기 쉬운 것
B42: 회차 vs 사건 | C42: 같은 사건을 참관 일정 때문에 여러 날 나눠 하면 [회차]가 1·2·3으로 붙습니다. [회차]는 작업량, [사건]은 실제 사건 개수이며 출장·분석을 따로 셉니다.
B43: 전체 사건 | C43: 출장 사건 + 분석 사건이 아닙니다. 한 사건에서 둘 다 했으면 전체에는 1로만 잡힙니다 — 두 칸을 더하지 마세요.
B44: 사건수 합계 | C44: 팀별·개인별 사건수의 합계 칸은 각 값의 단순 합이 아니라 부서 전체 고유 사건 수입니다. 한 사건에 여러 팀·여러 사람이 걸쳐 있기 때문입니다.
B45: 교육 | C45: 사건번호와 묶이지 않으므로 회차만 집계합니다. 사건 수에는 들어가지 않습니다.
B46: 월 귀속 | C46: 출장·분석·교육은 '시작일', 일일실시사항은 '일자', 사업추진일지는 '일자'가 속한 달로 집계됩니다.
B47: 투입인원(명) | C47: 주담당 + 참여자 수. [사건마스터] 배정표에서 자동으로 채워집니다.
...

Sheet 월력표
A1: 월력표 · 월간 업무 캘린더
A2: ※ 노란 칸(연도·월)만 바꾸면 달력이 다시 그려집니다. ※ 각 날짜의 파란 줄은 [업무일지]에서 자동 집계된 출장·분석 건수입니다. ※ 흰 칸은 자유 메모입니다 — 연·월을 바꿔도 메모는 그대로 남으니, 달이 끝나면 시트를 복사해 보관하세요.
A4: 연도 | B4: 2026 | C4: 월 | D4: 3 | E4: =TEXT(DATE($B$4,$D$4,1),"yyyy년 m월") | H4: =DATE($B$4,$D$4,1)-WEEKDAY(DATE($B$4,$D$4,1))+1
A6: 일 | B6: 월 | C6: 화 | D6: 수 | E6: 목 | F6: 금 | G6: 토
A7: =IF(MONTH($H$4+0)<>$D$4,"",$H$4+0) | B7: =IF(MONTH($H$4+1)<>$D$4,"",$H$4+1) | C7: =IF(MONTH($H$4+2)<>$D$4,"",$H$4+2) | D7: =IF(MONTH($H$4+3)<>$D$4,"",$H$4+3) | E7: =IF(MONTH($H$4+4)<>$D$4,"",$H$4+4) | F7: =IF(MONTH($H$4+5)<>$D$4,"",$H$4+5) | G7: =IF(MONTH($H$4+6)<>$D$4,"",$H$4+6) | J7: =IF(A7="",0,COUNTIFS(업무일지!$B$5:$B$1004,"<="&A7,업무일지!$C$5:$C$1004,">="&A7,업무일지!$D$5:$D$1004,"출장")) | K7: =IF(B7="",0,COUNTIFS(업무일지!$B$5:$B$1004,"<="&B7,업무일지!$C$5:$C$1004,">="&B7,업무일지!$D$5:$D$1004,"출장")) | L7: =IF(C7="",0,COUNTIFS(업무일지!$B$5:$B$1004,"<="&C7,업무일지!$C$5:$C$1004,">="&C7,업무일지!$D$5:$D$1004,"출장")) | M7: =IF(D7="",0,COUNTIFS(업무일지!$B$5:$B$1004,"<="&D7,업무일지!$C$5:$C$1004,">="&D7,업무일지!$D$5:$D$1004,"출장")) | N7: =IF(E7="",0,COUNTIFS(업무일지!$B$5:$B$1004,"<="&E7,업무일지!$C$5:$C$1004,">="&E7,업무일지!$D$5:$D$1004,"출장")) | O7: =IF(F7="",0,COUNTIFS(업무일지!$B$5:$B$1004,"<="&F7,업무일지!$C$5:$C$1004,">="&F7,업무일지!$D$5:$D$1004,"출장")) | P7: =IF(G7="",0,COUNTIFS(업무일지!$B$5:$B$1004,"<="&G7,업무일지!$C$5:$C$1004,">="&G7,업무일지!$D$5:$D$1004,"출장")) | Q7: =IF(A7="",0,COUNTIFS(업무일지!$B$5:$B$1004,"<="&A7,업무일지!$C$5:$C$1004,">="&A7,업무일지!$D$5:$D$1004,"분석")) | R7: =IF(B7="",0,COUNTIFS(업무일지!$B$5:$B$1004,"<="&B7,업무일지!$C$5:$C$1004,">="&B7,업무일지!$D$5:$D$1004,"분석")) | S7: =IF(C7="",0,COUNTIFS(업무일지!$B$5:$B$1004,"<="&C7,업무일지!$C$5:$C$1004,">="&C7,업무일지!$D$5:$D$1004,"분석")) | T7: =IF(D7="",0,COUNTIFS(업무일지!$B$5:$B$1004,"<="&D7,업무일지!$C$5:$C$1004,">="&D7,업무일지!$D$5:$D$1004,"분석")) | U7: =IF(E7="",0,COUNTIFS(업무일지!$B$5:$B$1004,"<="&E7,업무일지!$C$5:$C$1004,">="&E7,업무일지!$D$5:$D$1004,"분석")) | V7: =IF(F7="",0,COUNTIFS(업무일지!$B$5:$B$1004,"<="&F7,업무일지!$C$5:$C$1004,">="&F7,업무일지!$D$5:$D$1004,"분석")) | W7: =IF(G7="",0,COUNTIFS(업무일지!$B$5:$B$1004,"<="&G7,업무일지!$C$5:$C$1004,">="&G7,업무일지!$D$5:$D$1004,"분석")) | X7: =IF(A7="",0,COUNTIFS(업무일지!$B$5:$B$1004,"<="&A7,업무일지!$C$5:$C$1004,">="&A7,업무일지!$D$5:$D$1004,"교육")) | Y7: =IF(B7="",0,COUNTIFS(업무일지!$B$5:$B$1004,"<="&B7,업무일지!$C$5:$C$1004,">="&B7,업무일지!$D$5:$D$1004,"교육")) | Z7: =IF(C7="",0,COUNTIFS(업무일지!$B$5:$B$1004,"<="&C7,업무일지!$C$5:$C$1004,">="&C7,업무일지!$D$5:$D$1004,"교육")) | AA7: =IF(D7="",0,COUNTIFS(업무일지!$B$5:$B$1004,"<="&D7,업무일지!$C$5:$C$1004,">="&D7,업무일지!$D$5:$D$1004,"교육")) | AB7: =IF(E7="",0,COUNTIFS(업무일지!$B$5:$B$1004,"<="&E7,업무일지!$C$5:$C$1004,">="&E7,업무일지!$D$5:$D$1004,"교육")) | AC7: =IF(F7="",0,COUNTIFS(업무일지!$B$5:$B$1004,"<="&F7,업무일지!$C$5:$C$1004,">="&F7,업무일지!$D$5:$D$1004,"교육")) | AD7: =IF(G7="",0,COUNTIFS(업무일지!$B$5:$B$1004,"<="&G7,업무일지!$C$5:$C$1004,">="&G7,업무일지!$D$5:$D$1004,"교육"))
A8: =IF(A7="","",IF(J7+Q7+X7=0,"",IF(J7=0,"","출장 "&J7&" ")&IF(Q7=0,"","분석 "&Q7&" ")&IF(X7=0,"","교육 "&X7))) | B8: =IF(B7="","",IF(K7+R7+Y7=0,"",IF(K7=0,"","출장 "&K7&" ")&IF(R7=0,"","분석 "&R7&" ")&IF(Y7=0,"","교육 "&Y7))) | C8: =IF(C7="","",IF(L7+S7+Z7=0,"",IF(L7=0,"","출장 "&L7&" ")&IF(S7=0,"","분석 "&S7&" ")&IF(Z7=0,"","교육 "&Z7))) | D8: =IF(D7="","",IF(M7+T7+AA7=0,"",IF(M7=0,"","출장 "&M7&" ")&IF(T7=0,"","분석 "&T7&" ")&IF(AA7=0,"","교육 "&AA7))) | E8: =IF(E7="","",IF(N7+U7+AB7=0,"",IF(N7=0,"","출장 "&N7&" ")&IF(U7=0,"","분석 "&U7&" ")&IF(AB7=0,"","교육 "&AB7))) | F8: =IF(F7="","",IF(O7+V7+AC7=0,"",IF(O7=0,"","출장 "&O7&" ")&IF(V7=0,"","분석 "&V7&" ")&IF(AC7=0,"","교육 "&AC7))) | G8: =IF(G7="","",IF(P7+W7+AD7=0,"",IF(P7=0,"","출장 "&P7&" ")&IF(W7=0,"","분석 "&W7&" ")&IF(AD7=0,"","교육 "&AD7))) | J8: =IF(A10="",0,COUNTIFS(업무일지!$B$5:$B$1004,"<="&A10,업무일지!$C$5:$C$1004,">="&A10,업무일지!$D$5:$D$1004,"출장")) | K8: =IF(B10="",0,COUNTIFS(업무일지!$B$5:$B$1004,"<="&B10,업무일지!$C$5:$C$1004,">="&B10,업무일지!$D$5:$D$1004,"출장")) | L8: =IF(C10="",0,COUNTIFS(업무일지!$B$5:$B$1004,"<="&C10,업무일지!$C$5:$C$1004,">="&C10,업무일지!$D$5:$D$1004,"출장")) | M8: =IF(D10="",0,COUNTIFS(업무일지!$B$5:$B$1004,"<="&D10,업무일지!$C$5:$C$1004,">="&D10,업무일지!$D$5:$D$1004,"출장")) | N8: =IF(E10="",0,COUNTIFS(업무일지!$B$5:$B$1004,"<="&E10,업무일지!$C$5:$C$1004,">="&E10,업무일지!$D$5:$D$1004,"출장")) | O8: =IF(F10="",0,COUNTIFS(업무일지!$B$5:$B$1004,"<="&F10,업무일지!$C$5:$C$1004,">="&F10,업무일지!$D$5:$D$1004,"출장")) | P8: =IF(G10="",0,COUNTIFS(업무일지!$B$5:$B$1004,"<="&G10,업무일지!$C$5:$C$1004,">="&G10,업무일지!$D$5:$D$1004,"출장")) | Q8: =IF(A10="",0,COUNTIFS(업무일지!$B$5:$B$1004,"<="&A10,업무일지!$C$5:$C$1004,">="&A10,업무일지!$D$5:$D$1004,"분석")) | R8: =IF(B10="",0,COUNTIFS(업무일지!$B$5:$B$1004,"<="&B10,업무일지!$C$5:$C$1004,">="&B10,업무일지!$D$5:$D$1004,"분석")) | S8: =IF(C10="",0,COUNTIFS(업무일지!$B$5:$B$1004,"<="&C10,업무일지!$C$5:$C$1004,">="&C10,업무일지!$D$5:$D$1004,"분석")) | T8: =IF(D10="",0,COUNTIFS(업무일지!$B$5:$B$1004,"<="&D10,업무일지!$C$5:$C$1004,">="&D10,업무일지!$D$5:$D$1004,"분석")) | U8: =IF(E10="",0,COUNTIFS(업무일지!$B$5:$B$1004,"<="&E10,업무일지!$C$5:$C$1004,">="&E10,업무일지!$D$5:$D$1004,"분석")) | V8: =IF(F10="",0,COUNTIFS(업무일지!$B$5:$B$1004,"<="&F10,업무일지!$C$5:$C$1004,">="&F10,업무일지!$D$5:$D$1004,"분석")) | W8: =IF(G10="",0,COUNTIFS(업무일지!$B$5:$B$1004,"<="&G10,업무일지!$C$5:$C$1004,">="&G10,업무일지!$D$5:$D$1004,"분석")) | X8: =IF(A10="",0,COUNTIFS(업무일지!$B$5:$B$1004,"<="&A10,업무일지!$C$5:$C$1004,">="&A10,업무일지!$D$5:$D$1004,"교육")) | Y8: =IF(B10="",0,COUNTIFS(업무일지!$B$5:$B$1004,"<="&B10,업무일지!$C$5:$C$1004,">="&B10,업무일지!$D$5:$D$1004,"교육")) | Z8: =IF(C10="",0,COUNTIFS(업무일지!$B$5:$B$1004,"<="&C10,업무일지!$C$5:$C$1004,">="&C10,업무일지!$D$5:$D$1004,"교육")) | AA8: =IF(D10="",0,COUNTIFS(업무일지!$B$5:$B$1004,"<="&D10,업무일지!$C$5:$C$1004,">="&D10,업무일지!$D$5:$D$1004,"교육")) | AB8: =IF(E10="",0,COUNTIFS(업무일지!$B$5:$B$1004,"<="&E10,업무일지!$C$5:$C$1004,">="&E10,업무일지!$D$5:$D$1004,"교육")) | AC8: =IF(F10="",0,COUNTIFS(업무일지!$B$5:$B$1004,"<="&F10,업무일지!$C$5:$C$1004,">="&F10,업무일지!$D$5:$D$1004,"교육")) | AD8: =IF(G10="",0,COUNTIFS(업무일지!$B$5:$B$1004,"<="&G10,업무일지!$C$5:$C$1004,">="&G10,업무일지!$D$5:$D$1004,"교육"))
J9: =IF(A13="",0,COUNTIFS(업무일지!$B$5:$B$1004,"<="&A13,업무일지!$C$5:$C$1004,">="&A13,업무일지!$D$5:$D$1004,"출장")) | K9: =IF(B13="",0,COUNTIFS(업무일지!$B$5:$B$1004,"<="&B13,업무일지!$C$5:$C$1004,">="&B13,업무일지!$D$5:$D$1004,"출장")) | L9: =IF(C13="",0,COUNTIFS(업무일지!$B$5:$B$1004,"<="&C13,업무일지!$C$5:$C$1004,">="&C13,업무일지!$D$5:$D$1004,"출장")) | M9: =IF(D13="",0,COUNTIFS(업무일지!$B$5:$B$1004,"<="&D13,업무일지!$C$5:$C$1004,">="&D13,업무일지!$D$5:$D$1004,"출장")) | N9: =IF(E13="",0,COUNTIFS(업무일지!$B$5:$B$1004,"<="&E13,업무일지!$C$5:$C$1004,">="&E13,업무일지!$D$5:$D$1004,"출장")) | O9: =IF(F13="",0,COUNTIFS(업무일지!$B$5:$B$1004,"<="&F13,업무일지!$C$5:$C$1004,">="&F13,업무일지!$D$5:$D$1004,"출장")) | P9: =IF(G13="",0,COUNTIFS(업무일지!$B$5:$B$1004,"<="&G13,업무일지!$C$5:$C$1004,">="&G13,업무일지!$D$5:$D$1004,"출장")) | Q9: =IF(A13="",0,COUNTIFS(업무일지!$B$5:$B$1004,"<="&A13,업무일지!$C$5:$C$1004,">="&A13,업무일지!$D$5:$D$1004,"분석")) | R9: =IF(B13="",0,COUNTIFS(업무일지!$B$5:$B$1004,"<="&B13,업무일지!$C$5:$C$1004,">="&B13,업무일지!$D$5:$D$1004,"분석")) | S9: =IF(C13="",0,COUNTIFS(업무일지!$B$5:$B$1004,"<="&C13,업무일지!$C$5:$C$1004,">="&C13,업무일지!$D$5:$D$1004,"분석")) | T9: =IF(D13="",0,COUNTIFS(업무일지!$B$5:$B$1004,"<="&D13,업무일지!$C$5:$C$1004,">="&D13,업무일지!$D$5:$D$1004,"분석")) | U9: =IF(E13="",0,COUNTIFS(업무일지!$B$5:$B$1004,"<="&E13,업무일지!$C$5:$C$1004,">="&E13,업무일지!$D$5:$D$1004,"분석")) | V9: =IF(F13="",0,COUNTIFS(업무일지!$B$5:$B$1004,"<="&F13,업무일지!$C$5:$C$1004,">="&F13,업무일지!$D$5:$D$1004,"분석")) | W9: =IF(G13="",0,COUNTIFS(업무일지!$B$5:$B$1004,"<="&G13,업무일지!$C$5:$C$1004,">="&G13,업무일지!$D$5:$D$1004,"분석")) | X9: =IF(A13="",0,COUNTIFS(업무일지!$B$5:$B$1004,"<="&A13,업무일지!$C$5:$C$1004,">="&A13,업무일지!$D$5:$D$1004,"교육")) | Y9: =IF(B13="",0,COUNTIFS(업무일지!$B$5:$B$1004,"<="&B13,업무일지!$C$5:$C$1004,">="&B13,업무일지!$D$5:$D$1004,"교육")) | Z9: =IF(C13="",0,COUNTIFS(업무일지!$B$5:$B$1004,"<="&C13,업무일지!$C$5:$C$1004,">="&C13,업무일지!$D$5:$D$1004,"교육")) | AA9: =IF(D13="",0,COUNTIFS(업무일지!$B$5:$B$1004,"<="&D13,업무일지!$C$5:$C$1004,">="&D13,업무일지!$D$5:$D$1004,"교육")) | AB9: =IF(E13="",0,COUNTIFS(업무일지!$B$5:$B$1004,"<="&E13,업무일지!$C$5:$C$1004,">="&E13,업무일지!$D$5:$D$1004,"교육")) | AC9: =IF(F13="",0,COUNTIFS(업무일지!$B$5:$B$1004,"<="&F13,업무일지!$C$5:$C$1004,">="&F13,업무일지!$D$5:$D$1004,"교육")) | AD9: =IF(G13="",0,COUNTIFS(업무일지!$B$5:$B$1004,"<="&G13,업무일지!$C$5:$C$1004,">="&G13,업무일지!$D$5:$D$1004,"교육"))
A10: =IF(MONTH($H$4+7)<>$D$4,"",$H$4+7) | B10: =IF(MONTH($H$4+8)<>$D$4,"",$H$4+8) | C10: =IF(MONTH($H$4+9)<>$D$4,"",$H$4+9) | D10: =IF(MONTH($H$4+10)<>$D$4,"",$H$4+10) | E10: =IF(MONTH($H$4+11)<>$D$4,"",$H$4+11) | F10: =IF(MONTH($H$4+12)<>$D$4,"",$H$4+12) | G10: =IF(MONTH($H$4+13)<>$D$4,"",$H$4+13) | J10: =IF(A16="",0,COUNTIFS(업무일지!$B$5:$B$1004,"<="&A16,업무일지!$C$5:$C$1004,">="&A16,업무일지!$D$5:$D$1004,"출장")) | K10: =IF(B16="",0,COUNTIFS(업무일지!$B$5:$B$1004,"<="&B16,업무일지!$C$5:$C$1004,">="&B16,업무일지!$D$5:$D$1004,"출장")) | L10: =IF(C16="",0,COUNTIFS(업무일지!$B$5:$B$1004,"<="&C16,업무일지!$C$5:$C$1004,">="&C16,업무일지!$D$5:$D$1004,"출장")) | M10: =IF(D16="",0,COUNTIFS(업무일지!$B$5:$B$1004,"<="&D16,업무일지!$C$5:$C$1004,">="&D16,업무일지!$D$5:$D$1004,"출장")) | N10: =IF(E16="",0,COUNTIFS(업무일지!$B$5:$B$1004,"<="&E16,업무일지!$C$5:$C$1004,">="&E16,업무일지!$D$5:$D$1004,"출장")) | O10: =IF(F16="",0,COUNTIFS(업무일지!$B$5:$B$1004,"<="&F16,업무일지!$C$5:$C$1004,">="&F16,업무일지!$D$5:$D$1004,"출장")) | P10: =IF(G16="",0,COUNTIFS(업무일지!$B$5:$B$1004,"<="&G16,업무일지!$C$5:$C$1004,">="&G16,업무일지!$D$5:$D$1004,"출장")) | Q10: =IF(A16="",0,COUNTIFS(업무일지!$B$5:$B$1004,"<="&A16,업무일지!$C$5:$C$1004,">="&A16,업무일지!$D$5:$D$1004,"분석")) | R10: =IF(B16="",0,COUNTIFS(업무일지!$B$5:$B$1004,"<="&B16,업무일지!$C$5:$C$1004,">="&B16,업무일지!$D$5:$D$1004,"분석")) | S10: =IF(C16="",0,COUNTIFS(업무일지!$B$5:$B$1004,"<="&C16,업무일지!$C$5:$C$1004,">="&C16,업무일지!$D$5:$D$1004,"분석")) | T10: =IF(D16="",0,COUNTIFS(업무일지!$B$5:$B$1004,"<="&D16,업무일지!$C$5:$C$1004,">="&D16,업무일지!$D$5:$D$1004,"분석")) | U10: =IF(E16="",0,COUNTIFS(업무일지!$B$5:$B$1004,"<="&E16,업무일지!$C$5:$C$1004,">="&E16,업무일지!$D$5:$D$1004,"분석")) | V10: =IF(F16="",0,COUNTIFS(업무일지!$B$5:$B$1004,"<="&F16,업무일지!$C$5:$C$1004,">="&F16,업무일지!$D$5:$D$1004,"분석")) | W10: =IF(G16="",0,COUNTIFS(업무일지!$B$5:$B$1004,"<="&G16,업무일지!$C$5:$C$1004,">="&G16,업무일지!$D$5:$D$1004,"분석")) | X10: =IF(A16="",0,COUNTIFS(업무일지!$B$5:$B$1004,"<="&A16,업무일지!$C$5:$C$1004,">="&A16,업무일지!$D$5:$D$1004,"교육")) | Y10: =IF(B16="",0,COUNTIFS(업무일지!$B$5:$B$1004,"<="&B16,업무일지!$C$5:$C$1004,">="&B16,업무일지!$D$5:$D$1004,"교육")) | Z10: =IF(C16="",0,COUNTIFS(업무일지!$B$5:$B$1004,"<="&C16,업무일지!$C$5:$C$1004,">="&C16,업무일지!$D$5:$D$1004,"교육")) | AA10: =IF(D16="",0,COUNTIFS(업무일지!$B$5:$B$1004,"<="&D16,업무일지!$C$5:$C$1004,">="&D16,업무일지!$D$5:$D$1004,"교육")) | AB10: =IF(E16="",0,COUNTIFS(업무일지!$B$5:$B$1004,"<="&E16,업무일지!$C$5:$C$1004,">="&E16,업무일지!$D$5:$D$1004,"교육")) | AC10: =IF(F16="",0,COUNTIFS(업무일지!$B$5:$B$1004,"<="&F16,업무일지!$C$5:$C$1004,">="&F16,업무일지!$D$5:$D$1004,"교육")) | AD10: =IF(G16="",0,COUNTIFS(업무일지!$B$5:$B$1004,"<="&G16,업무일지!$C$5:$C$1004,">="&G16,업무일지!$D$5:$D$1004,"교육"))
A11: =IF(A10="","",IF(J8+Q8+X8=0,"",IF(J8=0,"","출장 "&J8&" ")&IF(Q8=0,"","분석 "&Q8&" ")&IF(X8=0,"","교육 "&X8))) | B11: =IF(B10="","",IF(K8+R8+Y8=0,"",IF(K8=0,"","출장 "&K8&" ")&IF(R8=0,"","분석 "&R8&" ")&IF(Y8=0,"","교육 "&Y8))) | C11: =IF(C10="","",IF(L8+S8+Z8=0,"",IF(L8=0,"","출장 "&L8&" ")&IF(S8=0,"","분석 "&S8&" ")&IF(Z8=0,"","교육 "&Z8))) | D11: =IF(D10="","",IF(M8+T8+AA8=0,"",IF(M8=0,"","출장 "&M8&" ")&IF(T8=0,"","분석 "&T8&" ")&IF(AA8=0,"","교육 "&AA8))) | E11: =IF(E10="","",IF(N8+U8+AB8=0,"",IF(N8=0,"","출장 "&N8&" ")&IF(U8=0,"","분석 "&U8&" ")&IF(AB8=0,"","교육 "&AB8))) | F11: =IF(F10="","",IF(O8+V8+AC8=0,"",IF(O8=0,"","출장 "&O8&" ")&IF(V8=0,"","분석 "&V8&" ")&IF(AC8=0,"","교육 "&AC8))) | G11: =IF(G10="","",IF(P8+W8+AD8=0,"",IF(P8=0,"","출장 "&P8&" ")&IF(W8=0,"","분석 "&W8&" ")&IF(AD8=0,"","교육 "&AD8))) | J11: =IF(A19="",0,COUNTIFS(업무일지!$B$5:$B$1004,"<="&A19,업무일지!$C$5:$C$1004,">="&A19,업무일지!$D$5:$D$1004,"출장")) | K11: =IF(B19="",0,COUNTIFS(업무일지!$B$5:$B$1004,"<="&B19,업무일지!$C$5:$C$1004,">="&B19,업무일지!$D$5:$D$1004,"출장")) | L11: =IF(C19="",0,COUNTIFS(업무일지!$B$5:$B$1004,"<="&C19,업무일지!$C$5:$C$1004,">="&C19,업무일지!$D$5:$D$1004,"출장")) | M11: =IF(D19="",0,COUNTIFS(업무일지!$B$5:$B$1004,"<="&D19,업무일지!$C$5:$C$1004,">="&D19,업무일지!$D$5:$D$1004,"출장")) | N11: =IF(E19="",0,COUNTIFS(업무일지!$B$5:$B$1004,"<="&E19,업무일지!$C$5:$C$1004,">="&E19,업무일지!$D$5:$D$1004,"출장")) | O11: =IF(F19="",0,COUNTIFS(업무일지!$B$5:$B$1004,"<="&F19,업무일지!$C$5:$C$1004,">="&F19,업무일지!$D$5:$D$1004,"출장")) | P11: =IF(G19="",0,COUNTIFS(업무일지!$B$5:$B$1004,"<="&G19,업무일지!$C$5:$C$1004,">="&G19,업무일지!$D$5:$D$1004,"출장")) | Q11: =IF(A19="",0,COUNTIFS(업무일지!$B$5:$B$1004,"<="&A19,업무일지!$C$5:$C$1004,">="&A19,업무일지!$D$5:$D$1004,"분석")) | R11: =IF(B19="",0,COUNTIFS(업무일지!$B$5:$B$1004,"<="&B19,업무일지!$C$5:$C$1004,">="&B19,업무일지!$D$5:$D$1004,"분석")) | S11: =IF(C19="",0,COUNTIFS(업무일지!$B$5:$B$1004,"<="&C19,업무일지!$C$5:$C$1004,">="&C19,업무일지!$D$5:$D$1004,"분석")) | T11: =IF(D19="",0,COUNTIFS(업무일지!$B$5:$B$1004,"<="&D19,업무일지!$C$5:$C$1004,">="&D19,업무일지!$D$5:$D$1004,"분석")) | U11: =IF(E19="",0,COUNTIFS(업무일지!$B$5:$B$1004,"<="&E19,업무일지!$C$5:$C$1004,">="&E19,업무일지!$D$5:$D$1004,"분석")) | V11: =IF(F19="",0,COUNTIFS(업무일지!$B$5:$B$1004,"<="&F19,업무일지!$C$5:$C$1004,">="&F19,업무일지!$D$5:$D$1004,"분석")) | W11: =IF(G19="",0,COUNTIFS(업무일지!$B$5:$B$1004,"<="&G19,업무일지!$C$5:$C$1004,">="&G19,업무일지!$D$5:$D$1004,"분석")) | X11: =IF(A19="",0,COUNTIFS(업무일지!$B$5:$B$1004,"<="&A19,업무일지!$C$5:$C$1004,">="&A19,업무일지!$D$5:$D$1004,"교육")) | Y11: =IF(B19="",0,COUNTIFS(업무일지!$B$5:$B$1004,"<="&B19,업무일지!$C$5:$C$1004,">="&B19,업무일지!$D$5:$D$1004,"교육")) | Z11: =IF(C19="",0,COUNTIFS(업무일지!$B$5:$B$1004,"<="&C19,업무일지!$C$5:$C$1004,">="&C19,업무일지!$D$5:$D$1004,"교육")) | AA11: =IF(D19="",0,COUNTIFS(업무일지!$B$5:$B$1004,"<="&D19,업무일지!$C$5:$C$1004,">="&D19,업무일지!$D$5:$D$1004,"교육")) | AB11: =IF(E19="",0,COUNTIFS(업무일지!$B$5:$B$1004,"<="&E19,업무일지!$C$5:$C$1004,">="&E19,업무일지!$D$5:$D$1004,"교육")) | AC11: =IF(F19="",0,COUNTIFS(업무일지!$B$5:$B$1004,"<="&F19,업무일지!$C$5:$C$1004,">="&F19,업무일지!$D$5:$D$1004,"교육")) | AD11: =IF(G19="",0,COUNTIFS(업무일지!$B$5:$B$1004,"<="&G19,업무일지!$C$5:$C$1004,">="&G19,업무일지!$D$5:$D$1004,"교육"))
J12: =IF(A22="",0,COUNTIFS(업무일지!$B$5:$B$1004,"<="&A22,업무일지!$C$5:$C$1004,">="&A22,업무일지!$D$5:$D$1004,"출장")) | K12: =IF(B22="",0,COUNTIFS(업무일지!$B$5:$B$1004,"<="&B22,업무일지!$C$5:$C$1004,">="&B22,업무일지!$D$5:$D$1004,"출장")) | L12: =IF(C22="",0,COUNTIFS(업무일지!$B$5:$B$1004,"<="&C22,업무일지!$C$5:$C$1004,">="&C22,업무일지!$D$5:$D$1004,"출장")) | M12: =IF(D22="",0,COUNTIFS(업무일지!$B$5:$B$1004,"<="&D22,업무일지!$C$5:$C$1004,">="&D22,업무일지!$D$5:$D$1004,"출장")) | N12: =IF(E22="",0,COUNTIFS(업무일지!$B$5:$B$1004,"<="&E22,업무일지!$C$5:$C$1004,">="&E22,업무일지!$D$5:$D$1004,"출장")) | O12: =IF(F22="",0,COUNTIFS(업무일지!$B$5:$B$1004,"<="&F22,업무일지!$C$5:$C$1004,">="&F22,업무일지!$D$5:$D$1004,"출장")) | P12: =IF(G22="",0,COUNTIFS(업무일지!$B$5:$B$1004,"<="&G22,업무일지!$C$5:$C$1004,">="&G22,업무일지!$D$5:$D$1004,"출장")) | Q12: =IF(A22="",0,COUNTIFS(업무일지!$B$5:$B$1004,"<="&A22,업무일지!$C$5:$C$1004,">="&A22,업무일지!$D$5:$D$1004,"분석")) | R12: =IF(B22="",0,COUNTIFS(업무일지!$B$5:$B$1004,"<="&B22,업무일지!$C$5:$C$1004,">="&B22,업무일지!$D$5:$D$1004,"분석")) | S12: =IF(C22="",0,COUNTIFS(업무일지!$B$5:$B$1004,"<="&C22,업무일지!$C$5:$C$1004,">="&C22,업무일지!$D$5:$D$1004,"분석")) | T12: =IF(D22="",0,COUNTIFS(업무일지!$B$5:$B$1004,"<="&D22,업무일지!$C$5:$C$1004,">="&D22,업무일지!$D$5:$D$1004,"분석")) | U12: =IF(E22="",0,COUNTIFS(업무일지!$B$5:$B$1004,"<="&E22,업무일지!$C$5:$C$1004,">="&E22,업무일지!$D$5:$D$1004,"분석")) | V12: =IF(F22="",0,COUNTIFS(업무일지!$B$5:$B$1004,"<="&F22,업무일지!$C$5:$C$1004,">="&F22,업무일지!$D$5:$D$1004,"분석")) | W12: =IF(G22="",0,COUNTIFS(업무일지!$B$5:$B$1004,"<="&G22,업무일지!$C$5:$C$1004,">="&G22,업무일지!$D$5:$D$1004,"분석")) | X12: =IF(A22="",0,COUNTIFS(업무일지!$B$5:$B$1004,"<="&A22,업무일지!$C$5:$C$1004,">="&A22,업무일지!$D$5:$D$1004,"교육")) | Y12: =IF(B22="",0,COUNTIFS(업무일지!$B$5:$B$1004,"<="&B22,업무일지!$C$5:$C$1004,">="&B22,업무일지!$D$5:$D$1004,"교육")) | Z12: =IF(C22="",0,COUNTIFS(업무일지!$B$5:$B$1004,"<="&C22,업무일지!$C$5:$C$1004,">="&C22,업무일지!$D$5:$D$1004,"교육")) | AA12: =IF(D22="",0,COUNTIFS(업무일지!$B$5:$B$1004,"<="&D22,업무일지!$C$5:$C$1004,">="&D22,업무일지!$D$5:$D$1004,"교육")) | AB12: =IF(E22="",0,COUNTIFS(업무일지!$B$5:$B$1004,"<="&E22,업무일지!$C$5:$C$1004,">="&E22,업무일지!$D$5:$D$1004,"교육")) | AC12: =IF(F22="",0,COUNTIFS(업무일지!$B$5:$B$1004,"<="&F22,업무일지!$C$5:$C$1004,">="&F22,업무일지!$D$5:$D$1004,"교육")) | AD12: =IF(G22="",0,COUNTIFS(업무일지!$B$5:$B$1004,"<="&G22,업무일지!$C$5:$C$1004,">="&G22,업무일지!$D$5:$D$1004,"교육"))
A13: =IF(MONTH($H$4+14)<>$D$4,"",$H$4+14) | B13: =IF(MONTH($H$4+15)<>$D$4,"",$H$4+15) | C13: =IF(MONTH($H$4+16)<>$D$4,"",$H$4+16) | D13: =IF(MONTH($H$4+17)<>$D$4,"",$H$4+17) | E13: =IF(MONTH($H$4+18)<>$D$4,"",$H$4+18) | F13: =IF(MONTH($H$4+19)<>$D$4,"",$H$4+19) | G13: =IF(MONTH($H$4+20)<>$D$4,"",$H$4+20)
A14: =IF(A13="","",IF(J9+Q9+X9=0,"",IF(J9=0,"","출장 "&J9&" ")&IF(Q9=0,"","분석 "&Q9&" ")&IF(X9=0,"","교육 "&X9))) | B14: =IF(B13="","",IF(K9+R9+Y9=0,"",IF(K9=0,"","출장 "&K9&" ")&IF(R9=0,"","분석 "&R9&" ")&IF(Y9=0,"","교육 "&Y9))) | C14: =IF(C13="","",IF(L9+S9+Z9=0,"",IF(L9=0,"","출장 "&L9&" ")&IF(S9=0,"","분석 "&S9&" ")&IF(Z9=0,"","교육 "&Z9))) | D14: =IF(D13="","",IF(M9+T9+AA9=0,"",IF(M9=0,"","출장 "&M9&" ")&IF(T9=0,"","분석 "&T9&" ")&IF(AA9=0,"","교육 "&AA9))) | E14: =IF(E13="","",IF(N9+U9+AB9=0,"",IF(N9=0,"","출장 "&N9&" ")&IF(U9=0,"","분석 "&U9&" ")&IF(AB9=0,"","교육 "&AB9))) | F14: =IF(F13="","",IF(O9+V9+AC9=0,"",IF(O9=0,"","출장 "&O9&" ")&IF(V9=0,"","분석 "&V9&" ")&IF(AC9=0,"","교육 "&AC9))) | G14: =IF(G13="","",IF(P9+W9+AD9=0,"",IF(P9=0,"","출장 "&P9&" ")&IF(W9=0,"","분석 "&W9&" ")&IF(AD9=0,"","교육 "&AD9)))
A16: =IF(MONTH($H$4+21)<>$D$4,"",$H$4+21) | B16: =IF(MONTH($H$4+22)<>$D$4,"",$H$4+22) | C16: =IF(MONTH($H$4+23)<>$D$4,"",$H$4+23) | D16: =IF(MONTH($H$4+24)<>$D$4,"",$H$4+24) | E16: =IF(MONTH($H$4+25)<>$D$4,"",$H$4+25) | F16: =IF(MONTH($H$4+26)<>$D$4,"",$H$4+26) | G16: =IF(MONTH($H$4+27)<>$D$4,"",$H$4+27)
A17: =IF(A16="","",IF(J10+Q10+X10=0,"",IF(J10=0,"","출장 "&J10&" ")&IF(Q10=0,"","분석 "&Q10&" ")&IF(X10=0,"","교육 "&X10))) | B17: =IF(B16="","",IF(K10+R10+Y10=0,"",IF(K10=0,"","출장 "&K10&" ")&IF(R10=0,"","분석 "&R10&" ")&IF(Y10=0,"","교육 "&Y10))) | C17: =IF(C16="","",IF(L10+S10+Z10=0,"",IF(L10=0,"","출장 "&L10&" ")&IF(S10=0,"","분석 "&S10&" ")&IF(Z10=0,"","교육 "&Z10))) | D17: =IF(D16="","",IF(M10+T10+AA10=0,"",IF(M10=0,"","출장 "&M10&" ")&IF(T10=0,"","분석 "&T10&" ")&IF(AA10=0,"","교육 "&AA10))) | E17: =IF(E16="","",IF(N10+U10+AB10=0,"",IF(N10=0,"","출장 "&N10&" ")&IF(U10=0,"","분석 "&U10&" ")&IF(AB10=0,"","교육 "&AB10))) | F17: =IF(F16="","",IF(O10+V10+AC10=0,"",IF(O10=0,"","출장 "&O10&" ")&IF(V10=0,"","분석 "&V10&" ")&IF(AC10=0,"","교육 "&AC10))) | G17: =IF(G16="","",IF(P10+W10+AD10=0,"",IF(P10=0,"","출장 "&P10&" ")&IF(W10=0,"","분석 "&W10&" ")&IF(AD10=0,"","교육 "&AD10)))
A19: =IF(MONTH($H$4+28)<>$D$4,"",$H$4+28) | B19: =IF(MONTH($H$4+29)<>$D$4,"",$H$4+29) | C19: =IF(MONTH($H$4+30)<>$D$4,"",$H$4+30) | D19: =IF(MONTH($H$4+31)<>$D$4,"",$H$4+31) | E19: =IF(MONTH($H$4+32)<>$D$4,"",$H$4+32) | F19: =IF(MONTH($H$4+33)<>$D$4,"",$H$4+33) | G19: =IF(MONTH($H$4+34)<>$D$4,"",$H$4+34)
A20: =IF(A19="","",IF(J11+Q11+X11=0,"",IF(J11=0,"","출장 "&J11&" ")&IF(Q11=0,"","분석 "&Q11&" ")&IF(X11=0,"","교육 "&X11))) | B20: =IF(B19="","",IF(K11+R11+Y11=0,"",IF(K11=0,"","출장 "&K11&" ")&IF(R11=0,"","분석 "&R11&" ")&IF(Y11=0,"","교육 "&Y11))) | C20: =IF(C19="","",IF(L11+S11+Z11=0,"",IF(L11=0,"","출장 "&L11&" ")&IF(S11=0,"","분석 "&S11&" ")&IF(Z11=0,"","교육 "&Z11))) | D20: =IF(D19="","",IF(M11+T11+AA11=0,"",IF(M11=0,"","출장 "&M11&" ")&IF(T11=0,"","분석 "&T11&" ")&IF(AA11=0,"","교육 "&AA11))) | E20: =IF(E19="","",IF(N11+U11+AB11=0,"",IF(N11=0,"","출장 "&N11&" ")&IF(U11=0,"","분석 "&U11&" ")&IF(AB11=0,"","교육 "&AB11))) | F20: =IF(F19="","",IF(O11+V11+AC11=0,"",IF(O11=0,"","출장 "&O11&" ")&IF(V11=0,"","분석 "&V11&" ")&IF(AC11=0,"","교육 "&AC11))) | G20: =IF(G19="","",IF(P11+W11+AD11=0,"",IF(P11=0,"","출장 "&P11&" ")&IF(W11=0,"","분석 "&W11&" ")&IF(AD11=0,"","교육 "&AD11)))
A22: =IF(MONTH($H$4+35)<>$D$4,"",$H$4+35) | B22: =IF(MONTH($H$4+36)<>$D$4,"",$H$4+36) | C22: =IF(MONTH($H$4+37)<>$D$4,"",$H$4+37) | D22: =IF(MONTH($H$4+38)<>$D$4,"",$H$4+38) | E22: =IF(MONTH($H$4+39)<>$D$4,"",$H$4+39) | F22: =IF(MONTH($H$4+40)<>$D$4,"",$H$4+40) | G22: =IF(MONTH($H$4+41)<>$D$4,"",$H$4+41)
A23: =IF(A22="","",IF(J12+Q12+X12=0,"",IF(J12=0,"","출장 "&J12&" ")&IF(Q12=0,"","분석 "&Q12&" ")&IF(X12=0,"","교육 "&X12))) | B23: =IF(B22="","",IF(K12+R12+Y12=0,"",IF(K12=0,"","출장 "&K12&" ")&IF(R12=0,"","분석 "&R12&" ")&IF(Y12=0,"","교육 "&Y12))) | C23: =IF(C22="","",IF(L12+S12+Z12=0,"",IF(L12=0,"","출장 "&L12&" ")&IF(S12=0,"","분석 "&S12&" ")&IF(Z12=0,"","교육 "&Z12))) | D23: =IF(D22="","",IF(M12+T12+AA12=0,"",IF(M12=0,"","출장 "&M12&" ")&IF(T12=0,"","분석 "&T12&" ")&IF(AA12=0,"","교육 "&AA12))) | E23: =IF(E22="","",IF(N12+U12+AB12=0,"",IF(N12=0,"","출장 "&N12&" ")&IF(U12=0,"","분석 "&U12&" ")&IF(AB12=0,"","교육 "&AB12))) | F23: =IF(F22="","",IF(O12+V12+AC12=0,"",IF(O12=0,"","출장 "&O12&" ")&IF(V12=0,"","분석 "&V12&" ")&IF(AC12=0,"","교육 "&AC12))) | G23: =IF(G22="","",IF(P12+W12+AD12=0,"",IF(P12=0,"","출장 "&P12&" ")&IF(W12=0,"","분석 "&W12&" ")&IF(AD12=0,"","교육 "&AD12)))
A26: 이달 요약
A27: 구분 | B27: 회차 | C27: 출장 소요일수 | D27: 대상매체(건) | E27: 데이터량(GB) | F27: 진행중
A28: 출장 | B28: =COUNTIFS(업무일지!$B$5:$B$1004,">="&DATE($B$4,$D$4,1),업무일지!$B$5:$B$1004,"<"&DATE($B$4,$D$4+1,1),업무일지!$D$5:$D$1004,"출장") | C28: =SUMIFS(업무일지!$AF$5:$AF$1004,업무일지!$B$5:$B$1004,">="&DATE($B$4,$D$4,1),업무일지!$B$5:$B$1004,"<"&DATE($B$4,$D$4+1,1),업무일지!$D$5:$D$1004,"출장") | D28: =SUMIFS(업무일지!$AD$5:$AD$1004,업무일지!$B$5:$B$1004,">="&DATE($B$4,$D$4,1),업무일지!$B$5:$B$1004,"<"&DATE($B$4,$D$4+1,1),업무일지!$D$5:$D$1004,"출장") | E28: =SUMIFS(업무일지!$AE$5:$AE$1004,업무일지!$B$5:$B$1004,">="&DATE($B$4,$D$4,1),업무일지!$B$5:$B$1004,"<"&DATE($B$4,$D$4+1,1),업무일지!$D$5:$D$1004,"출장") | F28: =COUNTIFS(업무일지!$B$5:$B$1004,">="&DATE($B$4,$D$4,1),업무일지!$B$5:$B$1004,"<"&DATE($B$4,$D$4+1,1),업무일지!$D$5:$D$1004,"출장",업무일지!$AG$5:$AG$1004,"진행중")
A29: 분석 | B29: =COUNTIFS(업무일지!$B$5:$B$1004,">="&DATE($B$4,$D$4,1),업무일지!$B$5:$B$1004,"<"&DATE($B$4,$D$4+1,1),업무일지!$D$5:$D$1004,"분석") | C29: =SUMIFS(업무일지!$AF$5:$AF$1004,업무일지!$B$5:$B$1004,">="&DATE($B$4,$D$4,1),업무일지!$B$5:$B$1004,"<"&DATE($B$4,$D$4+1,1),업무일지!$D$5:$D$1004,"분석") | D29: =SUMIFS(업무일지!$AD$5:$AD$1004,업무일지!$B$5:$B$1004,">="&DATE($B$4,$D$4,1),업무일지!$B$5:$B$1004,"<"&DATE($B$4,$D$4+1,1),업무일지!$D$5:$D$1004,"분석") | E29: =SUMIFS(업무일지!$AE$5:$AE$1004,업무일지!$B$5:$B$1004,">="&DATE($B$4,$D$4,1),업무일지!$B$5:$B$1004,"<"&DATE($B$4,$D$4+1,1),업무일지!$D$5:$D$1004,"분석") | F29: =COUNTIFS(업무일지!$B$5:$B$1004,">="&DATE($B$4,$D$4,1),업무일지!$B$5:$B$1004,"<"&DATE($B$4,$D$4+1,1),업무일지!$D$5:$D$1004,"분석",업무일지!$AG$5:$AG$1004,"진행중")
A30: 교육 | B30: =COUNTIFS(업무일지!$B$5:$B$1004,">="&DATE($B$4,$D$4,1),업무일지!$B$5:$B$1004,"<"&DATE($B$4,$D$4+1,1),업무일지!$D$5:$D$1004,"교육") | C30: =SUMIFS(업무일지!$AF$5:$AF$1004,업무일지!$B$5:$B$1004,">="&DATE($B$4,$D$4,1),업무일지!$B$5:$B$1004,"<"&DATE($B$4,$D$4+1,1),업무일지!$D$5:$D$1004,"교육") | D30: =SUMIFS(업무일지!$AD$5:$AD$1004,업무일지!$B$5:$B$1004,">="&DATE($B$4,$D$4,1),업무일지!$B$5:$B$1004,"<"&DATE($B$4,$D$4+1,1),업무일지!$D$5:$D$1004,"교육") | E30: =SUMIFS(업무일지!$AE$5:$AE$1004,업무일지!$B$5:$B$1004,">="&DATE($B$4,$D$4,1),업무일지!$B$5:$B$1004,"<"&DATE($B$4,$D$4+1,1),업무일지!$D$5:$D$1004,"교육") | F30: =COUNTIFS(업무일지!$B$5:$B$1004,">="&DATE($B$4,$D$4,1),업무일지!$B$5:$B$1004,"<"&DATE($B$4,$D$4+1,1),업무일지!$D$5:$D$1004,"교육",업무일지!$AG$5:$AG$1004,"진행중")
A31: 일일실시 | B31: =COUNTIFS(일일실시사항!$B$5:$B$1004,">="&DATE($B$4,$D$4,1),일일실시사항!$B$5:$B$1004,"<"&DATE($B$4,$D$4+1,1)) | C31: - | D31: - | E31: - | F31: =COUNTIFS(일일실시사항!$B$5:$B$1004,">="&DATE($B$4,$D$4,1),일일실시사항!$B$5:$B$1004,"<"&DATE($B$4,$D$4+1,1),일일실시사항!$J$5:$J$1004,"진행중")
A32: 합계 | B32: =SUM(B28:B31) | C32: =SUM(C28:C30) | D32: =SUM(D28:D30) | E32: =SUM(E28:E30) | F32: =SUM(F28:F31)
A34: ※ 달력 칸의 자동 집계는 [업무일지]에서 시작일~종료일이 그 날짜에 걸친 건을 셉니다. 일일실시사항은 아래 [이달 요약]에만 반영됩니다.
A35: ※ 오늘 날짜는 초록색, 공휴일([코드설정] K열)과 일요일은 빨간색으로 표시됩니다.

Sheet 업무일지
A1: 부서 업무일지 · 출장 / 분석 통합 대장
A2: ※ 출장·분석 1건 = 1행. 사건번호를 고르면 사건명·요청처와 [사건마스터]에 배정된 담당자가 통째로 따라옵니다. ※ 참여자는 15명까지 들어옵니다 — 열 위 [−] 버튼으로 접었다 펼 수 있습니다. ※ 같은 사건을 여러 날 나눠 하면 행을 나눠 쓰세요 — [회차]가 1, 2, 3…으로 자동으로 붙습니다. ※ 그 건에만 인원이 다르면 참여자 칸을 직접 골라 덮어쓰세요(그 행만 수동으로 바뀝니다). ※ 파란 글씨만 입력 / 초록 글씨는 사건마스터 연동 / 검정 글씨는 자동.
A4: 연번 | B4: 시작일 | C4: 종료일 | D4: 직무구분 | E4: 세부유형 | F4: 사건번호 | G4: 회차 | H4: 사건명 · 업무명 | I4: 요청·의뢰처 | J4: 주담당자 | K4: 참여자 1 | L4: 참여자 2 | M4: 참여자 3 | N4: 참여자 4 | O4: 참여자 5 | P4: 참여자 6 | Q4: 참여자 7 | R4: 참여자 8 | S4: 참여자 9 | T4: 참여자 10 | U4: 참여자 11 | V4: 참여자 12 | W4: 참여자 13 | X4: 참여자 14 | Y4: 참여자 15 | Z4: 투입인원(명) | AA4: 참여자 명단(자동) | AB4: 소속팀 | AC4: 장소 / 분석실 | AD4: 대상매체(건) | AE4: 데이터량(GB) | AF4: 소요일수 | AG4: 진행상태 | AH4: 비고
A5: =IF($B5="","",COUNT($B$5:$B5)) | G5: =IF($F5="","",COUNTIF($F$5:$F5,$F5)) | H5: =IF($F5="","",IFERROR(INDEX(사건마스터!$B$5:$B$64,MATCH($F5,사건마스터!$A$5:$A$64,0)),"")) | I5: =IF($F5="","",IFERROR(INDEX(사건마스터!$C$5:$C$64,MATCH($F5,사건마스터!$A$5:$A$64,0)),"")) | J5: =IF($F5="","",IFERROR(INDEX(사건마스터!$H$5:$H$64,MATCH($F5,사건마스터!$A$5:$A$64,0)),"")) | K5: =IF($F5="","",IFERROR(INDEX(사건마스터!$AH$5:$AH$64,MATCH($F5,사건마스터!$A$5:$A$64,0)),"")) | L5: =IF($F5="","",IFERROR(INDEX(사건마스터!$AI$5:$AI$64,MATCH($F5,사건마스터!$A$5:$A$64,0)),"")) | M5: =IF($F5="","",IFERROR(INDEX(사건마스터!$AJ$5:$AJ$64,MATCH($F5,사건마스터!$A$5:$A$64,0)),"")) | N5: =IF($F5="","",IFERROR(INDEX(사건마스터!$AK$5:$AK$64,MATCH($F5,사건마스터!$A$5:$A$64,0)),"")) | O5: =IF($F5="","",IFERROR(INDEX(사건마스터!$AL$5:$AL$64,MATCH($F5,사건마스터!$A$5:$A$64,0)),"")) | P5: =IF($F5="","",IFERROR(INDEX(사건마스터!$AM$5:$AM$64,MATCH($F5,사건마스터!$A$5:$A$64,0)),"")) | Q5: =IF($F5="","",IFERROR(INDEX(사건마스터!$AN$5:$AN$64,MATCH($F5,사건마스터!$A$5:$A$64,0)),"")) | R5: =IF($F5="","",IFERROR(INDEX(사건마스터!$AO$5:$AO$64,MATCH($F5,사건마스터!$A$5:$A$64,0)),"")) | S5: =IF($F5="","",IFERROR(INDEX(사건마스터!$AP$5:$AP$64,MATCH($F5,사건마스터!$A$5:$A$64,0)),"")) | T5: =IF($F5="","",IFERROR(INDEX(사건마스터!$AQ$5:$AQ$64,MATCH($F5,사건마스터!$A$5:$A$64,0)),"")) | U5: =IF($F5="","",IFERROR(INDEX(사건마스터!$AR$5:$AR$64,MATCH($F5,사건마스터!$A$5:$A$64,0)),"")) | V5: =IF($F5="","",IFERROR(INDEX(사건마스터!$AS$5:$AS$64,MATCH($F5,사건마스터!$A$5:$A$64,0)),"")) | W5: =IF($F5="","",IFERROR(INDEX(사건마스터!$AT$5:$AT$64,MATCH($F5,사건마스터!$A$5:$A$64,0)),"")) | X5: =IF($F5="","",IFERROR(INDEX(사건마스터!$AU$5:$AU$64,MATCH($F5,사건마스터!$A$5:$A$64,0)),"")) | Y5: =IF($F5="","",IFERROR(INDEX(사건마스터!$AV$5:$AV$64,MATCH($F5,사건마스터!$A$5:$A$64,0)),"")) | Z5: =IF(COUNTBLANK($J5:$Y5)=16,"",16-COUNTBLANK($J5:$Y5)) | AA5: =IF($J5="",MID($AX5,3,255),$J5&$AX5) | AB5: =IF($J5="","",IFERROR(INDEX(코드설정!$D$5:$D$24,MATCH($J5,코드설정!$C$5:$C$24,0)),"")) | AF5: =IF(OR($B5="",$C5=""),"",$C5-$B5+1) | AJ5: =IF($K5="","",", "&$K5) | AK5: =AJ5&IF($L5="","",", "&$L5) | AL5: =AK5&IF($M5="","",", "&$M5) | AM5: =AL5&IF($N5="","",", "&$N5) | AN5: =AM5&IF($O5="","",", "&$O5) | AO5: =AN5&IF($P5="","",", "&$P5) | AP5: =AO5&IF($Q5="","",", "&$Q5) | AQ5: =AP5&IF($R5="","",", "&$R5) | AR5: =AQ5&IF($S5="","",", "&$S5) | AS5: =AR5&IF($T5="","",", "&$T5) | AT5: =AS5&IF($U5="","",", "&$U5) | AU5: =AT5&IF($V5="","",", "&$V5) | AV5: =AU5&IF($W5="","",", "&$W5) | AW5: =AV5&IF($X5="","",", "&$X5) | AX5: =AW5&IF($Y5="","",", "&$Y5)
A6: =IF($B6="","",COUNT($B$5:$B6)) | G6: =IF($F6="","",COUNTIF($F$5:$F6,$F6)) | H6: =IF($F6="","",IFERROR(INDEX(사건마스터!$B$5:$B$64,MATCH($F6,사건마스터!$A$5:$A$64,0)),"")) | I6: =IF($F6="","",IFERROR(INDEX(사건마스터!$C$5:$C$64,MATCH($F6,사건마스터!$A$5:$A$64,0)),"")) | J6: =IF($F6="","",IFERROR(INDEX(사건마스터!$H$5:$H$64,MATCH($F6,사건마스터!$A$5:$A$64,0)),"")) | K6: =IF($F6="","",IFERROR(INDEX(사건마스터!$AH$5:$AH$64,MATCH($F6,사건마스터!$A$5:$A$64,0)),"")) | L6: =IF($F6="","",IFERROR(INDEX(사건마스터!$AI$5:$AI$64,MATCH($F6,사건마스터!$A$5:$A$64,0)),"")) | M6: =IF($F6="","",IFERROR(INDEX(사건마스터!$AJ$5:$AJ$64,MATCH($F6,사건마스터!$A$5:$A$64,0)),"")) | N6: =IF($F6="","",IFERROR(INDEX(사건마스터!$AK$5:$AK$64,MATCH($F6,사건마스터!$A$5:$A$64,0)),"")) | O6: =IF($F6="","",IFERROR(INDEX(사건마스터!$AL$5:$AL$64,MATCH($F6,사건마스터!$A$5:$A$64,0)),"")) | P6: =IF($F6="","",IFERROR(INDEX(사건마스터!$AM$5:$AM$64,MATCH($F6,사건마스터!$A$5:$A$64,0)),"")) | Q6: =IF($F6="","",IFERROR(INDEX(사건마스터!$AN$5:$AN$64,MATCH($F6,사건마스터!$A$5:$A$64,0)),"")) | R6: =IF($F6="","",IFERROR(INDEX(사건마스터!$AO$5:$AO$64,MATCH($F6,사건마스터!$A$5:$A$64,0)),"")) | S6: =IF($F6="","",IFERROR(INDEX(사건마스터!$AP$5:$AP$64,MATCH($F6,사건마스터!$A$5:$A$64,0)),"")) | T6: =IF($F6="","",IFERROR(INDEX(사건마스터!$AQ$5:$AQ$64,MATCH($F6,사건마스터!$A$5:$A$64,0)),"")) | U6: =IF($F6="","",IFERROR(INDEX(사건마스터!$AR$5:$AR$64,MATCH($F6,사건마스터!$A$5:$A$64,0)),"")) | V6: =IF($F6="","",IFERROR(INDEX(사건마스터!$AS$5:$AS$64,MATCH($F6,사건마스터!$A$5:$A$64,0)),"")) | W6: =IF($F6="","",IFERROR(INDEX(사건마스터!$AT$5:$AT$64,MATCH($F6,사건마스터!$A$5:$A$64,0)),"")) | X6: =IF($F6="","",IFERROR(INDEX(사건마스터!$AU$5:$AU$64,MATCH($F6,사건마스터!$A$5:$A$64,0)),"")) | Y6: =IF($F6="","",IFERROR(INDEX(사건마스터!$AV$5:$AV$64,MATCH($F6,사건마스터!$A$5:$A$64,0)),"")) | Z6: =IF(COUNTBLANK($J6:$Y6)=16,"",16-COUNTBLANK($J6:$Y6)) | AA6: =IF($J6="",MID($AX6,3,255),$J6&$AX6) | AB6: =IF($J6="","",IFERROR(INDEX(코드설정!$D$5:$D$24,MATCH($J6,코드설정!$C$5:$C$24,0)),"")) | AF6: =IF(OR($B6="",$C6=""),"",$C6-$B6+1) | AJ6: =IF($K6="","",", "&$K6) | AK6: =AJ6&IF($L6="","",", "&$L6) | AL6: =AK6&IF($M6="","",", "&$M6) | AM6: =AL6&IF($N6="","",", "&$N6) | AN6: =AM6&IF($O6="","",", "&$O6) | AO6: =AN6&IF($P6="","",", "&$P6) | AP6: =AO6&IF($Q6="","",", "&$Q6) | AQ6: =AP6&IF($R6="","",", "&$R6) | AR6: =AQ6&IF($S6="","",", "&$S6) | AS6: =AR6&IF($T6="","",", "&$T6) | AT6: =AS6&IF($U6="","",", "&$U6) | AU6: =AT6&IF($V6="","",", "&$V6) | AV6: =AU6&IF($W6="","",", "&$W6) | AW6: =AV6&IF($X6="","",", "&$X6) | AX6: =AW6&IF($Y6="","",", "&$Y6)
A7: =IF($B7="","",COUNT($B$5:$B7)) | G7: =IF($F7="","",COUNTIF($F$5:$F7,$F7)) | H7: =IF($F7="","",IFERROR(INDEX(사건마스터!$B$5:$B$64,MATCH($F7,사건마스터!$A$5:$A$64,0)),"")) | I7: =IF($F7="","",IFERROR(INDEX(사건마스터!$C$5:$C$64,MATCH($F7,사건마스터!$A$5:$A$64,0)),"")) | J7: =IF($F7="","",IFERROR(INDEX(사건마스터!$H$5:$H$64,MATCH($F7,사건마스터!$A$5:$A$64,0)),"")) | K7: =IF($F7="","",IFERROR(INDEX(사건마스터!$AH$5:$AH$64,MATCH($F7,사건마스터!$A$5:$A$64,0)),"")) | L7: =IF($F7="","",IFERROR(INDEX(사건마스터!$AI$5:$AI$64,MATCH($F7,사건마스터!$A$5:$A$64,0)),"")) | M7: =IF($F7="","",IFERROR(INDEX(사건마스터!$AJ$5:$AJ$64,MATCH($F7,사건마스터!$A$5:$A$64,0)),"")) | N7: =IF($F7="","",IFERROR(INDEX(사건마스터!$AK$5:$AK$64,MATCH($F7,사건마스터!$A$5:$A$64,0)),"")) | O7: =IF($F7="","",IFERROR(INDEX(사건마스터!$AL$5:$AL$64,MATCH($F7,사건마스터!$A$5:$A$64,0)),"")) | P7: =IF($F7="","",IFERROR(INDEX(사건마스터!$AM$5:$AM$64,MATCH($F7,사건마스터!$A$5:$A$64,0)),"")) | Q7: =IF($F7="","",IFERROR(INDEX(사건마스터!$AN$5:$AN$64,MATCH($F7,사건마스터!$A$5:$A$64,0)),"")) | R7: =IF($F7="","",IFERROR(INDEX(사건마스터!$AO$5:$AO$64,MATCH($F7,사건마스터!$A$5:$A$64,0)),"")) | S7: =IF($F7="","",IFERROR(INDEX(사건마스터!$AP$5:$AP$64,MATCH($F7,사건마스터!$A$5:$A$64,0)),"")) | T7: =IF($F7="","",IFERROR(INDEX(사건마스터!$AQ$5:$AQ$64,MATCH($F7,사건마스터!$A$5:$A$64,0)),"")) | U7: =IF($F7="","",IFERROR(INDEX(사건마스터!$AR$5:$AR$64,MATCH($F7,사건마스터!$A$5:$A$64,0)),"")) | V7: =IF($F7="","",IFERROR(INDEX(사건마스터!$AS$5:$AS$64,MATCH($F7,사건마스터!$A$5:$A$64,0)),"")) | W7: =IF($F7="","",IFERROR(INDEX(사건마스터!$AT$5:$AT$64,MATCH($F7,사건마스터!$A$5:$A$64,0)),"")) | X7: =IF($F7="","",IFERROR(INDEX(사건마스터!$AU$5:$AU$64,MATCH($F7,사건마스터!$A$5:$A$64,0)),"")) | Y7: =IF($F7="","",IFERROR(INDEX(사건마스터!$AV$5:$AV$64,MATCH($F7,사건마스터!$A$5:$A$64,0)),"")) | Z7: =IF(COUNTBLANK($J7:$Y7)=16,"",16-COUNTBLANK($J7:$Y7)) | AA7: =IF($J7="",MID($AX7,3,255),$J7&$AX7) | AB7: =IF($J7="","",IFERROR(INDEX(코드설정!$D$5:$D$24,MATCH($J7,코드설정!$C$5:$C$24,0)),"")) | AF7: =IF(OR($B7="",$C7=""),"",$C7-$B7+1) | AJ7: =IF($K7="","",", "&$K7) | AK7: =AJ7&IF($L7="","",", "&$L7) | AL7: =AK7&IF($M7="","",", "&$M7) | AM7: =AL7&IF($N7="","",", "&$N7) | AN7: =AM7&IF($O7="","",", "&$O7) | AO7: =AN7&IF($P7="","",", "&$P7) | AP7: =AO7&IF($Q7="","",", "&$Q7) | AQ7: =AP7&IF($R7="","",", "&$R7) | AR7: =AQ7&IF($S7="","",", "&$S7) | AS7: =AR7&IF($T7="","",", "&$T7) | AT7: =AS7&IF($U7="","",", "&$U7) | AU7: =AT7&IF($V7="","",", "&$V7) | AV7: =AU7&IF($W7="","",", "&$W7) | AW7: =AV7&IF($X7="","",", "&$X7) | AX7: =AW7&IF($Y7="","",", "&$Y7)
A8: =IF($B8="","",COUNT($B$5:$B8)) | G8: =IF($F8="","",COUNTIF($F$5:$F8,$F8)) | H8: =IF($F8="","",IFERROR(INDEX(사건마스터!$B$5:$B$64,MATCH($F8,사건마스터!$A$5:$A$64,0)),"")) | I8: =IF($F8="","",IFERROR(INDEX(사건마스터!$C$5:$C$64,MATCH($F8,사건마스터!$A$5:$A$64,0)),"")) | J8: =IF($F8="","",IFERROR(INDEX(사건마스터!$H$5:$H$64,MATCH($F8,사건마스터!$A$5:$A$64,0)),"")) | K8: =IF($F8="","",IFERROR(INDEX(사건마스터!$AH$5:$AH$64,MATCH($F8,사건마스터!$A$5:$A$64,0)),"")) | L8: =IF($F8="","",IFERROR(INDEX(사건마스터!$AI$5:$AI$64,MATCH($F8,사건마스터!$A$5:$A$64,0)),"")) | M8: =IF($F8="","",IFERROR(INDEX(사건마스터!$AJ$5:$AJ$64,MATCH($F8,사건마스터!$A$5:$A$64,0)),"")) | N8: =IF($F8="","",IFERROR(INDEX(사건마스터!$AK$5:$AK$64,MATCH($F8,사건마스터!$A$5:$A$64,0)),"")) | O8: =IF($F8="","",IFERROR(INDEX(사건마스터!$AL$5:$AL$64,MATCH($F8,사건마스터!$A$5:$A$64,0)),"")) | P8: =IF($F8="","",IFERROR(INDEX(사건마스터!$AM$5:$AM$64,MATCH($F8,사건마스터!$A$5:$A$64,0)),"")) | Q8: =IF($F8="","",IFERROR(INDEX(사건마스터!$AN$5:$AN$64,MATCH($F8,사건마스터!$A$5:$A$64,0)),"")) | R8: =IF($F8="","",IFERROR(INDEX(사건마스터!$AO$5:$AO$64,MATCH($F8,사건마스터!$A$5:$A$64,0)),"")) | S8: =IF($F8="","",IFERROR(INDEX(사건마스터!$AP$5:$AP$64,MATCH($F8,사건마스터!$A$5:$A$64,0)),"")) | T8: =IF($F8="","",IFERROR(INDEX(사건마스터!$AQ$5:$AQ$64,MATCH($F8,사건마스터!$A$5:$A$64,0)),"")) | U8: =IF($F8="","",IFERROR(INDEX(사건마스터!$AR$5:$AR$64,MATCH($F8,사건마스터!$A$5:$A$64,0)),"")) | V8: =IF($F8="","",IFERROR(INDEX(사건마스터!$AS$5:$AS$64,MATCH($F8,사건마스터!$A$5:$A$64,0)),"")) | W8: =IF($F8="","",IFERROR(INDEX(사건마스터!$AT$5:$AT$64,MATCH($F8,사건마스터!$A$5:$A$64,0)),"")) | X8: =IF($F8="","",IFERROR(INDEX(사건마스터!$AU$5:$AU$64,MATCH($F8,사건마스터!$A$5:$A$64,0)),"")) | Y8: =IF($F8="","",IFERROR(INDEX(사건마스터!$AV$5:$AV$64,MATCH($F8,사건마스터!$A$5:$A$64,0)),"")) | Z8: =IF(COUNTBLANK($J8:$Y8)=16,"",16-COUNTBLANK($J8:$Y8)) | AA8: =IF($J8="",MID($AX8,3,255),$J8&$AX8) | AB8: =IF($J8="","",IFERROR(INDEX(코드설정!$D$5:$D$24,MATCH($J8,코드설정!$C$5:$C$24,0)),"")) | AF8: =IF(OR($B8="",$C8=""),"",$C8-$B8+1) | AJ8: =IF($K8="","",", "&$K8) | AK8: =AJ8&IF($L8="","",", "&$L8) | AL8: =AK8&IF($M8="","",", "&$M8) | AM8: =AL8&IF($N8="","",", "&$N8) | AN8: =AM8&IF($O8="","",", "&$O8) | AO8: =AN8&IF($P8="","",", "&$P8) | AP8: =AO8&IF($Q8="","",", "&$Q8) | AQ8: =AP8&IF($R8="","",", "&$R8) | AR8: =AQ8&IF($S8="","",", "&$S8) | AS8: =AR8&IF($T8="","",", "&$T8) | AT8: =AS8&IF($U8="","",", "&$U8) | AU8: =AT8&IF($V8="","",", "&$V8) | AV8: =AU8&IF($W8="","",", "&$W8) | AW8: =AV8&IF($X8="","",", "&$X8) | AX8: =AW8&IF($Y8="","",", "&$Y8)
A9: =IF($B9="","",COUNT($B$5:$B9)) | G9: =IF($F9="","",COUNTIF($F$5:$F9,$F9)) | H9: =IF($F9="","",IFERROR(INDEX(사건마스터!$B$5:$B$64,MATCH($F9,사건마스터!$A$5:$A$64,0)),"")) | I9: =IF($F9="","",IFERROR(INDEX(사건마스터!$C$5:$C$64,MATCH($F9,사건마스터!$A$5:$A$64,0)),"")) | J9: =IF($F9="","",IFERROR(INDEX(사건마스터!$H$5:$H$64,MATCH($F9,사건마스터!$A$5:$A$64,0)),"")) | K9: =IF($F9="","",IFERROR(INDEX(사건마스터!$AH$5:$AH$64,MATCH($F9,사건마스터!$A$5:$A$64,0)),"")) | L9: =IF($F9="","",IFERROR(INDEX(사건마스터!$AI$5:$AI$64,MATCH($F9,사건마스터!$A$5:$A$64,0)),"")) | M9: =IF($F9="","",IFERROR(INDEX(사건마스터!$AJ$5:$AJ$64,MATCH($F9,사건마스터!$A$5:$A$64,0)),"")) | N9: =IF($F9="","",IFERROR(INDEX(사건마스터!$AK$5:$AK$64,MATCH($F9,사건마스터!$A$5:$A$64,0)),"")) | O9: =IF($F9="","",IFERROR(INDEX(사건마스터!$AL$5:$AL$64,MATCH($F9,사건마스터!$A$5:$A$64,0)),"")) | P9: =IF($F9="","",IFERROR(INDEX(사건마스터!$AM$5:$AM$64,MATCH($F9,사건마스터!$A$5:$A$64,0)),"")) | Q9: =IF($F9="","",IFERROR(INDEX(사건마스터!$AN$5:$AN$64,MATCH($F9,사건마스터!$A$5:$A$64,0)),"")) | R9: =IF($F9="","",IFERROR(INDEX(사건마스터!$AO$5:$AO$64,MATCH($F9,사건마스터!$A$5:$A$64,0)),"")) | S9: =IF($F9="","",IFERROR(INDEX(사건마스터!$AP$5:$AP$64,MATCH($F9,사건마스터!$A$5:$A$64,0)),"")) | T9: =IF($F9="","",IFERROR(INDEX(사건마스터!$AQ$5:$AQ$64,MATCH($F9,사건마스터!$A$5:$A$64,0)),"")) | U9: =IF($F9="","",IFERROR(INDEX(사건마스터!$AR$5:$AR$64,MATCH($F9,사건마스터!$A$5:$A$64,0)),"")) | V9: =IF($F9="","",IFERROR(INDEX(사건마스터!$AS$5:$AS$64,MATCH($F9,사건마스터!$A$5:$A$64,0)),"")) | W9: =IF($F9="","",IFERROR(INDEX(사건마스터!$AT$5:$AT$64,MATCH($F9,사건마스터!$A$5:$A$64,0)),"")) | X9: =IF($F9="","",IFERROR(INDEX(사건마스터!$AU$5:$AU$64,MATCH($F9,사건마스터!$A$5:$A$64,0)),"")) | Y9: =IF($F9="","",IFERROR(INDEX(사건마스터!$AV$5:$AV$64,MATCH($F9,사건마스터!$A$5:$A$64,0)),"")) | Z9: =IF(COUNTBLANK($J9:$Y9)=16,"",16-COUNTBLANK($J9:$Y9)) | AA9: =IF($J9="",MID($AX9,3,255),$J9&$AX9) | AB9: =IF($J9="","",IFERROR(INDEX(코드설정!$D$5:$D$24,MATCH($J9,코드설정!$C$5:$C$24,0)),"")) | AF9: =IF(OR($B9="",$C9=""),"",$C9-$B9+1) | AJ9: =IF($K9="","",", "&$K9) | AK9: =AJ9&IF($L9="","",", "&$L9) | AL9: =AK9&IF($M9="","",", "&$M9) | AM9: =AL9&IF($N9="","",", "&$N9) | AN9: =AM9&IF($O9="","",", "&$O9) | AO9: =AN9&IF($P9="","",", "&$P9) | AP9: =AO9&IF($Q9="","",", "&$Q9) | AQ9: =AP9&IF($R9="","",", "&$R9) | AR9: =AQ9&IF($S9="","",", "&$S9) | AS9: =AR9&IF($T9="","",", "&$T9) | AT9: =AS9&IF($U9="","",", "&$U9) | AU9: =AT9&IF($V9="","",", "&$V9) | AV9: =AU9&IF($W9="","",", "&$W9) | AW9: =AV9&IF($X9="","",", "&$X9) | AX9: =AW9&IF($Y9="","",", "&$Y9)
A10: =IF($B10="","",COUNT($B$5:$B10)) | G10: =IF($F10="","",COUNTIF($F$5:$F10,$F10)) | H10: =IF($F10="","",IFERROR(INDEX(사건마스터!$B$5:$B$64,MATCH($F10,사건마스터!$A$5:$A$64,0)),"")) | I10: =IF($F10="","",IFERROR(INDEX(사건마스터!$C$5:$C$64,MATCH($F10,사건마스터!$A$5:$A$64,0)),"")) | J10: =IF($F10="","",IFERROR(INDEX(사건마스터!$H$5:$H$64,MATCH($F10,사건마스터!$A$5:$A$64,0)),"")) | K10: =IF($F10="","",IFERROR(INDEX(사건마스터!$AH$5:$AH$64,MATCH($F10,사건마스터!$A$5:$A$64,0)),"")) | L10: =IF($F10="","",IFERROR(INDEX(사건마스터!$AI$5:$AI$64,MATCH($F10,사건마스터!$A$5:$A$64,0)),"")) | M10: =IF($F10="","",IFERROR(INDEX(사건마스터!$AJ$5:$AJ$64,MATCH($F10,사건마스터!$A$5:$A$64,0)),"")) | N10: =IF($F10="","",IFERROR(INDEX(사건마스터!$AK$5:$AK$64,MATCH($F10,사건마스터!$A$5:$A$64,0)),"")) | O10: =IF($F10="","",IFERROR(INDEX(사건마스터!$AL$5:$AL$64,MATCH($F10,사건마스터!$A$5:$A$64,0)),"")) | P10: =IF($F10="","",IFERROR(INDEX(사건마스터!$AM$5:$AM$64,MATCH($F10,사건마스터!$A$5:$A$64,0)),"")) | Q10: =IF($F10="","",IFERROR(INDEX(사건마스터!$AN$5:$AN$64,MATCH($F10,사건마스터!$A$5:$A$64,0)),"")) | R10: =IF($F10="","",IFERROR(INDEX(사건마스터!$AO$5:$AO$64,MATCH($F10,사건마스터!$A$5:$A$64,0)),"")) | S10: =IF($F10="","",IFERROR(INDEX(사건마스터!$AP$5:$AP$64,MATCH($F10,사건마스터!$A$5:$A$64,0)),"")) | T10: =IF($F10="","",IFERROR(INDEX(사건마스터!$AQ$5:$AQ$64,MATCH($F10,사건마스터!$A$5:$A$64,0)),"")) | U10: =IF($F10="","",IFERROR(INDEX(사건마스터!$AR$5:$AR$64,MATCH($F10,사건마스터!$A$5:$A$64,0)),"")) | V10: =IF($F10="","",IFERROR(INDEX(사건마스터!$AS$5:$AS$64,MATCH($F10,사건마스터!$A$5:$A$64,0)),"")) | W10: =IF($F10="","",IFERROR(INDEX(사건마스터!$AT$5:$AT$64,MATCH($F10,사건마스터!$A$5:$A$64,0)),"")) | X10: =IF($F10="","",IFERROR(INDEX(사건마스터!$AU$5:$AU$64,MATCH($F10,사건마스터!$A$5:$A$64,0)),"")) | Y10: =IF($F10="","",IFERROR(INDEX(사건마스터!$AV$5:$AV$64,MATCH($F10,사건마스터!$A$5:$A$64,0)),"")) | Z10: =IF(COUNTBLANK($J10:$Y10)=16,"",16-COUNTBLANK($J10:$Y10)) | AA10: =IF($J10="",MID($AX10,3,255),$J10&$AX10) | AB10: =IF($J10="","",IFERROR(INDEX(코드설정!$D$5:$D$24,MATCH($J10,코드설정!$C$5:$C$24,0)),"")) | AF10: =IF(OR($B10="",$C10=""),"",$C10-$B10+1) | AJ10: =IF($K10="","",", "&$K10) | AK10: =AJ10&IF($L10="","",", "&$L10) | AL10: =AK10&IF($M10="","",", "&$M10) | AM10: =AL10&IF($N10="","",", "&$N10) | AN10: =AM10&IF($O10="","",", "&$O10) | AO10: =AN10&IF($P10="","",", "&$P10) | AP10: =AO10&IF($Q10="","",", "&$Q10) | AQ10: =AP10&IF($R10="","",", "&$R10) | AR10: =AQ10&IF($S10="","",", "&$S10) | AS10: =AR10&IF($T10="","",", "&$T10) | AT10: =AS10&IF($U10="","",", "&$U10) | AU10: =AT10&IF($V10="","",", "&$V10) | AV10: =AU10&IF($W10="","",", "&$W10) | AW10: =AV10&IF($X10="","",", "&$X10) | AX10: =AW10&IF($Y10="","",", "&$Y10)
A11: =IF($B11="","",COUNT($B$5:$B11)) | G11: =IF($F11="","",COUNTIF($F$5:$F11,$F11)) | H11: =IF($F11="","",IFERROR(INDEX(사건마스터!$B$5:$B$64,MATCH($F11,사건마스터!$A$5:$A$64,0)),"")) | I11: =IF($F11="","",IFERROR(INDEX(사건마스터!$C$5:$C$64,MATCH($F11,사건마스터!$A$5:$A$64,0)),"")) | J11: =IF($F11="","",IFERROR(INDEX(사건마스터!$H$5:$H$64,MATCH($F11,사건마스터!$A$5:$A$64,0)),"")) | K11: =IF($F11="","",IFERROR(INDEX(사건마스터!$AH$5:$AH$64,MATCH($F11,사건마스터!$A$5:$A$64,0)),"")) | L11: =IF($F11="","",IFERROR(INDEX(사건마스터!$AI$5:$AI$64,MATCH($F11,사건마스터!$A$5:$A$64,0)),"")) | M11: =IF($F11="","",IFERROR(INDEX(사건마스터!$AJ$5:$AJ$64,MATCH($F11,사건마스터!$A$5:$A$64,0)),"")) | N11: =IF($F11="","",IFERROR(INDEX(사건마스터!$AK$5:$AK$64,MATCH($F11,사건마스터!$A$5:$A$64,0)),"")) | O11: =IF($F11="","",IFERROR(INDEX(사건마스터!$AL$5:$AL$64,MATCH($F11,사건마스터!$A$5:$A$64,0)),"")) | P11: =IF($F11="","",IFERROR(INDEX(사건마스터!$AM$5:$AM$64,MATCH($F11,사건마스터!$A$5:$A$64,0)),"")) | Q11: =IF($F11="","",IFERROR(INDEX(사건마스터!$AN$5:$AN$64,MATCH($F11,사건마스터!$A$5:$A$64,0)),"")) | R11: =IF($F11="","",IFERROR(INDEX(사건마스터!$AO$5:$AO$64,MATCH($F11,사건마스터!$A$5:$A$64,0)),"")) | S11: =IF($F11="","",IFERROR(INDEX(사건마스터!$AP$5:$AP$64,MATCH($F11,사건마스터!$A$5:$A$64,0)),"")) | T11: =IF($F11="","",IFERROR(INDEX(사건마스터!$AQ$5:$AQ$64,MATCH($F11,사건마스터!$A$5:$A$64,0)),"")) | U11: =IF($F11="","",IFERROR(INDEX(사건마스터!$AR$5:$AR$64,MATCH($F11,사건마스터!$A$5:$A$64,0)),"")) | V11: =IF($F11="","",IFERROR(INDEX(사건마스터!$AS$5:$AS$64,MATCH($F11,사건마스터!$A$5:$A$64,0)),"")) | W11: =IF($F11="","",IFERROR(INDEX(사건마스터!$AT$5:$AT$64,MATCH($F11,사건마스터!$A$5:$A$64,0)),"")) | X11: =IF($F11="","",IFERROR(INDEX(사건마스터!$AU$5:$AU$64,MATCH($F11,사건마스터!$A$5:$A$64,0)),"")) | Y11: =IF($F11="","",IFERROR(INDEX(사건마스터!$AV$5:$AV$64,MATCH($F11,사건마스터!$A$5:$A$64,0)),"")) | Z11: =IF(COUNTBLANK($J11:$Y11)=16,"",16-COUNTBLANK($J11:$Y11)) | AA11: =IF($J11="",MID($AX11,3,255),$J11&$AX11) | AB11: =IF($J11="","",IFERROR(INDEX(코드설정!$D$5:$D$24,MATCH($J11,코드설정!$C$5:$C$24,0)),"")) | AF11: =IF(OR($B11="",$C11=""),"",$C11-$B11+1) | AJ11: =IF($K11="","",", "&$K11) | AK11: =AJ11&IF($L11="","",", "&$L11) | AL11: =AK11&IF($M11="","",", "&$M11) | AM11: =AL11&IF($N11="","",", "&$N11) | AN11: =AM11&IF($O11="","",", "&$O11) | AO11: =AN11&IF($P11="","",", "&$P11) | AP11: =AO11&IF($Q11="","",", "&$Q11) | AQ11: =AP11&IF($R11="","",", "&$R11) | AR11: =AQ11&IF($S11="","",", "&$S11) | AS11: =AR11&IF($T11="","",", "&$T11) | AT11: =AS11&IF($U11="","",", "&$U11) | AU11: =AT11&IF($V11="","",", "&$V11) | AV11: =AU11&IF($W11="","",", "&$W11) | AW11: =AV11&IF($X11="","",", "&$X11) | AX11: =AW11&IF($Y11="","",", "&$Y11)
A12: =IF($B12="","",COUNT($B$5:$B12)) | G12: =IF($F12="","",COUNTIF($F$5:$F12,$F12)) | H12: =IF($F12="","",IFERROR(INDEX(사건마스터!$B$5:$B$64,MATCH($F12,사건마스터!$A$5:$A$64,0)),"")) | I12: =IF($F12="","",IFERROR(INDEX(사건마스터!$C$5:$C$64,MATCH($F12,사건마스터!$A$5:$A$64,0)),"")) | J12: =IF($F12="","",IFERROR(INDEX(사건마스터!$H$5:$H$64,MATCH($F12,사건마스터!$A$5:$A$64,0)),"")) | K12: =IF($F12="","",IFERROR(INDEX(사건마스터!$AH$5:$AH$64,MATCH($F12,사건마스터!$A$5:$A$64,0)),"")) | L12: =IF($F12="","",IFERROR(INDEX(사건마스터!$AI$5:$AI$64,MATCH($F12,사건마스터!$A$5:$A$64,0)),"")) | M12: =IF($F12="","",IFERROR(INDEX(사건마스터!$AJ$5:$AJ$64,MATCH($F12,사건마스터!$A$5:$A$64,0)),"")) | N12: =IF($F12="","",IFERROR(INDEX(사건마스터!$AK$5:$AK$64,MATCH($F12,사건마스터!$A$5:$A$64,0)),"")) | O12: =IF($F12="","",IFERROR(INDEX(사건마스터!$AL$5:$AL$64,MATCH($F12,사건마스터!$A$5:$A$64,0)),"")) | P12: =IF($F12="","",IFERROR(INDEX(사건마스터!$AM$5:$AM$64,MATCH($F12,사건마스터!$A$5:$A$64,0)),"")) | Q12: =IF($F12="","",IFERROR(INDEX(사건마스터!$AN$5:$AN$64,MATCH($F12,사건마스터!$A$5:$A$64,0)),"")) | R12: =IF($F12="","",IFERROR(INDEX(사건마스터!$AO$5:$AO$64,MATCH($F12,사건마스터!$A$5:$A$64,0)),"")) | S12: =IF($F12="","",IFERROR(INDEX(사건마스터!$AP$5:$AP$64,MATCH($F12,사건마스터!$A$5:$A$64,0)),"")) | T12: =IF($F12="","",IFERROR(INDEX(사건마스터!$AQ$5:$AQ$64,MATCH($F12,사건마스터!$A$5:$A$64,0)),"")) | U12: =IF($F12="","",IFERROR(INDEX(사건마스터!$AR$5:$AR$64,MATCH($F12,사건마스터!$A$5:$A$64,0)),"")) | V12: =IF($F12="","",IFERROR(INDEX(사건마스터!$AS$5:$AS$64,MATCH($F12,사건마스터!$A$5:$A$64,0)),"")) | W12: =IF($F12="","",IFERROR(INDEX(사건마스터!$AT$5:$AT$64,MATCH($F12,사건마스터!$A$5:$A$64,0)),"")) | X12: =IF($F12="","",IFERROR(INDEX(사건마스터!$AU$5:$AU$64,MATCH($F12,사건마스터!$A$5:$A$64,0)),"")) | Y12: =IF($F12="","",IFERROR(INDEX(사건마스터!$AV$5:$AV$64,MATCH($F12,사건마스터!$A$5:$A$64,0)),"")) | Z12: =IF(COUNTBLANK($J12:$Y12)=16,"",16-COUNTBLANK($J12:$Y12)) | AA12: =IF($J12="",MID($AX12,3,255),$J12&$AX12) | AB12: =IF($J12="","",IFERROR(INDEX(코드설정!$D$5:$D$24,MATCH($J12,코드설정!$C$5:$C$24,0)),"")) | AF12: =IF(OR($B12="",$C12=""),"",$C12-$B12+1) | AJ12: =IF($K12="","",", "&$K12) | AK12: =AJ12&IF($L12="","",", "&$L12) | AL12: =AK12&IF($M12="","",", "&$M12) | AM12: =AL12&IF($N12="","",", "&$N12) | AN12: =AM12&IF($O12="","",", "&$O12) | AO12: =AN12&IF($P12="","",", "&$P12) | AP12: =AO12&IF($Q12="","",", "&$Q12) | AQ12: =AP12&IF($R12="","",", "&$R12) | AR12: =AQ12&IF($S12="","",", "&$S12) | AS12: =AR12&IF($T12="","",", "&$T12) | AT12: =AS12&IF($U12="","",", "&$U12) | AU12: =AT12&IF($V12="","",", "&$V12) | AV12: =AU12&IF($W12="","",", "&$W12) | AW12: =AV12&IF($X12="","",", "&$X12) | AX12: =AW12&IF($Y12="","",", "&$Y12)
